Workbook

Sheet ACCUEIL
B2: =PARAMETRES!$C$5 -> CAFE VICTOR HUGO
B3: =PARAMETRES!$C$6&", "&PARAMETRES!$C$7 -> Mohammedia, Maroc
B4: SYSTÈME DE GESTION — CAISSE, DÉPENSES, CHARGES ET RÉSULTATS
B7: LE MOIS EN COURS | D7: =PARAMETRES!$C$15 -> 46235
B8: Recette | C8: Dépenses | D8: Résultat | E8: Marge | F8: Caisse | G8: Jours saisis
B9: =SUMIFS(JOURNAL!$H$8:$H$1007,JOURNAL!$D$8:$D$1007,"RECETTE",JOURNAL!$C$8:$C$1007,PARAMETRES!$C$14) -> 54937 | C9: =SUMIFS(JOURNAL!$H$8:$H$1007,JOURNAL!$D$8:$D$1007,"DEPENSE",JOURNAL!$C$8:$C$1007,PARAMETRES!$C$14) -> 50714 | D9: =SUMIFS(JOURNAL!$H$8:$H$1007,JOURNAL!$D$8:$D$1007,"RECETTE",JOURNAL!$C$8:$C$1007,PARAMETRES!$C$14)-SUMIFS(JOURNAL!$H$8:$H$1007,JOURNAL!$D$8:$D$1007,"DEPENSE",JOURNAL!$C$8:$C$1007,PARAMETRES!$C$14) -> 4223 | E9: =IFERROR((SUMIFS(JOURNAL!$H$8:$H$1007,JOURNAL!$D$8:$D$1007,"RECETTE",JOURNAL!$C$8:$C$1007,PARAMETRES!$C$14)-SUMIFS(JOURNAL!$H$8:$H$1007,JOURNAL!$D$8:$D$1007,"DEPENSE",JOURNAL!$C$8:$C$1007,PARAMETRES!$C$14))/SUMIFS(JOURNAL!$H$8:$H$1007,JOURNAL!$D$8:$D$1007,"RECETTE",JOURNAL!$C$8:$C$1007,PARAMETRES!$C$14),0) -> 0.076869869 | F9: ='RECAP JOUR'!$O$37 -> 4223 | G9: =COUNTIF('RECAP JOUR'!$F$6:$F$36,">0") -> 27
B11: COMMENT UTILISER CE CLASSEUR — 3 ÉTAPES
B12: 1 | C12: CHAQUE SOIR, APRÈS LA FERMETURE
C13: Ouvrez la feuille JOURNAL. Sur la première ligne vide : la date du jour, le type RECETTE, la catégorie « Vente Caisse », et le montant compté dans la caisse. Puis une ligne DEPENSE par achat ou paiement de la journée (fournisseur, montant).
B15: 2 | C15: VÉRIFIEZ QUE LA LIGNE EST VERTE
C16: La dernière colonne du JOURNAL affiche OK en vert quand la ligne est complète. Si elle affiche « Catégorie ? » ou « Montant ? », corrigez avant de passer à la suite.
B18: 3 | C18: REGARDEZ LE TABLEAU DE BORD
C19: Tout est déjà calculé : recette du mois, dépenses, résultat, marge, caisse, graphiques. Vous n’avez jamais à recopier un chiffre d’une feuille à l’autre.
B21: LES FEUILLES DU CLASSEUR
B22: FEUILLE | C22: À QUOI ELLE SERT | H22: SAISIE ?
B23: ACCUEIL | C23: Cette page : mode d’emploi et chiffres du mois. | H23: Non
B24: PARAMETRES | C24: Nom du commerce, mois analysé, caisse de départ, listes de fournisseurs et de catégories. | H24: Oui
B25: JOURNAL | C25: Le cœur du système : une ligne par opération, recette ou dépense. C’est la seule feuille à remplir tous les jours. | H25: Oui
B26: RECAP JOUR | C26: Le mois jour par jour : recette, dépenses par type, résultat, caisse cumulée. | H26: Non
B27: TABLEAU DE BORD | C27: La photo du mois : indicateurs et graphiques. | H27: Non
B28: SUIVI MENSUEL | C28: Mois par mois, 2025 et 2026, pour voir les tendances. | H28: Non
B29: CHARGES FIXES | C29: Budget mensuel par poste comparé au réalisé, et coût de fonctionnement par jour. | H29: Budget
B30: SALAIRES | C30: Le personnel, le salaire convenu et ce qui a été versé dans le mois. | H30: Salaires
B31: MARGES PRODUITS | C31: Ce que rapporte chaque boisson une fois le coût matière déduit. | H31: Couts
B32: ASSOCIÉS | C32: Apports de Hamid et Mouhssine : achat du fonds et aménagement du café. | H32: Non
B33: ARCHIVE | C33: Données de l’ancien classeur sans rapport avec le café, conservées pour mémoire. | H33: Non
B35: CE QUI A ÉTÉ REPRIS DE L’ANCIEN CLASSEUR
B36: 27 journées d’août 2026 | C36: 145 opérations transférées dans le JOURNAL | E36: 54 937 DH de recettes et 50 714 DH de dépenses — identiques à la feuille SUIVI d’origine.
B37: Historique mensuel 2025 | C37: 10 mois de recettes et d’achats | E37: Repris dans SUIVI MENSUEL depuis la feuille Feuil1.
B38: Charges fixes et salaires | C38: 9 postes de charges, 11 personnes | E38: Repris dans CHARGES FIXES et SALAIRES depuis la feuille CHARGE.
B39: Comptes des associés | C39: 105 lignes d’apports | E39: Reprises dans ASSOCIÉS depuis la feuille DEPENSE_CAFE, sans modification.
B40: Prix de vente | C40: 4 produits | E40: Repris dans MARGES PRODUITS depuis la feuille CHARGE.
B42: Différence avec l’ancien classeur : il fallait auparavant créer une feuille par jour et recopier les totaux à la main dans la feuille SUIVI. Ici, une seule feuille se remplit (JOURNAL) et les 31 jours du mois, le tableau de bord, le suivi mensuel et les charges se calculent seuls. Pour changer de mois, il suffit de modifier le numéro du mois dans PARAMÈTRES — rien d’autre.

Sheet TABLEAU DE BORD
A1: TABLEAU DE BORD
A2: Photo du mois en cours. Tout se met à jour dès que vous saisissez dans le JOURNAL.
A4: =PARAMETRES!$C$15 -> 46235 | K4: =PARAMETRES!$C$5&" — "&PARAMETRES!$C$6 -> CAFE VICTOR HUGO — Mohammedia
A6: RECETTE DU MOIS | E6: DÉPENSES DU MOIS | I6: RÉSULTAT NET | M6: MARGE NETTE
A7: =SUMIFS(JOURNAL!$H$8:$H$1007,JOURNAL!$D$8:$D$1007,"RECETTE",JOURNAL!$C$8:$C$1007,PARAMETRES!$C$14) -> 54937 | E7: =SUMIFS(JOURNAL!$H$8:$H$1007,JOURNAL!$D$8:$D$1007,"DEPENSE",JOURNAL!$C$8:$C$1007,PARAMETRES!$C$14) -> 50714 | I7: =SUMIFS(JOURNAL!$H$8:$H$1007,JOURNAL!$D$8:$D$1007,"RECETTE",JOURNAL!$C$8:$C$1007,PARAMETRES!$C$14)-SUMIFS(JOURNAL!$H$8:$H$1007,JOURNAL!$D$8:$D$1007,"DEPENSE",JOURNAL!$C$8:$C$1007,PARAMETRES!$C$14) -> 4223 | M7: =IFERROR((SUMIFS(JOURNAL!$H$8:$H$1007,JOURNAL!$D$8:$D$1007,"RECETTE",JOURNAL!$C$8:$C$1007,PARAMETRES!$C$14)-SUMIFS(JOURNAL!$H$8:$H$1007,JOURNAL!$D$8:$D$1007,"DEPENSE",JOURNAL!$C$8:$C$1007,PARAMETRES!$C$14))/SUMIFS(JOURNAL!$H$8:$H$1007,JOURNAL!$D$8:$D$1007,"RECETTE",JOURNAL!$C$8:$C$1007,PARAMETRES!$C$14),0) -> 0.076869869
A8: Total encaissé ce mois | E8: Achats, salaires, charges, virements | I8: Recette moins dépenses | M8: Part de la recette qui reste
A10: RECETTE MOYENNE / JOUR | E10: MEILLEURE JOURNÉE | I10: CAISSE EN FIN DE MOIS | M10: JOURS SAISIS
A11: =IFERROR(SUMIFS(JOURNAL!$H$8:$H$1007,JOURNAL!$D$8:$D$1007,"RECETTE",JOURNAL!$C$8:$C$1007,PARAMETRES!$C$14)/COUNTIF('RECAP JOUR'!$F$6:$F$36,">0"),0) -> 2034.7037 | E11: =IFERROR(MAX('RECAP JOUR'!$F$6:$F$36),0) -> 2456 | I11: ='RECAP JOUR'!$O$37 -> 4223 | M11: =COUNTIF('RECAP JOUR'!$F$6:$F$36,">0") -> 27
A12: Sur les jours réellement travaillés | E12: Recette la plus haute du mois | I12: Solde théorique d'espèces | M12: Jours avec une recette enregistrée
A15: ÉVOLUTION DU MOIS
A34: ANALYSE DES DÉPENSES
A58: DÉPENSES PAR CATÉGORIE | F58: PRINCIPAUX FOURNISSEURS
A59: CATÉGORIE | B59: MONTANT | C59: PART | D59: PAR JOUR | F59: FOURNISSEUR | G59: MONTANT | H59: PART | I59: NB ACHATS
A60: Boissons | B60: =SUMIFS(JOURNAL!$H$8:$H$1007,JOURNAL!$E$8:$E$1007,"Boissons",JOURNAL!$C$8:$C$1007,PARAMETRES!$C$14) -> 6566 | C60: =IFERROR($B60/$B$76,0) -> 0.12947115 | D60: =IFERROR($B60/COUNTIF('RECAP JOUR'!$F$6:$F$36,">0"),0) -> 243.18519 | F60: BIM | G60: =SUMIFS(JOURNAL!$H$8:$H$1007,JOURNAL!$F$8:$F$1007,"BIM",JOURNAL!$C$8:$C$1007,PARAMETRES!$C$14) -> 5500 | H60: =IFERROR($G60/$B$76,0) -> 0.10845132 | I60: =COUNTIFS(JOURNAL!$F$8:$F$1007,"BIM",JOURNAL!$C$8:$C$1007,PARAMETRES!$C$14) -> 22
A61: Café & Torréfaction | B61: =SUMIFS(JOURNAL!$H$8:$H$1007,JOURNAL!$E$8:$E$1007,"Café & Torréfaction",JOURNAL!$C$8:$C$1007,PARAMETRES!$C$14) -> 4910 | C61: =IFERROR($B61/$B$76,0) -> 0.096817447 | D61: =IFERROR($B61/COUNTIF('RECAP JOUR'!$F$6:$F$36,">0"),0) -> 181.85185 | F61: TAXE NADAFA 2026 | G61: =SUMIFS(JOURNAL!$H$8:$H$1007,JOURNAL!$F$8:$F$1007,"TAXE NADAFA 2026",JOURNAL!$C$8:$C$1007,PARAMETRES!$C$14) -> 5000 | H61: =IFERROR($G61/$B$76,0) -> 0.098592105 | I61: =COUNTIFS(JOURNAL!$F$8:$F$1007,"TAXE NADAFA 2026",JOURNAL!$C$8:$C$1007,PARAMETRES!$C$14) -> 1
A62: Boulangerie | B62: =SUMIFS(JOURNAL!$H$8:$H$1007,JOURNAL!$E$8:$E$1007,"Boulangerie",JOURNAL!$C$8:$C$1007,PARAMETRES!$C$14) -> 1303 | C62: =IFERROR($B62/$B$76,0) -> 0.025693102 | D62: =IFERROR($B62/COUNTIF('RECAP JOUR'!$F$6:$F$36,">0"),0) -> 48.259259 | F62: AIN SAISS | G62: =SUMIFS(JOURNAL!$H$8:$H$1007,JOURNAL!$F$8:$F$1007,"AIN SAISS",JOURNAL!$C$8:$C$1007,PARAMETRES!$C$14) -> 4956 | H62: =IFERROR($G62/$B$76,0) -> 0.097724494 | I62: =COUNTIFS(JOURNAL!$F$8:$F$1007,"AIN SAISS",JOURNAL!$C$8:$C$1007,PARAMETRES!$C$14) -> 16
A63: Fruits & Légumes | B63: =SUMIFS(JOURNAL!$H$8:$H$1007,JOURNAL!$E$8:$E$1007,"Fruits & Légumes",JOURNAL!$C$8:$C$1007,PARAMETRES!$C$14) -> 2135 | C63: =IFERROR($B63/$B$76,0) -> 0.042098829 | D63: =IFERROR($B63/COUNTIF('RECAP JOUR'!$F$6:$F$36,">0"),0) -> 79.074074 | F63: NADAFA | G63: =SUMIFS(JOURNAL!$H$8:$H$1007,JOURNAL!$F$8:$F$1007,"NADAFA",JOURNAL!$C$8:$C$1007,PARAMETRES!$C$14) -> 4050 | H63: =IFERROR($G63/$B$76,0) -> 0.079859605 | I63: =COUNTIFS(JOURNAL!$F$8:$F$1007,"NADAFA",JOURNAL!$C$8:$C$1007,PARAMETRES!$C$14) -> 27
A64: Épicerie & Divers | B64: =SUMIFS(JOURNAL!$H$8:$H$1007,JOURNAL!$E$8:$E$1007,"Épicerie & Divers",JOURNAL!$C$8:$C$1007,PARAMETRES!$C$14) -> 5565 | C64: =IFERROR($B64/$B$76,0) -> 0.10973301 | D64: =IFERROR($B64/COUNTIF('RECAP JOUR'!$F$6:$F$36,">0"),0) -> 206.11111 | F64: CAFE | G64: =SUMIFS(JOURNAL!$H$8:$H$1007,JOURNAL!$F$8:$F$1007,"CAFE",JOURNAL!$C$8:$C$1007,PARAMETRES!$C$14) -> 4000 | H64: =IFERROR($G64/$B$76,0) -> 0.078873684 | I64: =COUNTIFS(JOURNAL!$F$8:$F$1007,"CAFE",JOURNAL!$C$8:$C$1007,PARAMETRES!$C$14) -> 3
A65: Nettoyage | B65: =SUMIFS(JOURNAL!$H$8:$H$1007,JOURNAL!$E$8:$E$1007,"Nettoyage",JOURNAL!$C$8:$C$1007,PARAMETRES!$C$14) -> 4050 | C65: =IFERROR($B65/$B$76,0) -> 0.079859605 | D65: =IFERROR($B65/COUNTIF('RECAP JOUR'!$F$6:$F$36,">0"),0) -> 150 | F65: EAU + ELECTRICITE | G65: =SUMIFS(JOURNAL!$H$8:$H$1007,JOURNAL!$F$8:$F$1007,"EAU + ELECTRICITE",JOURNAL!$C$8:$C$1007,PARAMETRES!$C$14) -> 3785 | H65: =IFERROR($G65/$B$76,0) -> 0.074634223 | I65: =COUNTIFS(JOURNAL!$F$8:$F$1007,"EAU + ELECTRICITE",JOURNAL!$C$8:$C$1007,PARAMETRES!$C$14) -> 1
A66: Salaires | B66: =SUMIFS(JOURNAL!$H$8:$H$1007,JOURNAL!$E$8:$E$1007,"Salaires",JOURNAL!$C$8:$C$1007,PARAMETRES!$C$14) -> 12400 | C66: =IFERROR($B66/$B$76,0) -> 0.24450842 | D66: =IFERROR($B66/COUNTIF('RECAP JOUR'!$F$6:$F$36,">0"),0) -> 459.25926 | F66: ORANGE | G66: =SUMIFS(JOURNAL!$H$8:$H$1007,JOURNAL!$F$8:$F$1007,"ORANGE",JOURNAL!$C$8:$C$1007,PARAMETRES!$C$14) -> 1980 | H66: =IFERROR($G66/$B$76,0) -> 0.039042473 | I66: =COUNTIFS(JOURNAL!$F$8:$F$1007,"ORANGE",JOURNAL!$C$8:$C$1007,PARAMETRES!$C$14) -> 12
A67: Loyer | B67: =SUMIFS(JOURNAL!$H$8:$H$1007,JOURNAL!$E$8:$E$1007,"Loyer",JOURNAL!$C$8:$C$1007,PARAMETRES!$C$14) -> 5000 | C67: =IFERROR($B67/$B$76,0) -> 0.098592105 | D67: =IFERROR($B67/COUNTIF('RECAP JOUR'!$F$6:$F$36,">0"),0) -> 185.18519 | F67: BOULANGERIE | G67: =SUMIFS(JOURNAL!$H$8:$H$1007,JOURNAL!$F$8:$F$1007,"BOULANGERIE",JOURNAL!$C$8:$C$1007,PARAMETRES!$C$14) -> 1303 | H67: =IFERROR($G67/$B$76,0) -> 0.025693102 | I67: =COUNTIFS(JOURNAL!$F$8:$F$1007,"BOULANGERIE",JOURNAL!$C$8:$C$1007,PARAMETRES!$C$14) -> 4
A68: Eau & Électricité | B68: =SUMIFS(JOURNAL!$H$8:$H$1007,JOURNAL!$E$8:$E$1007,"Eau & Électricité",JOURNAL!$C$8:$C$1007,PARAMETRES!$C$14) -> 3785 | C68: =IFERROR($B68/$B$76,0) -> 0.074634223 | D68: =IFERROR($B68/COUNTIF('RECAP JOUR'!$F$6:$F$36,">0"),0) -> 140.18519 | F68: COCA | G68: =SUMIFS(JOURNAL!$H$8:$H$1007,JOURNAL!$F$8:$F$1007,"COCA",JOURNAL!$C$8:$C$1007,PARAMETRES!$C$14) -> 1116 | H68: =IFERROR($G68/$B$76,0) -> 0.022005758 | I68: =COUNTIFS(JOURNAL!$F$8:$F$1007,"COCA",JOURNAL!$C$8:$C$1007,PARAMETRES!$C$14) -> 2
A69: Internet & Télécom | B69: =SUMIFS(JOURNAL!$H$8:$H$1007,JOURNAL!$E$8:$E$1007,"Internet & Télécom",JOURNAL!$C$8:$C$1007,PARAMETRES!$C$14) -> 0 | C69: =IFERROR($B69/$B$76,0) -> 0 | D69: =IFERROR($B69/COUNTIF('RECAP JOUR'!$F$6:$F$36,">0"),0) -> 0 | F69: MECAFE | G69: =SUMIFS(JOURNAL!$H$8:$H$1007,JOURNAL!$F$8:$F$1007,"MECAFE",JOURNAL!$C$8:$C$1007,PARAMETRES!$C$14) -> 910 | H69: =IFERROR($G69/$B$76,0) -> 0.017943763 | I69: =COUNTIFS(JOURNAL!$F$8:$F$1007,"MECAFE",JOURNAL!$C$8:$C$1007,PARAMETRES!$C$14) -> 1
A70: Taxes & Impôts | B70: =SUMIFS(JOURNAL!$H$8:$H$1007,JOURNAL!$E$8:$E$1007,"Taxes & Impôts",JOURNAL!$C$8:$C$1007,PARAMETRES!$C$14) -> 5000 | C70: =IFERROR($B70/$B$76,0) -> 0.098592105 | D70: =IFERROR($B70/COUNTIF('RECAP JOUR'!$F$6:$F$36,">0"),0) -> 185.18519 | F70: OULMES | G70: =SUMIFS(JOURNAL!$H$8:$H$1007,JOURNAL!$F$8:$F$1007,"OULMES",JOURNAL!$C$8:$C$1007,PARAMETRES!$C$14) -> 468 | H70: =IFERROR($G70/$B$76,0) -> 0.009228221 | I70: =COUNTIFS(JOURNAL!$F$8:$F$1007,"OULMES",JOURNAL!$C$8:$C$1007,PARAMETRES!$C$14) -> 3
A71: Abonnements | B71: =SUMIFS(JOURNAL!$H$8:$H$1007,JOURNAL!$E$8:$E$1007,"Abonnements",JOURNAL!$C$8:$C$1007,PARAMETRES!$C$14) -> 0 | C71: =IFERROR($B71/$B$76,0) -> 0 | D71: =IFERROR($B71/COUNTIF('RECAP JOUR'!$F$6:$F$36,">0"),0) -> 0 | F71: FRUITS | G71: =SUMIFS(JOURNAL!$H$8:$H$1007,JOURNAL!$F$8:$F$1007,"FRUITS",JOURNAL!$C$8:$C$1007,PARAMETRES!$C$14) -> 155 | H71: =IFERROR($G71/$B$76,0) -> 0.0030563552 | I71: =COUNTIFS(JOURNAL!$F$8:$F$1007,"FRUITS",JOURNAL!$C$8:$C$1007,PARAMETRES!$C$14) -> 2
A72: Entretien & Réparation | B72: =SUMIFS(JOURNAL!$H$8:$H$1007,JOURNAL!$E$8:$E$1007,"Entretien & Réparation",JOURNAL!$C$8:$C$1007,PARAMETRES!$C$14) -> 0 | C72: =IFERROR($B72/$B$76,0) -> 0 | D72: =IFERROR($B72/COUNTIF('RECAP JOUR'!$F$6:$F$36,">0"),0) -> 0
A73: Virement Banque | B73: =SUMIFS(JOURNAL!$H$8:$H$1007,JOURNAL!$E$8:$E$1007,"Virement Banque",JOURNAL!$C$8:$C$1007,PARAMETRES!$C$14) -> 0 | C73: =IFERROR($B73/$B$76,0) -> 0 | D73: =IFERROR($B73/COUNTIF('RECAP JOUR'!$F$6:$F$36,">0"),0) -> 0
A74: Virement Associés | B74: =SUMIFS(JOURNAL!$H$8:$H$1007,JOURNAL!$E$8:$E$1007,"Virement Associés",JOURNAL!$C$8:$C$1007,PARAMETRES!$C$14) -> 0 | C74: =IFERROR($B74/$B$76,0) -> 0 | D74: =IFERROR($B74/COUNTIF('RECAP JOUR'!$F$6:$F$36,">0"),0) -> 0
A75: Divers | B75: =SUMIFS(JOURNAL!$H$8:$H$1007,JOURNAL!$E$8:$E$1007,"Divers",JOURNAL!$C$8:$C$1007,PARAMETRES!$C$14) -> 0 | C75: =IFERROR($B75/$B$76,0) -> 0 | D75: =IFERROR($B75/COUNTIF('RECAP JOUR'!$F$6:$F$36,">0"),0) -> 0
A76: TOTAL DÉPENSES | B76: =SUM($B$60:$B$75) -> 50714 | C76: =IFERROR($B76/$B76,0) -> 1 | D76: =IFERROR($B76/COUNTIF('RECAP JOUR'!$F$6:$F$36,">0"),0) -> 1878.2963
A79: Les deux tableaux ci-dessus alimentent les graphiques et se recalculent sur le mois choisi dans PARAMÈTRES. L’ordre des fournisseurs a été figé sur le poids constaté en août 2026 (données reprises de l’ancien classeur) ; les montants, eux, suivent toujours le mois en cours.

Sheet JOURNAL
A1: JOURNAL DES OPÉRATIONS
A2: Toute la vie du café se saisit ici, une ligne par opération. Le reste du classeur se met à jour tout seul.
A3: COMMENT SAISIR ▸ 1. Tapez la DATE ▸ 2. Choisissez RECETTE ou DEPENSE ▸ 3. Choisissez la CATÉGORIE et le FOURNISSEUR dans la liste ▸ 4. Tapez le MONTANT en DH. La colonne CONTRÔLE passe au vert quand la ligne est complète.
A5: Lignes saisies | C5: Total recettes | E5: Total dépenses | G5: Résultat
A6: =COUNT($B$8:$B$1007) -> 145 | C6: =SUMIF($D$8:$D$1007,"RECETTE",$H$8:$H$1007) -> 54937 | E6: =SUMIF($D$8:$D$1007,"DEPENSE",$H$8:$H$1007) -> 50714 | G6: =SUMIF($D$8:$D$1007,"RECETTE",$H$8:$H$1007)-SUMIF($D$8:$D$1007,"DEPENSE",$H$8:$H$1007) -> 4223
A7: N° | B7: DATE | C7: CLE MOIS | D7: TYPE | E7: CATÉGORIE | F7: FOURNISSEUR / BÉNÉFICIAIRE | G7: DESCRIPTION | H7: MONTANT (DH) | I7: MODE | J7: CONTROLE
A8: =IF($B8="","",ROW()-7) -> 1 | B8: 46235 | C8: =IF($B8="","",YEAR($B8)*100+MONTH($B8)) -> 202608 | D8: RECETTE | E8: Vente Caisse | F8: CLIENT | G8: Recette caisse du jour | H8: 2335 | I8: Espèce | J8: =IF($B8="","",IF(N($H8)<=0,"Montant ?",IF($D8="RECETTE",IF(COUNTIF(PARAMETRES!$E$5:$E$9,$E8)=0,"Catégorie ?","OK"),IF($D8="DEPENSE",IF(COUNTIF(PARAMETRES!$G$5:$G$20,$E8)=0,"Catégorie ?","OK"),"Type ?")))) -> OK
A9: =IF($B9="","",ROW()-7) -> 2 | B9: 46235 | C9: =IF($B9="","",YEAR($B9)*100+MONTH($B9)) -> 202608 | D9: DEPENSE | E9: Boissons | F9: AIN SAISS | G9: Achat du jour | H9: 306 | I9: Espèce | J9: =IF($B9="","",IF(N($H9)<=0,"Montant ?",IF($D9="RECETTE",IF(COUNTIF(PARAMETRES!$E$5:$E$9,$E9)=0,"Catégorie ?","OK"),IF($D9="DEPENSE",IF(COUNTIF(PARAMETRES!$G$5:$G$20,$E9)=0,"Catégorie ?","OK"),"Type ?")))) -> OK
A10: =IF($B10="","",ROW()-7) -> 3 | B10: 46235 | C10: =IF($B10="","",YEAR($B10)*100+MONTH($B10)) -> 202608 | D10: DEPENSE | E10: Épicerie & Divers | F10: BIM | G10: Achat du jour | H10: 300 | I10: Espèce | J10: =IF($B10="","",IF(N($H10)<=0,"Montant ?",IF($D10="RECETTE",IF(COUNTIF(PARAMETRES!$E$5:$E$9,$E10)=0,"Catégorie ?","OK"),IF($D10="DEPENSE",IF(COUNTIF(PARAMETRES!$G$5:$G$20,$E10)=0,"Catégorie ?","OK"),"Type ?")))) -> OK
A11: =IF($B11="","",ROW()-7) -> 4 | B11: 46235 | C11: =IF($B11="","",YEAR($B11)*100+MONTH($B11)) -> 202608 | D11: DEPENSE | E11: Fruits & Légumes | F11: ORANGE | G11: Achat du jour | H11: 165 | I11: Espèce | J11: =IF($B11="","",IF(N($H11)<=0,"Montant ?",IF($D11="RECETTE",IF(COUNTIF(PARAMETRES!$E$5:$E$9,$E11)=0,"Catégorie ?","OK"),IF($D11="DEPENSE",IF(COUNTIF(PARAMETRES!$G$5:$G$20,$E11)=0,"Catégorie ?","OK"),"Type ?")))) -> OK
A12: =IF($B12="","",ROW()-7) -> 5 | B12: 46235 | C12: =IF($B12="","",YEAR($B12)*100+MONTH($B12)) -> 202608 | D12: DEPENSE | E12: Nettoyage | F12: NADAFA | G12: Achat du jour | H12: 150 | I12: Espèce | J12: =IF($B12="","",IF(N($H12)<=0,"Montant ?",IF($D12="RECETTE",IF(COUNTIF(PARAMETRES!$E$5:$E$9,$E12)=0,"Catégorie ?","OK"),IF($D12="DEPENSE",IF(COUNTIF(PARAMETRES!$G$5:$G$20,$E12)=0,"Catégorie ?","OK"),"Type ?")))) -> OK
A13: =IF($B13="","",ROW()-7) -> 6 | B13: 46236 | C13: =IF($B13="","",YEAR($B13)*100+MONTH($B13)) -> 202608 | D13: RECETTE | E13: Vente Caisse | F13: CLIENT | G13: Recette caisse du jour | H13: 2456 | I13: Espèce | J13: =IF($B13="","",IF(N($H13)<=0,"Montant ?",IF($D13="RECETTE",IF(COUNTIF(PARAMETRES!$E$5:$E$9,$E13)=0,"Catégorie ?","OK"),IF($D13="DEPENSE",IF(COUNTIF(PARAMETRES!$G$5:$G$20,$E13)=0,"Catégorie ?","OK"),"Type ?")))) -> OK
A14: =IF($B14="","",ROW()-7) -> 7 | B14: 46236 | C14: =IF($B14="","",YEAR($B14)*100+MONTH($B14)) -> 202608 | D14: DEPENSE | E14: Boissons | F14: AIN SAISS | G14: Achat du jour | H14: 306 | I14: Espèce | J14: =IF($B14="","",IF(N($H14)<=0,"Montant ?",IF($D14="RECETTE",IF(COUNTIF(PARAMETRES!$E$5:$E$9,$E14)=0,"Catégorie ?","OK"),IF($D14="DEPENSE",IF(COUNTIF(PARAMETRES!$G$5:$G$20,$E14)=0,"Catégorie ?","OK"),"Type ?")))) -> OK
A15: =IF($B15="","",ROW()-7) -> 8 | B15: 46236 | C15: =IF($B15="","",YEAR($B15)*100+MONTH($B15)) -> 202608 | D15: DEPENSE | E15: Épicerie & Divers | F15: BIM | G15: Achat du jour | H15: 300 | I15: Espèce | J15: =IF($B15="","",IF(N($H15)<=0,"Montant ?",IF($D15="RECETTE",IF(COUNTIF(PARAMETRES!$E$5:$E$9,$E15)=0,"Catégorie ?","OK"),IF($D15="DEPENSE",IF(COUNTIF(PARAMETRES!$G$5:$G$20,$E15)=0,"Catégorie ?","OK"),"Type ?")))) -> OK
A16: =IF($B16="","",ROW()-7) -> 9 | B16: 46236 | C16: =IF($B16="","",YEAR($B16)*100+MONTH($B16)) -> 202608 | D16: DEPENSE | E16: Boissons | F16: OULMES | G16: Achat du jour | H16: 156 | I16: Espèce | J16: =IF($B16="","",IF(N($H16)<=0,"Montant ?",IF($D16="RECETTE",IF(COUNTIF(PARAMETRES!$E$5:$E$9,$E16)=0,"Catégorie ?","OK"),IF($D16="DEPENSE",IF(COUNTIF(PARAMETRES!$G$5:$G$20,$E16)=0,"Catégorie ?","OK"),"Type ?")))) -> OK
A17: =IF($B17="","",ROW()-7) -> 10 | B17: 46236 | C17: =IF($B17="","",YEAR($B17)*100+MONTH($B17)) -> 202608 | D17: DEPENSE | E17: Nettoyage | F17: NADAFA | G17: Achat du jour | H17: 150 | I17: Espèce | J17: =IF($B17="","",IF(N($H17)<=0,"Montant ?",IF($D17="RECETTE",IF(COUNTIF(PARAMETRES!$E$5:$E$9,$E17)=0,"Catégorie ?","OK"),IF($D17="DEPENSE",IF(COUNTIF(PARAMETRES!$G$5:$G$20,$E17)=0,"Catégorie ?","OK"),"Type ?")))) -> OK
A18: =IF($B18="","",ROW()-7) -> 11 | B18: 46236 | C18: =IF($B18="","",YEAR($B18)*100+MONTH($B18)) -> 202608 | D18: DEPENSE | E18: Salaires | F18: BAR MEN | G18: Salaire / avance | H18: 600 | I18: Espèce | J18: =IF($B18="","",IF(N($H18)<=0,"Montant ?",IF($D18="RECETTE",IF(COUNTIF(PARAMETRES!$E$5:$E$9,$E18)=0,"Catégorie ?","OK"),IF($D18="DEPENSE",IF(COUNTIF(PARAMETRES!$G$5:$G$20,$E18)=0,"Catégorie ?","OK"),"Type ?")))) -> OK
A19: =IF($B19="","",ROW()-7) -> 12 | B19: 46236 | C19: =IF($B19="","",YEAR($B19)*100+MONTH($B19)) -> 202608 | D19: DEPENSE | E19: Salaires | F19: BAR MEN ALI | G19: Salaire / avance | H19: 600 | I19: Espèce | J19: =IF($B19="","",IF(N($H19)<=0,"Montant ?",IF($D19="RECETTE",IF(COUNTIF(PARAMETRES!$E$5:$E$9,$E19)=0,"Catégorie ?","OK"),IF($D19="DEPENSE",IF(COUNTIF(PARAMETRES!$G$5:$G$20,$E19)=0,"Catégorie ?","OK"),"Type ?")))) -> OK
... A152: =IF($B152="","",ROW()-7) -> 145 | B152: 46261 | C152: =IF($B152="","",YEAR($B152)*100+MONTH($B152)) -> 202608 | D152: DEPENSE | E152: Épicerie & Divers | F152: BIM | G152: Achat du jour | H152: 200 | I152: Espèce | J152: =IF($B152="","",IF(N($H152)<=0,"Montant ?",IF($D152="RECETTE",IF(COUNTIF(PARAMETRES!$E$5:$E$9,$E152)=0,"Catégorie ?","OK"),IF($D152="DEPENSE",IF(COUNTIF(PARAMETRES!$G$5:$G$20,$E152)=0,"Catégorie ?","OK"),"Type ?")))) -> OK
A153: =IF($B153="","",ROW()-7) | C153: =IF($B153="","",YEAR($B153)*100+MONTH($B153)) | J153: =IF($B153="","",IF(N($H153)<=0,"Montant ?",IF($D153="RECETTE",IF(COUNTIF(PARAMETRES!$E$5:$E$9,$E153)=0,"Catégorie ?","OK"),IF($D153="DEPENSE",IF(COUNTIF(PARAMETRES!$G$5:$G$20,$E153)=0,"Catégorie ?","OK"),"Type ?"))))
A154: =IF($B154="","",ROW()-7) | C154: =IF($B154="","",YEAR($B154)*100+MONTH($B154)) | J154: =IF($B154="","",IF(N($H154)<=0,"Montant ?",IF($D154="RECETTE",IF(COUNTIF(PARAMETRES!$E$5:$E$9,$E154)=0,"Catégorie ?","OK"),IF($D154="DEPENSE",IF(COUNTIF(PARAMETRES!$G$5:$G$20,$E154)=0,"Catégorie ?","OK"),"Type ?"))))
A155: =IF($B155="","",ROW()-7) | C155: =IF($B155="","",YEAR($B155)*100+MONTH($B155)) | J155: =IF($B155="","",IF(N($H155)<=0,"Montant ?",IF($D155="RECETTE",IF(COUNTIF(PARAMETRES!$E$5:$E$9,$E155)=0,"Catégorie ?","OK"),IF($D155="DEPENSE",IF(COUNTIF(PARAMETRES!$G$5:$G$20,$E155)=0,"Catégorie ?","OK"),"Type ?"))))
A156: =IF($B156="","",ROW()-7) | C156: =IF($B156="","",YEAR($B156)*100+MONTH($B156)) | J156: =IF($B156="","",IF(N($H156)<=0,"Montant ?",IF($D156="RECETTE",IF(COUNTIF(PARAMETRES!$E$5:$E$9,$E156)=0,"Catégorie ?","OK"),IF($D156="DEPENSE",IF(COUNTIF(PARAMETRES!$G$5:$G$20,$E156)=0,"Catégorie ?","OK"),"Type ?"))))
A157: =IF($B157="","",ROW()-7) | C157: =IF($B157="","",YEAR($B157)*100+MONTH($B157)) | J157: =IF($B157="","",IF(N($H157)<=0,"Montant ?",IF($D157="RECETTE",IF(COUNTIF(PARAMETRES!$E$5:$E$9,$E157)=0,"Catégorie ?","OK"),IF($D157="DEPENSE",IF(COUNTIF(PARAMETRES!$G$5:$G$20,$E157)=0,"Catégorie ?","OK"),"Type ?"))))
A158: =IF($B158="","",ROW()-7) | C158: =IF($B158="","",YEAR($B158)*100+MONTH($B158)) | J158: =IF($B158="","",IF(N($H158)<=0,"Montant ?",IF($D158="RECETTE",IF(COUNTIF(PARAMETRES!$E$5:$E$9,$E158)=0,"Catégorie ?","OK"),IF($D158="DEPENSE",IF(COUNTIF(PARAMETRES!$G$5:$G$20,$E158)=0,"Catégorie ?","OK"),"Type ?"))))
A159: =IF($B159="","",ROW()-7) | C159: =IF($B159="","",YEAR($B159)*100+MONTH($B159)) | J159: =IF($B159="","",IF(N($H159)<=0,"Montant ?",IF($D159="RECETTE",IF(COUNTIF(PARAMETRES!$E$5:$E$9,$E159)=0,"Catégorie ?","OK"),IF($D159="DEPENSE",IF(COUNTIF(PARAMETRES!$G$5:$G$20,$E159)=0,"Catégorie ?","OK"),"Type ?"))))
A160: =IF($B160="","",ROW()-7) | C160: =IF($B160="","",YEAR($B160)*100+MONTH($B160)) | J160: =IF($B160="","",IF(N($H160)<=0,"Montant ?",IF($D160="RECETTE",IF(COUNTIF(PARAMETRES!$E$5:$E$9,$E160)=0,"Catégorie ?","OK"),IF($D160="DEPENSE",IF(COUNTIF(PARAMETRES!$G$5:$G$20,$E160)=0,"Catégorie ?","OK"),"Type ?"))))
A161: =IF($B161="","",ROW()-7) | C161: =IF($B161="","",YEAR($B161)*100+MONTH($B161)) | J161: =IF($B161="","",IF(N($H161)<=0,"Montant ?",IF($D161="RECETTE",IF(COUNTIF(PARAMETRES!$E$5:$E$9,$E161)=0,"Catégorie ?","OK"),IF($D161="DEPENSE",IF(COUNTIF(PARAMETRES!$G$5:$G$20,$E161)=0,"Catégorie ?","OK"),"Type ?"))))
A162: =IF($B162="","",ROW()-7) | C162: =IF($B162="","",YEAR($B162)*100+MONTH($B162)) | J162: =IF($B162="","",IF(N($H162)<=0,"Montant ?",IF($D162="RECETTE",IF(COUNTIF(PARAMETRES!$E$5:$E$9,$E162)=0,"Catégorie ?","OK"),IF($D162="DEPENSE",IF(COUNTIF(PARAMETRES!$G$5:$G$20,$E162)=0,"Catégorie ?","OK"),"Type ?"))))
A163: =IF($B163="","",ROW()-7) | C163: =IF($B163="","",YEAR($B163)*100+MONTH($B163)) | J163: =IF($B163="","",IF(N($H163)<=0,"Montant ?",IF($D163="RECETTE",IF(COUNTIF(PARAMETRES!$E$5:$E$9,$E163)=0,"Catégorie ?","OK"),IF($D163="DEPENSE",IF(COUNTIF(PARAMETRES!$G$5:$G$20,$E163)=0,"Catégorie ?","OK"),"Type ?"))))
A164: =IF($B164="","",ROW()-7) | C164: =IF($B164="","",YEAR($B164)*100+MONTH($B164)) | J164: =IF($B164="","",IF(N($H164)<=0,"Montant ?",IF($D164="RECETTE",IF(COUNTIF(PARAMETRES!$E$5:$E$9,$E164)=0,"Catégorie ?","OK"),IF($D164="DEPENSE",IF(COUNTIF(PARAMETRES!$G$5:$G$20,$E164)=0,"Catégorie ?","OK"),"Type ?"))))
... A1007: =IF($B1007="","",ROW()-7) | C1007: =IF($B1007="","",YEAR($B1007)*100+MONTH($B1007)) | J1007: =IF($B1007="","",IF(N($H1007)<=0,"Montant ?",IF($D1007="RECETTE",IF(COUNTIF(PARAMETRES!$E$5:$E$9,$E1007)=0,"Catégorie ?","OK"),IF($D1007="DEPENSE",IF(COUNTIF(PARAMETRES!$G$5:$G$20,$E1007)=0,"Catégorie ?","OK"),"Type ?"))))

Sheet RECAP JOUR
A1: RÉCAP JOURNALIER DU MOIS
A2: Calculé automatiquement depuis le JOURNAL. Aucune saisie ici. Changez le mois dans PARAMÈTRES pour changer la période.
A3: =PARAMETRES!$C$15 -> 46235
A5: DATE | B5: JOUR | C5: RECETTE CAISSE | D5: GLOVO ESPECE | E5: GLOVO CARTE | F5: TOTAL RECETTE | G5: ACHATS | H5: NETTOYAGE | I5: SALAIRES | J5: CHARGES FIXES | K5: VIREMENTS | L5: AUTRES | M5: TOTAL DÉPENSES | N5: RÉSULTAT DU JOUR | O5: CAISSE CUMULÉE | P5: vs OBJ.
A6: =IF(1>PARAMETRES!$C$16,"",DATE(PARAMETRES!$C$12,PARAMETRES!$C$13,1)) -> 46235 | B6: =IF($A6="","",CHOOSE(WEEKDAY($A6,2),"Lundi","Mardi","Mercredi","Jeudi","Vendredi","Samedi","Dimanche")) -> Samedi | C6: =IF($A6="","",SUMIFS(JOURNAL!$H$8:$H$1007,JOURNAL!$E$8:$E$1007,"Vente Caisse",JOURNAL!$B$8:$B$1007,$A6)+SUMIFS(JOURNAL!$H$8:$H$1007,JOURNAL!$E$8:$E$1007,"Terrasse",JOURNAL!$B$8:$B$1007,$A6)+SUMIFS(JOURNAL!$H$8:$H$1007,JOURNAL!$E$8:$E$1007,"Autre Recette",JOURNAL!$B$8:$B$1007,$A6)) -> 2335 | D6: =IF($A6="","",SUMIFS(JOURNAL!$H$8:$H$1007,JOURNAL!$E$8:$E$1007,"Glovo Espèce",JOURNAL!$B$8:$B$1007,$A6)) -> 0 | E6: =IF($A6="","",SUMIFS(JOURNAL!$H$8:$H$1007,JOURNAL!$E$8:$E$1007,"Glovo Carte",JOURNAL!$B$8:$B$1007,$A6)) -> 0 | F6: =IF($A6="","",SUM($C6:$E6)) -> 2335 | G6: =IF($A6="","",SUMIFS(JOURNAL!$H$8:$H$1007,JOURNAL!$E$8:$E$1007,"Boissons",JOURNAL!$B$8:$B$1007,$A6)+SUMIFS(JOURNAL!$H$8:$H$1007,JOURNAL!$E$8:$E$1007,"Café & Torréfaction",JOURNAL!$B$8:$B$1007,$A6)+SUMIFS(JOURNAL!$H$8:$H$1007,JOURNAL!$E$8:$E$1007,"Boulangerie",JOURNAL!$B$8:$B$1007,$A6)+SUMIFS(JOURNAL!$H$8:$H$1007,JOURNAL!$E$8:$E$1007,"Fruits & Légumes",JOURNAL!$B$8:$B$1007,$A6)+SUMIFS(JOURNAL!$H$8:$H$1007,JOURNAL!$E$8:$E$1007,"Épicerie & Divers",JOURNAL!$B$8:$B$1007,$A6)) -> 771 | H6: =IF($A6="","",SUMIFS(JOURNAL!$H$8:$H$1007,JOURNAL!$E$8:$E$1007,"Nettoyage",JOURNAL!$B$8:$B$1007,$A6)) -> 150 | I6: =IF($A6="","",SUMIFS(JOURNAL!$H$8:$H$1007,JOURNAL!$E$8:$E$1007,"Salaires",JOURNAL!$B$8:$B$1007,$A6)) -> 0 | J6: =IF($A6="","",SUMIFS(JOURNAL!$H$8:$H$1007,JOURNAL!$E$8:$E$1007,"Loyer",JOURNAL!$B$8:$B$1007,$A6)+SUMIFS(JOURNAL!$H$8:$H$1007,JOURNAL!$E$8:$E$1007,"Eau & Électricité",JOURNAL!$B$8:$B$1007,$A6)+SUMIFS(JOURNAL!$H$8:$H$1007,JOURNAL!$E$8:$E$1007,"Internet & Télécom",JOURNAL!$B$8:$B$1007,$A6)+SUMIFS(JOURNAL!$H$8:$H$1007,JOURNAL!$E$8:$E$1007,"Taxes & Impôts",JOURNAL!$B$8:$B$1007,$A6)+SUMIFS(JOURNAL!$H$8:$H$1007,JOURNAL!$E$8:$E$1007,"Abonnements",JOURNAL!$B$8:$B$1007,$A6)+SUMIFS(JOURNAL!$H$8:$H$1007,JOURNAL!$E$8:$E$1007,"Entretien & Réparation",JOURNAL!$B$8:$B$1007,$A6)) -> 0 | K6: =IF($A6="","",SUMIFS(JOURNAL!$H$8:$H$1007,JOURNAL!$E$8:$E$1007,"Virement Banque",JOURNAL!$B$8:$B$1007,$A6)+SUMIFS(JOURNAL!$H$8:$H$1007,JOURNAL!$E$8:$E$1007,"Virement Associés",JOURNAL!$B$8:$B$1007,$A6)) -> 0 | L6: =IF($A6="","",$M6-SUM($G6:$K6)) -> 0 | M6: =IF($A6="","",SUMIFS(JOURNAL!$H$8:$H$1007,JOURNAL!$D$8:$D$1007,"DEPENSE",JOURNAL!$B$8:$B$1007,$A6)) -> 921 | N6: =IF($A6="","",$F6-$M6) -> 1414 | O6: =IF($A6="","",PARAMETRES!$C$19+$N6) -> 1414 | P6: =IF($A6="","",IF($F6=0,"—",$F6-PARAMETRES!$C$20)) -> 135
A7: =IF(2>PARAMETRES!$C$16,"",DATE(PARAMETRES!$C$12,PARAMETRES!$C$13,2)) -> 46236 | B7: =IF($A7="","",CHOOSE(WEEKDAY($A7,2),"Lundi","Mardi","Mercredi","Jeudi","Vendredi","Samedi","Dimanche")) -> Dimanche | C7: =IF($A7="","",SUMIFS(JOURNAL!$H$8:$H$1007,JOURNAL!$E$8:$E$1007,"Vente Caisse",JOURNAL!$B$8:$B$1007,$A7)+SUMIFS(JOURNAL!$H$8:$H$1007,JOURNAL!$E$8:$E$1007,"Terrasse",JOURNAL!$B$8:$B$1007,$A7)+SUMIFS(JOURNAL!$H$8:$H$1007,JOURNAL!$E$8:$E$1007,"Autre Recette",JOURNAL!$B$8:$B$1007,$A7)) -> 2456 | D7: =IF($A7="","",SUMIFS(JOURNAL!$H$8:$H$1007,JOURNAL!$E$8:$E$1007,"Glovo Espèce",JOURNAL!$B$8:$B$1007,$A7)) -> 0 | E7: =IF($A7="","",SUMIFS(JOURNAL!$H$8:$H$1007,JOURNAL!$E$8:$E$1007,"Glovo Carte",JOURNAL!$B$8:$B$1007,$A7)) -> 0 | F7: =IF($A7="","",SUM($C7:$E7)) -> 2456 | G7: =IF($A7="","",SUMIFS(JOURNAL!$H$8:$H$1007,JOURNAL!$E$8:$E$1007,"Boissons",JOURNAL!$B$8:$B$1007,$A7)+SUMIFS(JOURNAL!$H$8:$H$1007,JOURNAL!$E$8:$E$1007,"Café & Torréfaction",JOURNAL!$B$8:$B$1007,$A7)+SUMIFS(JOURNAL!$H$8:$H$1007,JOURNAL!$E$8:$E$1007,"Boulangerie",JOURNAL!$B$8:$B$1007,$A7)+SUMIFS(JOURNAL!$H$8:$H$1007,JOURNAL!$E$8:$E$1007,"Fruits & Légumes",JOURNAL!$B$8:$B$1007,$A7)+SUMIFS(JOURNAL!$H$8:$H$1007,JOURNAL!$E$8:$E$1007,"Épicerie & Divers",JOURNAL!$B$8:$B$1007,$A7)) -> 762 | H7: =IF($A7="","",SUMIFS(JOURNAL!$H$8:$H$1007,JOURNAL!$E$8:$E$1007,"Nettoyage",JOURNAL!$B$8:$B$1007,$A7)) -> 150 | I7: =IF($A7="","",SUMIFS(JOURNAL!$H$8:$H$1007,JOURNAL!$E$8:$E$1007,"Salaires",JOURNAL!$B$8:$B$1007,$A7)) -> 2700 | J7: =IF($A7="","",SUMIFS(JOURNAL!$H$8:$H$1007,JOURNAL!$E$8:$E$1007,"Loyer",JOURNAL!$B$8:$B$1007,$A7)+SUMIFS(JOURNAL!$H$8:$H$1007,JOURNAL!$E$8:$E$1007,"Eau & Électricité",JOURNAL!$B$8:$B$1007,$A7)+SUMIFS(JOURNAL!$H$8:$H$1007,JOURNAL!$E$8:$E$1007,"Internet & Télécom",JOURNAL!$B$8:$B$1007,$A7)+SUMIFS(JOURNAL!$H$8:$H$1007,JOURNAL!$E$8:$E$1007,"Taxes & Impôts",JOURNAL!$B$8:$B$1007,$A7)+SUMIFS(JOURNAL!$H$8:$H$1007,JOURNAL!$E$8:$E$1007,"Abonnements",JOURNAL!$B$8:$B$1007,$A7)+SUMIFS(JOURNAL!$H$8:$H$1007,JOURNAL!$E$8:$E$1007,"Entretien & Réparation",JOURNAL!$B$8:$B$1007,$A7)) -> 0 | K7: =IF($A7="","",SUMIFS(JOURNAL!$H$8:$H$1007,JOURNAL!$E$8:$E$1007,"Virement Banque",JOURNAL!$B$8:$B$1007,$A7)+SUMIFS(JOURNAL!$H$8:$H$1007,JOURNAL!$E$8:$E$1007,"Virement Associés",JOURNAL!$B$8:$B$1007,$A7)) -> 0 | L7: =IF($A7="","",$M7-SUM($G7:$K7)) -> 0 | M7: =IF($A7="","",SUMIFS(JOURNAL!$H$8:$H$1007,JOURNAL!$D$8:$D$1007,"DEPENSE",JOURNAL!$B$8:$B$1007,$A7)) -> 3612 | N7: =IF($A7="","",$F7-$M7) -> -1156 | O7: =IF($A7="","",$O6+$N7) -> 258 | P7: =IF($A7="","",IF($F7=0,"—",$F7-PARAMETRES!$C$20)) -> 256
A8: =IF(3>PARAMETRES!$C$16,"",DATE(PARAMETRES!$C$12,PARAMETRES!$C$13,3)) -> 46237 | B8: =IF($A8="","",CHOOSE(WEEKDAY($A8,2),"Lundi","Mardi","Mercredi","Jeudi","Vendredi","Samedi","Dimanche")) -> Lundi | C8: =IF($A8="","",SUMIFS(JOURNAL!$H$8:$H$1007,JOURNAL!$E$8:$E$1007,"Vente Caisse",JOURNAL!$B$8:$B$1007,$A8)+SUMIFS(JOURNAL!$H$8:$H$1007,JOURNAL!$E$8:$E$1007,"Terrasse",JOURNAL!$B$8:$B$1007,$A8)+SUMIFS(JOURNAL!$H$8:$H$1007,JOURNAL!$E$8:$E$1007,"Autre Recette",JOURNAL!$B$8:$B$1007,$A8)) -> 2456 | D8: =IF($A8="","",SUMIFS(JOURNAL!$H$8:$H$1007,JOURNAL!$E$8:$E$1007,"Glovo Espèce",JOURNAL!$B$8:$B$1007,$A8)) -> 0 | E8: =IF($A8="","",SUMIFS(JOURNAL!$H$8:$H$1007,JOURNAL!$E$8:$E$1007,"Glovo Carte",JOURNAL!$B$8:$B$1007,$A8)) -> 0 | F8: =IF($A8="","",SUM($C8:$E8)) -> 2456 | G8: =IF($A8="","",SUMIFS(JOURNAL!$H$8:$H$1007,JOURNAL!$E$8:$E$1007,"Boissons",JOURNAL!$B$8:$B$1007,$A8)+SUMIFS(JOURNAL!$H$8:$H$1007,JOURNAL!$E$8:$E$1007,"Café & Torréfaction",JOURNAL!$B$8:$B$1007,$A8)+SUMIFS(JOURNAL!$H$8:$H$1007,JOURNAL!$E$8:$E$1007,"Boulangerie",JOURNAL!$B$8:$B$1007,$A8)+SUMIFS(JOURNAL!$H$8:$H$1007,JOURNAL!$E$8:$E$1007,"Fruits & Légumes",JOURNAL!$B$8:$B$1007,$A8)+SUMIFS(JOURNAL!$H$8:$H$1007,JOURNAL!$E$8:$E$1007,"Épicerie & Divers",JOURNAL!$B$8:$B$1007,$A8)) -> 465 | H8: =IF($A8="","",SUMIFS(JOURNAL!$H$8:$H$1007,JOURNAL!$E$8:$E$1007,"Nettoyage",JOURNAL!$B$8:$B$1007,$A8)) -> 150 | I8: =IF($A8="","",SUMIFS(JOURNAL!$H$8:$H$1007,JOURNAL!$E$8:$E$1007,"Salaires",JOURNAL!$B$8:$B$1007,$A8)) -> 0 | J8: =IF($A8="","",SUMIFS(JOURNAL!$H$8:$H$1007,JOURNAL!$E$8:$E$1007,"Loyer",JOURNAL!$B$8:$B$1007,$A8)+SUMIFS(JOURNAL!$H$8:$H$1007,JOURNAL!$E$8:$E$1007,"Eau & Électricité",JOURNAL!$B$8:$B$1007,$A8)+SUMIFS(JOURNAL!$H$8:$H$1007,JOURNAL!$E$8:$E$1007,"Internet & Télécom",JOURNAL!$B$8:$B$1007,$A8)+SUMIFS(JOURNAL!$H$8:$H$1007,JOURNAL!$E$8:$E$1007,"Taxes & Impôts",JOURNAL!$B$8:$B$1007,$A8)+SUMIFS(JOURNAL!$H$8:$H$1007,JOURNAL!$E$8:$E$1007,"Abonnements",JOURNAL!$B$8:$B$1007,$A8)+SUMIFS(JOURNAL!$H$8:$H$1007,JOURNAL!$E$8:$E$1007,"Entretien & Réparation",JOURNAL!$B$8:$B$1007,$A8)) -> 0 | K8: =IF($A8="","",SUMIFS(JOURNAL!$H$8:$H$1007,JOURNAL!$E$8:$E$1007,"Virement Banque",JOURNAL!$B$8:$B$1007,$A8)+SUMIFS(JOURNAL!$H$8:$H$1007,JOURNAL!$E$8:$E$1007,"Virement Associés",JOURNAL!$B$8:$B$1007,$A8)) -> 0 | L8: =IF($A8="","",$M8-SUM($G8:$K8)) -> 0 | M8: =IF($A8="","",SUMIFS(JOURNAL!$H$8:$H$1007,JOURNAL!$D$8:$D$1007,"DEPENSE",JOURNAL!$B$8:$B$1007,$A8)) -> 615 | N8: =IF($A8="","",$F8-$M8) -> 1841 | O8: =IF($A8="","",$O7+$N8) -> 2099 | P8: =IF($A8="","",IF($F8=0,"—",$F8-PARAMETRES!$C$20)) -> 256
A9: =IF(4>PARAMETRES!$C$16,"",DATE(PARAMETRES!$C$12,PARAMETRES!$C$13,4)) -> 46238 | B9: =IF($A9="","",CHOOSE(WEEKDAY($A9,2),"Lundi","Mardi","Mercredi","Jeudi","Vendredi","Samedi","Dimanche")) -> Mardi | C9: =IF($A9="","",SUMIFS(JOURNAL!$H$8:$H$1007,JOURNAL!$E$8:$E$1007,"Vente Caisse",JOURNAL!$B$8:$B$1007,$A9)+SUMIFS(JOURNAL!$H$8:$H$1007,JOURNAL!$E$8:$E$1007,"Terrasse",JOURNAL!$B$8:$B$1007,$A9)+SUMIFS(JOURNAL!$H$8:$H$1007,JOURNAL!$E$8:$E$1007,"Autre Recette",JOURNAL!$B$8:$B$1007,$A9)) -> 2145 | D9: =IF($A9="","",SUMIFS(JOURNAL!$H$8:$H$1007,JOURNAL!$E$8:$E$1007,"Glovo Espèce",JOURNAL!$B$8:$B$1007,$A9)) -> 0 | E9: =IF($A9="","",SUMIFS(JOURNAL!$H$8:$H$1007,JOURNAL!$E$8:$E$1007,"Glovo Carte",JOURNAL!$B$8:$B$1007,$A9)) -> 0 | F9: =IF($A9="","",SUM($C9:$E9)) -> 2145 | G9: =IF($A9="","",SUMIFS(JOURNAL!$H$8:$H$1007,JOURNAL!$E$8:$E$1007,"Boissons",JOURNAL!$B$8:$B$1007,$A9)+SUMIFS(JOURNAL!$H$8:$H$1007,JOURNAL!$E$8:$E$1007,"Café & Torréfaction",JOURNAL!$B$8:$B$1007,$A9)+SUMIFS(JOURNAL!$H$8:$H$1007,JOURNAL!$E$8:$E$1007,"Boulangerie",JOURNAL!$B$8:$B$1007,$A9)+SUMIFS(JOURNAL!$H$8:$H$1007,JOURNAL!$E$8:$E$1007,"Fruits & Légumes",JOURNAL!$B$8:$B$1007,$A9)+SUMIFS(JOURNAL!$H$8:$H$1007,JOURNAL!$E$8:$E$1007,"Épicerie & Divers",JOURNAL!$B$8:$B$1007,$A9)) -> 1416 | H9: =IF($A9="","",SUMIFS(JOURNAL!$H$8:$H$1007,JOURNAL!$E$8:$E$1007,"Nettoyage",JOURNAL!$B$8:$B$1007,$A9)) -> 150 | I9: =IF($A9="","",SUMIFS(JOURNAL!$H$8:$H$1007,JOURNAL!$E$8:$E$1007,"Salaires",JOURNAL!$B$8:$B$1007,$A9)) -> 0 | J9: =IF($A9="","",SUMIFS(JOURNAL!$H$8:$H$1007,JOURNAL!$E$8:$E$1007,"Loyer",JOURNAL!$B$8:$B$1007,$A9)+SUMIFS(JOURNAL!$H$8:$H$1007,JOURNAL!$E$8:$E$1007,"Eau & Électricité",JOURNAL!$B$8:$B$1007,$A9)+SUMIFS(JOURNAL!$H$8:$H$1007,JOURNAL!$E$8:$E$1007,"Internet & Télécom",JOURNAL!$B$8:$B$1007,$A9)+SUMIFS(JOURNAL!$H$8:$H$1007,JOURNAL!$E$8:$E$1007,"Taxes & Impôts",JOURNAL!$B$8:$B$1007,$A9)+SUMIFS(JOURNAL!$H$8:$H$1007,JOURNAL!$E$8:$E$1007,"Abonnements",JOURNAL!$B$8:$B$1007,$A9)+SUMIFS(JOURNAL!$H$8:$H$1007,JOURNAL!$E$8:$E$1007,"Entretien & Réparation",JOURNAL!$B$8:$B$1007,$A9)) -> 0 | K9: =IF($A9="","",SUMIFS(JOURNAL!$H$8:$H$1007,JOURNAL!$E$8:$E$1007,"Virement Banque",JOURNAL!$B$8:$B$1007,$A9)+SUMIFS(JOURNAL!$H$8:$H$1007,JOURNAL!$E$8:$E$1007,"Virement Associés",JOURNAL!$B$8:$B$1007,$A9)) -> 0 | L9: =IF($A9="","",$M9-SUM($G9:$K9)) -> 0 | M9: =IF($A9="","",SUMIFS(JOURNAL!$H$8:$H$1007,JOURNAL!$D$8:$D$1007,"DEPENSE",JOURNAL!$B$8:$B$1007,$A9)) -> 1566 | N9: =IF($A9="","",$F9-$M9) -> 579 | O9: =IF($A9="","",$O8+$N9) -> 2678 | P9: =IF($A9="","",IF($F9=0,"—",$F9-PARAMETRES!$C$20)) -> -55
A10: =IF(5>PARAMETRES!$C$16,"",DATE(PARAMETRES!$C$12,PARAMETRES!$C$13,5)) -> 46239 | B10: =IF($A10="","",CHOOSE(WEEKDAY($A10,2),"Lundi","Mardi","Mercredi","Jeudi","Vendredi","Samedi","Dimanche")) -> Mercredi | C10: =IF($A10="","",SUMIFS(JOURNAL!$H$8:$H$1007,JOURNAL!$E$8:$E$1007,"Vente Caisse",JOURNAL!$B$8:$B$1007,$A10)+SUMIFS(JOURNAL!$H$8:$H$1007,JOURNAL!$E$8:$E$1007,"Terrasse",JOURNAL!$B$8:$B$1007,$A10)+SUMIFS(JOURNAL!$H$8:$H$1007,JOURNAL!$E$8:$E$1007,"Autre Recette",JOURNAL!$B$8:$B$1007,$A10)) -> 2233 | D10: =IF($A10="","",SUMIFS(JOURNAL!$H$8:$H$1007,JOURNAL!$E$8:$E$1007,"Glovo Espèce",JOURNAL!$B$8:$B$1007,$A10)) -> 0 | E10: =IF($A10="","",SUMIFS(JOURNAL!$H$8:$H$1007,JOURNAL!$E$8:$E$1007,"Glovo Carte",JOURNAL!$B$8:$B$1007,$A10)) -> 0 | F10: =IF($A10="","",SUM($C10:$E10)) -> 2233 | G10: =IF($A10="","",SUMIFS(JOURNAL!$H$8:$H$1007,JOURNAL!$E$8:$E$1007,"Boissons",JOURNAL!$B$8:$B$1007,$A10)+SUMIFS(JOURNAL!$H$8:$H$1007,JOURNAL!$E$8:$E$1007,"Café & Torréfaction",JOURNAL!$B$8:$B$1007,$A10)+SUMIFS(JOURNAL!$H$8:$H$1007,JOURNAL!$E$8:$E$1007,"Boulangerie",JOURNAL!$B$8:$B$1007,$A10)+SUMIFS(JOURNAL!$H$8:$H$1007,JOURNAL!$E$8:$E$1007,"Fruits & Légumes",JOURNAL!$B$8:$B$1007,$A10)+SUMIFS(JOURNAL!$H$8:$H$1007,JOURNAL!$E$8:$E$1007,"Épicerie & Divers",JOURNAL!$B$8:$B$1007,$A10)) -> 571 | H10: =IF($A10="","",SUMIFS(JOURNAL!$H$8:$H$1007,JOURNAL!$E$8:$E$1007,"Nettoyage",JOURNAL!$B$8:$B$1007,$A10)) -> 150 | I10: =IF($A10="","",SUMIFS(JOURNAL!$H$8:$H$1007,JOURNAL!$E$8:$E$1007,"Salaires",JOURNAL!$B$8:$B$1007,$A10)) -> 0 | J10: =IF($A10="","",SUMIFS(JOURNAL!$H$8:$H$1007,JOURNAL!$E$8:$E$1007,"Loyer",JOURNAL!$B$8:$B$1007,$A10)+SUMIFS(JOURNAL!$H$8:$H$1007,JOURNAL!$E$8:$E$1007,"Eau & Électricité",JOURNAL!$B$8:$B$1007,$A10)+SUMIFS(JOURNAL!$H$8:$H$1007,JOURNAL!$E$8:$E$1007,"Internet & Télécom",JOURNAL!$B$8:$B$1007,$A10)+SUMIFS(JOURNAL!$H$8:$H$1007,JOURNAL!$E$8:$E$1007,"Taxes & Impôts",JOURNAL!$B$8:$B$1007,$A10)+SUMIFS(JOURNAL!$H$8:$H$1007,JOURNAL!$E$8:$E$1007,"Abonnements",JOURNAL!$B$8:$B$1007,$A10)+SUMIFS(JOURNAL!$H$8:$H$1007,JOURNAL!$E$8:$E$1007,"Entretien & Réparation",JOURNAL!$B$8:$B$1007,$A10)) -> 0 | K10: =IF($A10="","",SUMIFS(JOURNAL!$H$8:$H$1007,JOURNAL!$E$8:$E$1007,"Virement Banque",JOURNAL!$B$8:$B$1007,$A10)+SUMIFS(JOURNAL!$H$8:$H$1007,JOURNAL!$E$8:$E$1007,"Virement Associés",JOURNAL!$B$8:$B$1007,$A10)) -> 0 | L10: =IF($A10="","",$M10-SUM($G10:$K10)) -> 0 | M10: =IF($A10="","",SUMIFS(JOURNAL!$H$8:$H$1007,JOURNAL!$D$8:$D$1007,"DEPENSE",JOURNAL!$B$8:$B$1007,$A10)) -> 721 | N10: =IF($A10="","",$F10-$M10) -> 1512 | O10: =IF($A10="","",$O9+$N10) -> 4190 | P10: =IF($A10="","",IF($F10=0,"—",$F10-PARAMETRES!$C$20)) -> 33
A11: =IF(6>PARAMETRES!$C$16,"",DATE(PARAMETRES!$C$12,PARAMETRES!$C$13,6)) -> 46240 | B11: =IF($A11="","",CHOOSE(WEEKDAY($A11,2),"Lundi","Mardi","Mercredi","Jeudi","Vendredi","Samedi","Dimanche")) -> Jeudi | C11: =IF($A11="","",SUMIFS(JOURNAL!$H$8:$H$1007,JOURNAL!$E$8:$E$1007,"Vente Caisse",JOURNAL!$B$8:$B$1007,$A11)+SUMIFS(JOURNAL!$H$8:$H$1007,JOURNAL!$E$8:$E$1007,"Terrasse",JOURNAL!$B$8:$B$1007,$A11)+SUMIFS(JOURNAL!$H$8:$H$1007,JOURNAL!$E$8:$E$1007,"Autre Recette",JOURNAL!$B$8:$B$1007,$A11)) -> 2074 | D11: =IF($A11="","",SUMIFS(JOURNAL!$H$8:$H$1007,JOURNAL!$E$8:$E$1007,"Glovo Espèce",JOURNAL!$B$8:$B$1007,$A11)) -> 0 | E11: =IF($A11="","",SUMIFS(JOURNAL!$H$8:$H$1007,JOURNAL!$E$8:$E$1007,"Glovo Carte",JOURNAL!$B$8:$B$1007,$A11)) -> 0 | F11: =IF($A11="","",SUM($C11:$E11)) -> 2074 | G11: =IF($A11="","",SUMIFS(JOURNAL!$H$8:$H$1007,JOURNAL!$E$8:$E$1007,"Boissons",JOURNAL!$B$8:$B$1007,$A11)+SUMIFS(JOURNAL!$H$8:$H$1007,JOURNAL!$E$8:$E$1007,"Café & Torréfaction",JOURNAL!$B$8:$B$1007,$A11)+SUMIFS(JOURNAL!$H$8:$H$1007,JOURNAL!$E$8:$E$1007,"Boulangerie",JOURNAL!$B$8:$B$1007,$A11)+SUMIFS(JOURNAL!$H$8:$H$1007,JOURNAL!$E$8:$E$1007,"Fruits & Légumes",JOURNAL!$B$8:$B$1007,$A11)+SUMIFS(JOURNAL!$H$8:$H$1007,JOURNAL!$E$8:$E$1007,"Épicerie & Divers",JOURNAL!$B$8:$B$1007,$A11)) -> 591 | H11: =IF($A11="","",SUMIFS(JOURNAL!$H$8:$H$1007,JOURNAL!$E$8:$E$1007,"Nettoyage",JOURNAL!$B$8:$B$1007,$A11)) -> 150 | I11: =IF($A11="","",SUMIFS(JOURNAL!$H$8:$H$1007,JOURNAL!$E$8:$E$1007,"Salaires",JOURNAL!$B$8:$B$1007,$A11)) -> 0 | J11: =IF($A11="","",SUMIFS(JOURNAL!$H$8:$H$1007,JOURNAL!$E$8:$E$1007,"Loyer",JOURNAL!$B$8:$B$1007,$A11)+SUMIFS(JOURNAL!$H$8:$H$1007,JOURNAL!$E$8:$E$1007,"Eau & Électricité",JOURNAL!$B$8:$B$1007,$A11)+SUMIFS(JOURNAL!$H$8:$H$1007,JOURNAL!$E$8:$E$1007,"Internet & Télécom",JOURNAL!$B$8:$B$1007,$A11)+SUMIFS(JOURNAL!$H$8:$H$1007,JOURNAL!$E$8:$E$1007,"Taxes & Impôts",JOURNAL!$B$8:$B$1007,$A11)+SUMIFS(JOURNAL!$H$8:$H$1007,JOURNAL!$E$8:$E$1007,"Abonnements",JOURNAL!$B$8:$B$1007,$A11)+SUMIFS(JOURNAL!$H$8:$H$1007,JOURNAL!$E$8:$E$1007,"Entretien & Réparation",JOURNAL!$B$8:$B$1007,$A11)) -> 0 | K11: =IF($A11="","",SUMIFS(JOURNAL!$H$8:$H$1007,JOURNAL!$E$8:$E$1007,"Virement Banque",JOURNAL!$B$8:$B$1007,$A11)+SUMIFS(JOURNAL!$H$8:$H$1007,JOURNAL!$E$8:$E$1007,"Virement Associés",JOURNAL!$B$8:$B$1007,$A11)) -> 0 | L11: =IF($A11="","",$M11-SUM($G11:$K11)) -> 0 | M11: =IF($A11="","",SUMIFS(JOURNAL!$H$8:$H$1007,JOURNAL!$D$8:$D$1007,"DEPENSE",JOURNAL!$B$8:$B$1007,$A11)) -> 741 | N11: =IF($A11="","",$F11-$M11) -> 1333 | O11: =IF($A11="","",$O10+$N11) -> 5523 | P11: =IF($A11="","",IF($F11=0,"—",$F11-PARAMETRES!$C$20)) -> -126
A12: =IF(7>PARAMETRES!$C$16,"",DATE(PARAMETRES!$C$12,PARAMETRES!$C$13,7)) -> 46241 | B12: =IF($A12="","",CHOOSE(WEEKDAY($A12,2),"Lundi","Mardi","Mercredi","Jeudi","Vendredi","Samedi","Dimanche")) -> Vendredi | C12: =IF($A12="","",SUMIFS(JOURNAL!$H$8:$H$1007,JOURNAL!$E$8:$E$1007,"Vente Caisse",JOURNAL!$B$8:$B$1007,$A12)+SUMIFS(JOURNAL!$H$8:$H$1007,JOURNAL!$E$8:$E$1007,"Terrasse",JOURNAL!$B$8:$B$1007,$A12)+SUMIFS(JOURNAL!$H$8:$H$1007,JOURNAL!$E$8:$E$1007,"Autre Recette",JOURNAL!$B$8:$B$1007,$A12)) -> 1892 | D12: =IF($A12="","",SUMIFS(JOURNAL!$H$8:$H$1007,JOURNAL!$E$8:$E$1007,"Glovo Espèce",JOURNAL!$B$8:$B$1007,$A12)) -> 0 | E12: =IF($A12="","",SUMIFS(JOURNAL!$H$8:$H$1007,JOURNAL!$E$8:$E$1007,"Glovo Carte",JOURNAL!$B$8:$B$1007,$A12)) -> 0 | F12: =IF($A12="","",SUM($C12:$E12)) -> 1892 | G12: =IF($A12="","",SUMIFS(JOURNAL!$H$8:$H$1007,JOURNAL!$E$8:$E$1007,"Boissons",JOURNAL!$B$8:$B$1007,$A12)+SUMIFS(JOURNAL!$H$8:$H$1007,JOURNAL!$E$8:$E$1007,"Café & Torréfaction",JOURNAL!$B$8:$B$1007,$A12)+SUMIFS(JOURNAL!$H$8:$H$1007,JOURNAL!$E$8:$E$1007,"Boulangerie",JOURNAL!$B$8:$B$1007,$A12)+SUMIFS(JOURNAL!$H$8:$H$1007,JOURNAL!$E$8:$E$1007,"Fruits & Légumes",JOURNAL!$B$8:$B$1007,$A12)+SUMIFS(JOURNAL!$H$8:$H$1007,JOURNAL!$E$8:$E$1007,"Épicerie & Divers",JOURNAL!$B$8:$B$1007,$A12)) -> 326 | H12: =IF($A12="","",SUMIFS(JOURNAL!$H$8:$H$1007,JOURNAL!$E$8:$E$1007,"Nettoyage",JOURNAL!$B$8:$B$1007,$A12)) -> 150 | I12: =IF($A12="","",SUMIFS(JOURNAL!$H$8:$H$1007,JOURNAL!$E$8:$E$1007,"Salaires",JOURNAL!$B$8:$B$1007,$A12)) -> 0 | J12: =IF($A12="","",SUMIFS(JOURNAL!$H$8:$H$1007,JOURNAL!$E$8:$E$1007,"Loyer",JOURNAL!$B$8:$B$1007,$A12)+SUMIFS(JOURNAL!$H$8:$H$1007,JOURNAL!$E$8:$E$1007,"Eau & Électricité",JOURNAL!$B$8:$B$1007,$A12)+SUMIFS(JOURNAL!$H$8:$H$1007,JOURNAL!$E$8:$E$1007,"Internet & Télécom",JOURNAL!$B$8:$B$1007,$A12)+SUMIFS(JOURNAL!$H$8:$H$1007,JOURNAL!$E$8:$E$1007,"Taxes & Impôts",JOURNAL!$B$8:$B$1007,$A12)+SUMIFS(JOURNAL!$H$8:$H$1007,JOURNAL!$E$8:$E$1007,"Abonnements",JOURNAL!$B$8:$B$1007,$A12)+SUMIFS(JOURNAL!$H$8:$H$1007,JOURNAL!$E$8:$E$1007,"Entretien & Réparation",JOURNAL!$B$8:$B$1007,$A12)) -> 0 | K12: =IF($A12="","",SUMIFS(JOURNAL!$H$8:$H$1007,JOURNAL!$E$8:$E$1007,"Virement Banque",JOURNAL!$B$8:$B$1007,$A12)+SUMIFS(JOURNAL!$H$8:$H$1007,JOURNAL!$E$8:$E$1007,"Virement Associés",JOURNAL!$B$8:$B$1007,$A12)) -> 0 | L12: =IF($A12="","",$M12-SUM($G12:$K12)) -> 0 | M12: =IF($A12="","",SUMIFS(JOURNAL!$H$8:$H$1007,JOURNAL!$D$8:$D$1007,"DEPENSE",JOURNAL!$B$8:$B$1007,$A12)) -> 476 | N12: =IF($A12="","",$F12-$M12) -> 1416 | O12: =IF($A12="","",$O11+$N12) -> 6939 | P12: =IF($A12="","",IF($F12=0,"—",$F12-PARAMETRES!$C$20)) -> -308
A13: =IF(8>PARAMETRES!$C$16,"",DATE(PARAMETRES!$C$12,PARAMETRES!$C$13,8)) -> 46242 | B13: =IF($A13="","",CHOOSE(WEEKDAY($A13,2),"Lundi","Mardi","Mercredi","Jeudi","Vendredi","Samedi","Dimanche")) -> Samedi | C13: =IF($A13="","",SUMIFS(JOURNAL!$H$8:$H$1007,JOURNAL!$E$8:$E$1007,"Vente Caisse",JOURNAL!$B$8:$B$1007,$A13)+SUMIFS(JOURNAL!$H$8:$H$1007,JOURNAL!$E$8:$E$1007,"Terrasse",JOURNAL!$B$8:$B$1007,$A13)+SUMIFS(JOURNAL!$H$8:$H$1007,JOURNAL!$E$8:$E$1007,"Autre Recette",JOURNAL!$B$8:$B$1007,$A13)) -> 2172 | D13: =IF($A13="","",SUMIFS(JOURNAL!$H$8:$H$1007,JOURNAL!$E$8:$E$1007,"Glovo Espèce",JOURNAL!$B$8:$B$1007,$A13)) -> 0 | E13: =IF($A13="","",SUMIFS(JOURNAL!$H$8:$H$1007,JOURNAL!$E$8:$E$1007,"Glovo Carte",JOURNAL!$B$8:$B$1007,$A13)) -> 0 | F13: =IF($A13="","",SUM($C13:$E13)) -> 2172 | G13: =IF($A13="","",SUMIFS(JOURNAL!$H$8:$H$1007,JOURNAL!$E$8:$E$1007,"Boissons",JOURNAL!$B$8:$B$1007,$A13)+SUMIFS(JOURNAL!$H$8:$H$1007,JOURNAL!$E$8:$E$1007,"Café & Torréfaction",JOURNAL!$B$8:$B$1007,$A13)+SUMIFS(JOURNAL!$H$8:$H$1007,JOURNAL!$E$8:$E$1007,"Boulangerie",JOURNAL!$B$8:$B$1007,$A13)+SUMIFS(JOURNAL!$H$8:$H$1007,JOURNAL!$E$8:$E$1007,"Fruits & Légumes",JOURNAL!$B$8:$B$1007,$A13)+SUMIFS(JOURNAL!$H$8:$H$1007,JOURNAL!$E$8:$E$1007,"Épicerie & Divers",JOURNAL!$B$8:$B$1007,$A13)) -> 606 | H13: =IF($A13="","",SUMIFS(JOURNAL!$H$8:$H$1007,JOURNAL!$E$8:$E$1007,"Nettoyage",JOURNAL!$B$8:$B$1007,$A13)) -> 150 | I13: =IF($A13="","",SUMIFS(JOURNAL!$H$8:$H$1007,JOURNAL!$E$8:$E$1007,"Salaires",JOURNAL!$B$8:$B$1007,$A13)) -> 0 | J13: =IF($A13="","",SUMIFS(JOURNAL!$H$8:$H$1007,JOURNAL!$E$8:$E$1007,"Loyer",JOURNAL!$B$8:$B$1007,$A13)+SUMIFS(JOURNAL!$H$8:$H$1007,JOURNAL!$E$8:$E$1007,"Eau & Électricité",JOURNAL!$B$8:$B$1007,$A13)+SUMIFS(JOURNAL!$H$8:$H$1007,JOURNAL!$E$8:$E$1007,"Internet & Télécom",JOURNAL!$B$8:$B$1007,$A13)+SUMIFS(JOURNAL!$H$8:$H$1007,JOURNAL!$E$8:$E$1007,"Taxes & Impôts",JOURNAL!$B$8:$B$1007,$A13)+SUMIFS(JOURNAL!$H$8:$H$1007,JOURNAL!$E$8:$E$1007,"Abonnements",JOURNAL!$B$8:$B$1007,$A13)+SUMIFS(JOURNAL!$H$8:$H$1007,JOURNAL!$E$8:$E$1007,"Entretien & Réparation",JOURNAL!$B$8:$B$1007,$A13)) -> 0 | K13: =IF($A13="","",SUMIFS(JOURNAL!$H$8:$H$1007,JOURNAL!$E$8:$E$1007,"Virement Banque",JOURNAL!$B$8:$B$1007,$A13)+SUMIFS(JOURNAL!$H$8:$H$1007,JOURNAL!$E$8:$E$1007,"Virement Associés",JOURNAL!$B$8:$B$1007,$A13)) -> 0 | L13: =IF($A13="","",$M13-SUM($G13:$K13)) -> 0 | M13: =IF($A13="","",SUMIFS(JOURNAL!$H$8:$H$1007,JOURNAL!$D$8:$D$1007,"DEPENSE",JOURNAL!$B$8:$B$1007,$A13)) -> 756 | N13: =IF($A13="","",$F13-$M13) -> 1416 | O13: =IF($A13="","",$O12+$N13) -> 8355 | P13: =IF($A13="","",IF($F13=0,"—",$F13-PARAMETRES!$C$20)) -> -28
A14: =IF(9>PARAMETRES!$C$16,"",DATE(PARAMETRES!$C$12,PARAMETRES!$C$13,9)) -> 46243 | B14: =IF($A14="","",CHOOSE(WEEKDAY($A14,2),"Lundi","Mardi","Mercredi","Jeudi","Vendredi","Samedi","Dimanche")) -> Dimanche | C14: =IF($A14="","",SUMIFS(JOURNAL!$H$8:$H$1007,JOURNAL!$E$8:$E$1007,"Vente Caisse",JOURNAL!$B$8:$B$1007,$A14)+SUMIFS(JOURNAL!$H$8:$H$1007,JOURNAL!$E$8:$E$1007,"Terrasse",JOURNAL!$B$8:$B$1007,$A14)+SUMIFS(JOURNAL!$H$8:$H$1007,JOURNAL!$E$8:$E$1007,"Autre Recette",JOURNAL!$B$8:$B$1007,$A14)) -> 2218 | D14: =IF($A14="","",SUMIFS(JOURNAL!$H$8:$H$1007,JOURNAL!$E$8:$E$1007,"Glovo Espèce",JOURNAL!$B$8:$B$1007,$A14)) -> 0 | E14: =IF($A14="","",SUMIFS(JOURNAL!$H$8:$H$1007,JOURNAL!$E$8:$E$1007,"Glovo Carte",JOURNAL!$B$8:$B$1007,$A14)) -> 0 | F14: =IF($A14="","",SUM($C14:$E14)) -> 2218 | G14: =IF($A14="","",SUMIFS(JOURNAL!$H$8:$H$1007,JOURNAL!$E$8:$E$1007,"Boissons",JOURNAL!$B$8:$B$1007,$A14)+SUMIFS(JOURNAL!$H$8:$H$1007,JOURNAL!$E$8:$E$1007,"Café & Torréfaction",JOURNAL!$B$8:$B$1007,$A14)+SUMIFS(JOURNAL!$H$8:$H$1007,JOURNAL!$E$8:$E$1007,"Boulangerie",JOURNAL!$B$8:$B$1007,$A14)+SUMIFS(JOURNAL!$H$8:$H$1007,JOURNAL!$E$8:$E$1007,"Fruits & Légumes",JOURNAL!$B$8:$B$1007,$A14)+SUMIFS(JOURNAL!$H$8:$H$1007,JOURNAL!$E$8:$E$1007,"Épicerie & Divers",JOURNAL!$B$8:$B$1007,$A14)) -> 1023 | H14: =IF($A14="","",SUMIFS(JOURNAL!$H$8:$H$1007,JOURNAL!$E$8:$E$1007,"Nettoyage",JOURNAL!$B$8:$B$1007,$A14)) -> 150 | I14: =IF($A14="","",SUMIFS(JOURNAL!$H$8:$H$1007,JOURNAL!$E$8:$E$1007,"Salaires",JOURNAL!$B$8:$B$1007,$A14)) -> 2700 | J14: =IF($A14="","",SUMIFS(JOURNAL!$H$8:$H$1007,JOURNAL!$E$8:$E$1007,"Loyer",JOURNAL!$B$8:$B$1007,$A14)+SUMIFS(JOURNAL!$H$8:$H$1007,JOURNAL!$E$8:$E$1007,"Eau & Électricité",JOURNAL!$B$8:$B$1007,$A14)+SUMIFS(JOURNAL!$H$8:$H$1007,JOURNAL!$E$8:$E$1007,"Internet & Télécom",JOURNAL!$B$8:$B$1007,$A14)+SUMIFS(JOURNAL!$H$8:$H$1007,JOURNAL!$E$8:$E$1007,"Taxes & Impôts",JOURNAL!$B$8:$B$1007,$A14)+SUMIFS(JOURNAL!$H$8:$H$1007,JOURNAL!$E$8:$E$1007,"Abonnements",JOURNAL!$B$8:$B$1007,$A14)+SUMIFS(JOURNAL!$H$8:$H$1007,JOURNAL!$E$8:$E$1007,"Entretien & Réparation",JOURNAL!$B$8:$B$1007,$A14)) -> 0 | K14: =IF($A14="","",SUMIFS(JOURNAL!$H$8:$H$1007,JOURNAL!$E$8:$E$1007,"Virement Banque",JOURNAL!$B$8:$B$1007,$A14)+SUMIFS(JOURNAL!$H$8:$H$1007,JOURNAL!$E$8:$E$1007,"Virement Associés",JOURNAL!$B$8:$B$1007,$A14)) -> 0 | L14: =IF($A14="","",$M14-SUM($G14:$K14)) -> 0 | M14: =IF($A14="","",SUMIFS(JOURNAL!$H$8:$H$1007,JOURNAL!$D$8:$D$1007,"DEPENSE",JOURNAL!$B$8:$B$1007,$A14)) -> 3873 | N14: =IF($A14="","",$F14-$M14) -> -1655 | O14: =IF($A14="","",$O13+$N14) -> 6700 | P14: =IF($A14="","",IF($F14=0,"—",$F14-PARAMETRES!$C$20)) -> 18
A15: =IF(10>PARAMETRES!$C$16,"",DATE(PARAMETRES!$C$12,PARAMETRES!$C$13,10)) -> 46244 | B15: =IF($A15="","",CHOOSE(WEEKDAY($A15,2),"Lundi","Mardi","Mercredi","Jeudi","Vendredi","Samedi","Dimanche")) -> Lundi | C15: =IF($A15="","",SUMIFS(JOURNAL!$H$8:$H$1007,JOURNAL!$E$8:$E$1007,"Vente Caisse",JOURNAL!$B$8:$B$1007,$A15)+SUMIFS(JOURNAL!$H$8:$H$1007,JOURNAL!$E$8:$E$1007,"Terrasse",JOURNAL!$B$8:$B$1007,$A15)+SUMIFS(JOURNAL!$H$8:$H$1007,JOURNAL!$E$8:$E$1007,"Autre Recette",JOURNAL!$B$8:$B$1007,$A15)) -> 1548 | D15: =IF($A15="","",SUMIFS(JOURNAL!$H$8:$H$1007,JOURNAL!$E$8:$E$1007,"Glovo Espèce",JOURNAL!$B$8:$B$1007,$A15)) -> 0 | E15: =IF($A15="","",SUMIFS(JOURNAL!$H$8:$H$1007,JOURNAL!$E$8:$E$1007,"Glovo Carte",JOURNAL!$B$8:$B$1007,$A15)) -> 0 | F15: =IF($A15="","",SUM($C15:$E15)) -> 1548 | G15: =IF($A15="","",SUMIFS(JOURNAL!$H$8:$H$1007,JOURNAL!$E$8:$E$1007,"Boissons",JOURNAL!$B$8:$B$1007,$A15)+SUMIFS(JOURNAL!$H$8:$H$1007,JOURNAL!$E$8:$E$1007,"Café & Torréfaction",JOURNAL!$B$8:$B$1007,$A15)+SUMIFS(JOURNAL!$H$8:$H$1007,JOURNAL!$E$8:$E$1007,"Boulangerie",JOURNAL!$B$8:$B$1007,$A15)+SUMIFS(JOURNAL!$H$8:$H$1007,JOURNAL!$E$8:$E$1007,"Fruits & Légumes",JOURNAL!$B$8:$B$1007,$A15)+SUMIFS(JOURNAL!$H$8:$H$1007,JOURNAL!$E$8:$E$1007,"Épicerie & Divers",JOURNAL!$B$8:$B$1007,$A15)) -> 471 | H15: =IF($A15="","",SUMIFS(JOURNAL!$H$8:$H$1007,JOURNAL!$E$8:$E$1007,"Nettoyage",JOURNAL!$B$8:$B$1007,$A15)) -> 150 | I15: =IF($A15="","",SUMIFS(JOURNAL!$H$8:$H$1007,JOURNAL!$E$8:$E$1007,"Salaires",JOURNAL!$B$8:$B$1007,$A15)) -> 0 | J15: =IF($A15="","",SUMIFS(JOURNAL!$H$8:$H$1007,JOURNAL!$E$8:$E$1007,"Loyer",JOURNAL!$B$8:$B$1007,$A15)+SUMIFS(JOURNAL!$H$8:$H$1007,JOURNAL!$E$8:$E$1007,"Eau & Électricité",JOURNAL!$B$8:$B$1007,$A15)+SUMIFS(JOURNAL!$H$8:$H$1007,JOURNAL!$E$8:$E$1007,"Internet & Télécom",JOURNAL!$B$8:$B$1007,$A15)+SUMIFS(JOURNAL!$H$8:$H$1007,JOURNAL!$E$8:$E$1007,"Taxes & Impôts",JOURNAL!$B$8:$B$1007,$A15)+SUMIFS(JOURNAL!$H$8:$H$1007,JOURNAL!$E$8:$E$1007,"Abonnements",JOURNAL!$B$8:$B$1007,$A15)+SUMIFS(JOURNAL!$H$8:$H$1007,JOURNAL!$E$8:$E$1007,"Entretien & Réparation",JOURNAL!$B$8:$B$1007,$A15)) -> 0 | K15: =IF($A15="","",SUMIFS(JOURNAL!$H$8:$H$1007,JOURNAL!$E$8:$E$1007,"Virement Banque",JOURNAL!$B$8:$B$1007,$A15)+SUMIFS(JOURNAL!$H$8:$H$1007,JOURNAL!$E$8:$E$1007,"Virement Associés",JOURNAL!$B$8:$B$1007,$A15)) -> 0 | L15: =IF($A15="","",$M15-SUM($G15:$K15)) -> 0 | M15: =IF($A15="","",SUMIFS(JOURNAL!$H$8:$H$1007,JOURNAL!$D$8:$D$1007,"DEPENSE",JOURNAL!$B$8:$B$1007,$A15)) -> 621 | N15: =IF($A15="","",$F15-$M15) -> 927 | O15: =IF($A15="","",$O14+$N15) -> 7627 | P15: =IF($A15="","",IF($F15=0,"—",$F15-PARAMETRES!$C$20)) -> -652
A16: =IF(11>PARAMETRES!$C$16,"",DATE(PARAMETRES!$C$12,PARAMETRES!$C$13,11)) -> 46245 | B16: =IF($A16="","",CHOOSE(WEEKDAY($A16,2),"Lundi","Mardi","Mercredi","Jeudi","Vendredi","Samedi","Dimanche")) -> Mardi | C16: =IF($A16="","",SUMIFS(JOURNAL!$H$8:$H$1007,JOURNAL!$E$8:$E$1007,"Vente Caisse",JOURNAL!$B$8:$B$1007,$A16)+SUMIFS(JOURNAL!$H$8:$H$1007,JOURNAL!$E$8:$E$1007,"Terrasse",JOURNAL!$B$8:$B$1007,$A16)+SUMIFS(JOURNAL!$H$8:$H$1007,JOURNAL!$E$8:$E$1007,"Autre Recette",JOURNAL!$B$8:$B$1007,$A16)) -> 1973 | D16: =IF($A16="","",SUMIFS(JOURNAL!$H$8:$H$1007,JOURNAL!$E$8:$E$1007,"Glovo Espèce",JOURNAL!$B$8:$B$1007,$A16)) -> 0 | E16: =IF($A16="","",SUMIFS(JOURNAL!$H$8:$H$1007,JOURNAL!$E$8:$E$1007,"Glovo Carte",JOURNAL!$B$8:$B$1007,$A16)) -> 0 | F16: =IF($A16="","",SUM($C16:$E16)) -> 1973 | G16: =IF($A16="","",SUMIFS(JOURNAL!$H$8:$H$1007,JOURNAL!$E$8:$E$1007,"Boissons",JOURNAL!$B$8:$B$1007,$A16)+SUMIFS(JOURNAL!$H$8:$H$1007,JOURNAL!$E$8:$E$1007,"Café & Torréfaction",JOURNAL!$B$8:$B$1007,$A16)+SUMIFS(JOURNAL!$H$8:$H$1007,JOURNAL!$E$8:$E$1007,"Boulangerie",JOURNAL!$B$8:$B$1007,$A16)+SUMIFS(JOURNAL!$H$8:$H$1007,JOURNAL!$E$8:$E$1007,"Fruits & Légumes",JOURNAL!$B$8:$B$1007,$A16)+SUMIFS(JOURNAL!$H$8:$H$1007,JOURNAL!$E$8:$E$1007,"Épicerie & Divers",JOURNAL!$B$8:$B$1007,$A16)) -> 737 | H16: =IF($A16="","",SUMIFS(JOURNAL!$H$8:$H$1007,JOURNAL!$E$8:$E$1007,"Nettoyage",JOURNAL!$B$8:$B$1007,$A16)) -> 150 | I16: =IF($A16="","",SUMIFS(JOURNAL!$H$8:$H$1007,JOURNAL!$E$8:$E$1007,"Salaires",JOURNAL!$B$8:$B$1007,$A16)) -> 2000 | J16: =IF($A16="","",SUMIFS(JOURNAL!$H$8:$H$1007,JOURNAL!$E$8:$E$1007,"Loyer",JOURNAL!$B$8:$B$1007,$A16)+SUMIFS(JOURNAL!$H$8:$H$1007,JOURNAL!$E$8:$E$1007,"Eau & Électricité",JOURNAL!$B$8:$B$1007,$A16)+SUMIFS(JOURNAL!$H$8:$H$1007,JOURNAL!$E$8:$E$1007,"Internet & Télécom",JOURNAL!$B$8:$B$1007,$A16)+SUMIFS(JOURNAL!$H$8:$H$1007,JOURNAL!$E$8:$E$1007,"Taxes & Impôts",JOURNAL!$B$8:$B$1007,$A16)+SUMIFS(JOURNAL!$H$8:$H$1007,JOURNAL!$E$8:$E$1007,"Abonnements",JOURNAL!$B$8:$B$1007,$A16)+SUMIFS(JOURNAL!$H$8:$H$1007,JOURNAL!$E$8:$E$1007,"Entretien & Réparation",JOURNAL!$B$8:$B$1007,$A16)) -> 5000 | K16: =IF($A16="","",SUMIFS(JOURNAL!$H$8:$H$1007,JOURNAL!$E$8:$E$1007,"Virement Banque",JOURNAL!$B$8:$B$1007,$A16)+SUMIFS(JOURNAL!$H$8:$H$1007,JOURNAL!$E$8:$E$1007,"Virement Associés",JOURNAL!$B$8:$B$1007,$A16)) -> 0 | L16: =IF($A16="","",$M16-SUM($G16:$K16)) -> 0 | M16: =IF($A16="","",SUMIFS(JOURNAL!$H$8:$H$1007,JOURNAL!$D$8:$D$1007,"DEPENSE",JOURNAL!$B$8:$B$1007,$A16)) -> 7887 | N16: =IF($A16="","",$F16-$M16) -> -5914 | O16: =IF($A16="","",$O15+$N16) -> 1713 | P16: =IF($A16="","",IF($F16=0,"—",$F16-PARAMETRES!$C$20)) -> -227
A17: =IF(12>PARAMETRES!$C$16,"",DATE(PARAMETRES!$C$12,PARAMETRES!$C$13,12)) -> 46246 | B17: =IF($A17="","",CHOOSE(WEEKDAY($A17,2),"Lundi","Mardi","Mercredi","Jeudi","Vendredi","Samedi","Dimanche")) -> Mercredi | C17: =IF($A17="","",SUMIFS(JOURNAL!$H$8:$H$1007,JOURNAL!$E$8:$E$1007,"Vente Caisse",JOURNAL!$B$8:$B$1007,$A17)+SUMIFS(JOURNAL!$H$8:$H$1007,JOURNAL!$E$8:$E$1007,"Terrasse",JOURNAL!$B$8:$B$1007,$A17)+SUMIFS(JOURNAL!$H$8:$H$1007,JOURNAL!$E$8:$E$1007,"Autre Recette",JOURNAL!$B$8:$B$1007,$A17)) -> 2045 | D17: =IF($A17="","",SUMIFS(JOURNAL!$H$8:$H$1007,JOURNAL!$E$8:$E$1007,"Glovo Espèce",JOURNAL!$B$8:$B$1007,$A17)) -> 0 | E17: =IF($A17="","",SUMIFS(JOURNAL!$H$8:$H$1007,JOURNAL!$E$8:$E$1007,"Glovo Carte",JOURNAL!$B$8:$B$1007,$A17)) -> 0 | F17: =IF($A17="","",SUM($C17:$E17)) -> 2045 | G17: =IF($A17="","",SUMIFS(JOURNAL!$H$8:$H$1007,JOURNAL!$E$8:$E$1007,"Boissons",JOURNAL!$B$8:$B$1007,$A17)+SUMIFS(JOURNAL!$H$8:$H$1007,JOURNAL!$E$8:$E$1007,"Café & Torréfaction",JOURNAL!$B$8:$B$1007,$A17)+SUMIFS(JOURNAL!$H$8:$H$1007,JOURNAL!$E$8:$E$1007,"Boulangerie",JOURNAL!$B$8:$B$1007,$A17)+SUMIFS(JOURNAL!$H$8:$H$1007,JOURNAL!$E$8:$E$1007,"Fruits & Légumes",JOURNAL!$B$8:$B$1007,$A17)+SUMIFS(JOURNAL!$H$8:$H$1007,JOURNAL!$E$8:$E$1007,"Épicerie & Divers",JOURNAL!$B$8:$B$1007,$A17)) -> 2191 | H17: =IF($A17="","",SUMIFS(JOURNAL!$H$8:$H$1007,JOURNAL!$E$8:$E$1007,"Nettoyage",JOURNAL!$B$8:$B$1007,$A17)) -> 150 | I17: =IF($A17="","",SUMIFS(JOURNAL!$H$8:$H$1007,JOURNAL!$E$8:$E$1007,"Salaires",JOURNAL!$B$8:$B$1007,$A17)) -> 0 | J17: =IF($A17="","",SUMIFS(JOURNAL!$H$8:$H$1007,JOURNAL!$E$8:$E$1007,"Loyer",JOURNAL!$B$8:$B$1007,$A17)+SUMIFS(JOURNAL!$H$8:$H$1007,JOURNAL!$E$8:$E$1007,"Eau & Électricité",JOURNAL!$B$8:$B$1007,$A17)+SUMIFS(JOURNAL!$H$8:$H$1007,JOURNAL!$E$8:$E$1007,"Internet & Télécom",JOURNAL!$B$8:$B$1007,$A17)+SUMIFS(JOURNAL!$H$8:$H$1007,JOURNAL!$E$8:$E$1007,"Taxes & Impôts",JOURNAL!$B$8:$B$1007,$A17)+SUMIFS(JOURNAL!$H$8:$H$1007,JOURNAL!$E$8:$E$1007,"Abonnements",JOURNAL!$B$8:$B$1007,$A17)+SUMIFS(JOURNAL!$H$8:$H$1007,JOURNAL!$E$8:$E$1007,"Entretien & Réparation",JOURNAL!$B$8:$B$1007,$A17)) -> 0 | K17: =IF($A17="","",SUMIFS(JOURNAL!$H$8:$H$1007,JOURNAL!$E$8:$E$1007,"Virement Banque",JOURNAL!$B$8:$B$1007,$A17)+SUMIFS(JOURNAL!$H$8:$H$1007,JOURNAL!$E$8:$E$1007,"Virement Associés",JOURNAL!$B$8:$B$1007,$A17)) -> 0 | L17: =IF($A17="","",$M17-SUM($G17:$K17)) -> 0 | M17: =IF($A17="","",SUMIFS(JOURNAL!$H$8:$H$1007,JOURNAL!$D$8:$D$1007,"DEPENSE",JOURNAL!$B$8:$B$1007,$A17)) -> 2341 | N17: =IF($A17="","",$F17-$M17) -> -296 | O17: =IF($A17="","",$O16+$N17) -> 1417 | P17: =IF($A17="","",IF($F17=0,"—",$F17-PARAMETRES!$C$20)) -> -155
A18: =IF(13>PARAMETRES!$C$16,"",DATE(PARAMETRES!$C$12,PARAMETRES!$C$13,13)) -> 46247 | B18: =IF($A18="","",CHOOSE(WEEKDAY($A18,2),"Lundi","Mardi","Mercredi","Jeudi","Vendredi","Samedi","Dimanche")) -> Jeudi | C18: =IF($A18="","",SUMIFS(JOURNAL!$H$8:$H$1007,JOURNAL!$E$8:$E$1007,"Vente Caisse",JOURNAL!$B$8:$B$1007,$A18)+SUMIFS(JOURNAL!$H$8:$H$1007,JOURNAL!$E$8:$E$1007,"Terrasse",JOURNAL!$B$8:$B$1007,$A18)+SUMIFS(JOURNAL!$H$8:$H$1007,JOURNAL!$E$8:$E$1007,"Autre Recette",JOURNAL!$B$8:$B$1007,$A18)) -> 2014 | D18: =IF($A18="","",SUMIFS(JOURNAL!$H$8:$H$1007,JOURNAL!$E$8:$E$1007,"Glovo Espèce",JOURNAL!$B$8:$B$1007,$A18)) -> 0 | E18: =IF($A18="","",SUMIFS(JOURNAL!$H$8:$H$1007,JOURNAL!$E$8:$E$1007,"Glovo Carte",JOURNAL!$B$8:$B$1007,$A18)) -> 0 | F18: =IF($A18="","",SUM($C18:$E18)) -> 2014 | G18: =IF($A18="","",SUMIFS(JOURNAL!$H$8:$H$1007,JOURNAL!$E$8:$E$1007,"Boissons",JOURNAL!$B$8:$B$1007,$A18)+SUMIFS(JOURNAL!$H$8:$H$1007,JOURNAL!$E$8:$E$1007,"Café & Torréfaction",JOURNAL!$B$8:$B$1007,$A18)+SUMIFS(JOURNAL!$H$8:$H$1007,JOURNAL!$E$8:$E$1007,"Boulangerie",JOURNAL!$B$8:$B$1007,$A18)+SUMIFS(JOURNAL!$H$8:$H$1007,JOURNAL!$E$8:$E$1007,"Fruits & Légumes",JOURNAL!$B$8:$B$1007,$A18)+SUMIFS(JOURNAL!$H$8:$H$1007,JOURNAL!$E$8:$E$1007,"Épicerie & Divers",JOURNAL!$B$8:$B$1007,$A18)) -> 465 | H18: =IF($A18="","",SUMIFS(JOURNAL!$H$8:$H$1007,JOURNAL!$E$8:$E$1007,"Nettoyage",JOURNAL!$B$8:$B$1007,$A18)) -> 150 | I18: =IF($A18="","",SUMIFS(JOURNAL!$H$8:$H$1007,JOURNAL!$E$8:$E$1007,"Salaires",JOURNAL!$B$8:$B$1007,$A18)) -> 0 | J18: =IF($A18="","",SUMIFS(JOURNAL!$H$8:$H$1007,JOURNAL!$E$8:$E$1007,"Loyer",JOURNAL!$B$8:$B$1007,$A18)+SUMIFS(JOURNAL!$H$8:$H$1007,JOURNAL!$E$8:$E$1007,"Eau & Électricité",JOURNAL!$B$8:$B$1007,$A18)+SUMIFS(JOURNAL!$H$8:$H$1007,JOURNAL!$E$8:$E$1007,"Internet & Télécom",JOURNAL!$B$8:$B$1007,$A18)+SUMIFS(JOURNAL!$H$8:$H$1007,JOURNAL!$E$8:$E$1007,"Taxes & Impôts",JOURNAL!$B$8:$B$1007,$A18)+SUMIFS(JOURNAL!$H$8:$H$1007,JOURNAL!$E$8:$E$1007,"Abonnements",JOURNAL!$B$8:$B$1007,$A18)+SUMIFS(JOURNAL!$H$8:$H$1007,JOURNAL!$E$8:$E$1007,"Entretien & Réparation",JOURNAL!$B$8:$B$1007,$A18)) -> 0 | K18: =IF($A18="","",SUMIFS(JOURNAL!$H$8:$H$1007,JOURNAL!$E$8:$E$1007,"Virement Banque",JOURNAL!$B$8:$B$1007,$A18)+SUMIFS(JOURNAL!$H$8:$H$1007,JOURNAL!$E$8:$E$1007,"Virement Associés",JOURNAL!$B$8:$B$1007,$A18)) -> 0 | L18: =IF($A18="","",$M18-SUM($G18:$K18)) -> 0 | M18: =IF($A18="","",SUMIFS(JOURNAL!$H$8:$H$1007,JOURNAL!$D$8:$D$1007,"DEPENSE",JOURNAL!$B$8:$B$1007,$A18)) -> 615 | N18: =IF($A18="","",$F18-$M18) -> 1399 | O18: =IF($A18="","",$O17+$N18) -> 2816 | P18: =IF($A18="","",IF($F18=0,"—",$F18-PARAMETRES!$C$20)) -> -186
