Workbook

Sheet TABLEAU DE BORD
A1: TABLEAU DE BORD
A2: La photo du mois. Tout vient des feuilles jour, via le RÉCAP DU JOURNAL.
A4: ='RECAP DU JOURNAL'!$F$3 -> 46266 | K4: CAFÉ VICTOR HUGO — Mohammedia
A6: RECETTE DU MOIS | E6: DÉPENSES DU MOIS | I6: RÉSULTAT NET | M6: MARGE NETTE
A7: ='RECAP DU JOURNAL'!$F$40 -> 0 | E7: ='RECAP DU JOURNAL'!$K$40 -> 0 | I7: ='RECAP DU JOURNAL'!$F$40-'RECAP DU JOURNAL'!$K$40 -> 0 | M7: =IFERROR(('RECAP DU JOURNAL'!$F$40-'RECAP DU JOURNAL'!$K$40)/'RECAP DU JOURNAL'!$F$40,0) -> 0
A8: Total encaissé ce mois | E8: Achats, charges, salaires, virements | I8: Recette moins dépenses | M8: Part de la recette qui reste
A10: RECETTE MOYENNE / JOUR | E10: MEILLEURE JOURNÉE | I10: CAISSE EN FIN DE MOIS | M10: JOURS SAISIS
A11: =IFERROR('RECAP DU JOURNAL'!$F$40/COUNTIF('RECAP DU JOURNAL'!$F$9:$F$39,">0"),0) -> 0 | E11: =IFERROR(MAX('RECAP DU JOURNAL'!$F$9:$F$39),0) -> 0 | I11: ='RECAP DU JOURNAL'!$M$40 -> 4223 | M11: =COUNTIF('RECAP DU JOURNAL'!$F$9:$F$39,">0") -> 0
A12: Sur les jours réellement travaillés | E12: Recette la plus haute du mois | I12: Solde théorique d’espèces | M12: Jours avec une recette enregistrée
A15: ÉVOLUTION DU MOIS
A34: ANALYSE DES DÉPENSES
A54: RÉPARTITION DES DÉPENSES | F54: PRINCIPAUX FOURNISSEURS
A55: NATURE | B55: MONTANT | C55: PART | D55: PAR JOUR | F55: FOURNISSEUR | G55: MONTANT | H55: PART | I55: PAR JOUR
A56: Achats de marchandise | B56: ='RECAP DU JOURNAL'!$G$40 -> 0 | C56: =IFERROR($B56/'RECAP DU JOURNAL'!$K$40,0) -> 0 | D56: =IFERROR($B56/COUNTIF('RECAP DU JOURNAL'!$F$9:$F$39,">0"),0) -> 0 | F56: BIM | G56: =SUMIF('01'!$B$12:$B$25,$F56,'01'!$C$12:$C$25)+SUMIF('02'!$B$12:$B$25,$F56,'02'!$C$12:$C$25)+SUMIF('03'!$B$12:$B$25,$F56,'03'!$C$12:$C$25)+SUMIF('04'!$B$12:$B$25,$F56,'04'!$C$12:$C$25)+SUMIF('05'!$B$12:$B$25,$F56,'05'!$C$12:$C$25)+SUMIF('06'!$B$12:$B$25,$F56,'06'!$C$12:$C$25)+SUMIF('07'!$B$12:$B$25,$F56,'07'!$C$12:$C$25)+SUMIF('08'!$B$12:$B$25,$F56,'08'!$C$12:$C$25)+SUMIF('09'!$B$12:$B$25,$F56,'09'!$C$12:$C$25)+SUMIF('10'!$B$12:$B$25,$F56,'10'!$C$12:$C$25)+SUMIF('11'!$B$12:$B$25,$F56,'11'!$C$12:$C$25)+SUMIF('12'!$B$12:$B$25,$F56,'12'!$C$12:$C$25)+SUMIF('13'!$B$12:$B$25,$F56,'13'!$C$12:$C$25)+SUMIF('14'!$B$12:$B$25,$F56,'14'!$C$12:$C$25)+SUMIF('15'!$B$12:$B$25,$F56,'15'!$C$12:$C$25)+SUMIF('16'!$B$12:$B$25,$F56,'16'!$C$12:$C$25)+SUMIF('17'!$B$12:$B$25,$F56,'17'!$C$12:$C$25)+SUMIF('18'!$B$12:$B$25,$F56,'18'!$C$12:$C$25)+SUMIF('19'!$B$12:$B$25,$F56,'19'!$C$12:$C$25)+SUMIF('20'!$B$12:$B$25,$F56,'20'!$C$12:$C$25)+SUMIF('21'!$B$12:$B$25,$F56,'21'!$C$12:$C$25)+SUMIF('22'!$B$12:$B$25,$F56,'22'!$C$12:$C$25)+SUMIF('23'!$B$12:$B$25,$F56,'23'!$C$12:$C$25)+SUMIF('24'!$B$12:$B$25,$F56,'24'!$C$12:$C$25)+SUMIF('25'!$B$12:$B$25,$F56,'25'!$C$12:$C$25)+SUMIF('26'!$B$12:$B$25,$F56,'26'!$C$12:$C$25)+SUMIF('27'!$B$12:$B$25,$F56,'27'!$C$12:$C$25)+SUMIF('28'!$B$12:$B$25,$F56,'28'!$C$12:$C$25)+SUMIF('29'!$B$12:$B$25,$F56,'29'!$C$12:$C$25)+SUMIF('30'!$B$12:$B$25,$F56,'30'!$C$12:$C$25)+SUMIF('31'!$B$12:$B$25,$F56,'31'!$C$12:$C$25) -> 0 | H56: =IFERROR($G56/'RECAP DU JOURNAL'!$G$40,0) -> 0 | I56: =IFERROR($G56/COUNTIF('RECAP DU JOURNAL'!$F$9:$F$39,">0"),0) -> 0
A57: Charges fixes | B57: ='RECAP DU JOURNAL'!$H$40 -> 0 | C57: =IFERROR($B57/'RECAP DU JOURNAL'!$K$40,0) -> 0 | D57: =IFERROR($B57/COUNTIF('RECAP DU JOURNAL'!$F$9:$F$39,">0"),0) -> 0 | F57: AIN SAISS | G57: =SUMIF('01'!$B$12:$B$25,$F57,'01'!$C$12:$C$25)+SUMIF('02'!$B$12:$B$25,$F57,'02'!$C$12:$C$25)+SUMIF('03'!$B$12:$B$25,$F57,'03'!$C$12:$C$25)+SUMIF('04'!$B$12:$B$25,$F57,'04'!$C$12:$C$25)+SUMIF('05'!$B$12:$B$25,$F57,'05'!$C$12:$C$25)+SUMIF('06'!$B$12:$B$25,$F57,'06'!$C$12:$C$25)+SUMIF('07'!$B$12:$B$25,$F57,'07'!$C$12:$C$25)+SUMIF('08'!$B$12:$B$25,$F57,'08'!$C$12:$C$25)+SUMIF('09'!$B$12:$B$25,$F57,'09'!$C$12:$C$25)+SUMIF('10'!$B$12:$B$25,$F57,'10'!$C$12:$C$25)+SUMIF('11'!$B$12:$B$25,$F57,'11'!$C$12:$C$25)+SUMIF('12'!$B$12:$B$25,$F57,'12'!$C$12:$C$25)+SUMIF('13'!$B$12:$B$25,$F57,'13'!$C$12:$C$25)+SUMIF('14'!$B$12:$B$25,$F57,'14'!$C$12:$C$25)+SUMIF('15'!$B$12:$B$25,$F57,'15'!$C$12:$C$25)+SUMIF('16'!$B$12:$B$25,$F57,'16'!$C$12:$C$25)+SUMIF('17'!$B$12:$B$25,$F57,'17'!$C$12:$C$25)+SUMIF('18'!$B$12:$B$25,$F57,'18'!$C$12:$C$25)+SUMIF('19'!$B$12:$B$25,$F57,'19'!$C$12:$C$25)+SUMIF('20'!$B$12:$B$25,$F57,'20'!$C$12:$C$25)+SUMIF('21'!$B$12:$B$25,$F57,'21'!$C$12:$C$25)+SUMIF('22'!$B$12:$B$25,$F57,'22'!$C$12:$C$25)+SUMIF('23'!$B$12:$B$25,$F57,'23'!$C$12:$C$25)+SUMIF('24'!$B$12:$B$25,$F57,'24'!$C$12:$C$25)+SUMIF('25'!$B$12:$B$25,$F57,'25'!$C$12:$C$25)+SUMIF('26'!$B$12:$B$25,$F57,'26'!$C$12:$C$25)+SUMIF('27'!$B$12:$B$25,$F57,'27'!$C$12:$C$25)+SUMIF('28'!$B$12:$B$25,$F57,'28'!$C$12:$C$25)+SUMIF('29'!$B$12:$B$25,$F57,'29'!$C$12:$C$25)+SUMIF('30'!$B$12:$B$25,$F57,'30'!$C$12:$C$25)+SUMIF('31'!$B$12:$B$25,$F57,'31'!$C$12:$C$25) -> 0 | H57: =IFERROR($G57/'RECAP DU JOURNAL'!$G$40,0) -> 0 | I57: =IFERROR($G57/COUNTIF('RECAP DU JOURNAL'!$F$9:$F$39,">0"),0) -> 0
A58: Salaires et avances | B58: ='RECAP DU JOURNAL'!$I$40 -> 0 | C58: =IFERROR($B58/'RECAP DU JOURNAL'!$K$40,0) -> 0 | D58: =IFERROR($B58/COUNTIF('RECAP DU JOURNAL'!$F$9:$F$39,">0"),0) -> 0 | F58: NADAFA | G58: =SUMIF('01'!$B$12:$B$25,$F58,'01'!$C$12:$C$25)+SUMIF('02'!$B$12:$B$25,$F58,'02'!$C$12:$C$25)+SUMIF('03'!$B$12:$B$25,$F58,'03'!$C$12:$C$25)+SUMIF('04'!$B$12:$B$25,$F58,'04'!$C$12:$C$25)+SUMIF('05'!$B$12:$B$25,$F58,'05'!$C$12:$C$25)+SUMIF('06'!$B$12:$B$25,$F58,'06'!$C$12:$C$25)+SUMIF('07'!$B$12:$B$25,$F58,'07'!$C$12:$C$25)+SUMIF('08'!$B$12:$B$25,$F58,'08'!$C$12:$C$25)+SUMIF('09'!$B$12:$B$25,$F58,'09'!$C$12:$C$25)+SUMIF('10'!$B$12:$B$25,$F58,'10'!$C$12:$C$25)+SUMIF('11'!$B$12:$B$25,$F58,'11'!$C$12:$C$25)+SUMIF('12'!$B$12:$B$25,$F58,'12'!$C$12:$C$25)+SUMIF('13'!$B$12:$B$25,$F58,'13'!$C$12:$C$25)+SUMIF('14'!$B$12:$B$25,$F58,'14'!$C$12:$C$25)+SUMIF('15'!$B$12:$B$25,$F58,'15'!$C$12:$C$25)+SUMIF('16'!$B$12:$B$25,$F58,'16'!$C$12:$C$25)+SUMIF('17'!$B$12:$B$25,$F58,'17'!$C$12:$C$25)+SUMIF('18'!$B$12:$B$25,$F58,'18'!$C$12:$C$25)+SUMIF('19'!$B$12:$B$25,$F58,'19'!$C$12:$C$25)+SUMIF('20'!$B$12:$B$25,$F58,'20'!$C$12:$C$25)+SUMIF('21'!$B$12:$B$25,$F58,'21'!$C$12:$C$25)+SUMIF('22'!$B$12:$B$25,$F58,'22'!$C$12:$C$25)+SUMIF('23'!$B$12:$B$25,$F58,'23'!$C$12:$C$25)+SUMIF('24'!$B$12:$B$25,$F58,'24'!$C$12:$C$25)+SUMIF('25'!$B$12:$B$25,$F58,'25'!$C$12:$C$25)+SUMIF('26'!$B$12:$B$25,$F58,'26'!$C$12:$C$25)+SUMIF('27'!$B$12:$B$25,$F58,'27'!$C$12:$C$25)+SUMIF('28'!$B$12:$B$25,$F58,'28'!$C$12:$C$25)+SUMIF('29'!$B$12:$B$25,$F58,'29'!$C$12:$C$25)+SUMIF('30'!$B$12:$B$25,$F58,'30'!$C$12:$C$25)+SUMIF('31'!$B$12:$B$25,$F58,'31'!$C$12:$C$25) -> 0 | H58: =IFERROR($G58/'RECAP DU JOURNAL'!$G$40,0) -> 0 | I58: =IFERROR($G58/COUNTIF('RECAP DU JOURNAL'!$F$9:$F$39,">0"),0) -> 0
A59: Virements et divers | B59: ='RECAP DU JOURNAL'!$J$40 -> 0 | C59: =IFERROR($B59/'RECAP DU JOURNAL'!$K$40,0) -> 0 | D59: =IFERROR($B59/COUNTIF('RECAP DU JOURNAL'!$F$9:$F$39,">0"),0) -> 0 | F59: CAFE | G59: =SUMIF('01'!$B$12:$B$25,$F59,'01'!$C$12:$C$25)+SUMIF('02'!$B$12:$B$25,$F59,'02'!$C$12:$C$25)+SUMIF('03'!$B$12:$B$25,$F59,'03'!$C$12:$C$25)+SUMIF('04'!$B$12:$B$25,$F59,'04'!$C$12:$C$25)+SUMIF('05'!$B$12:$B$25,$F59,'05'!$C$12:$C$25)+SUMIF('06'!$B$12:$B$25,$F59,'06'!$C$12:$C$25)+SUMIF('07'!$B$12:$B$25,$F59,'07'!$C$12:$C$25)+SUMIF('08'!$B$12:$B$25,$F59,'08'!$C$12:$C$25)+SUMIF('09'!$B$12:$B$25,$F59,'09'!$C$12:$C$25)+SUMIF('10'!$B$12:$B$25,$F59,'10'!$C$12:$C$25)+SUMIF('11'!$B$12:$B$25,$F59,'11'!$C$12:$C$25)+SUMIF('12'!$B$12:$B$25,$F59,'12'!$C$12:$C$25)+SUMIF('13'!$B$12:$B$25,$F59,'13'!$C$12:$C$25)+SUMIF('14'!$B$12:$B$25,$F59,'14'!$C$12:$C$25)+SUMIF('15'!$B$12:$B$25,$F59,'15'!$C$12:$C$25)+SUMIF('16'!$B$12:$B$25,$F59,'16'!$C$12:$C$25)+SUMIF('17'!$B$12:$B$25,$F59,'17'!$C$12:$C$25)+SUMIF('18'!$B$12:$B$25,$F59,'18'!$C$12:$C$25)+SUMIF('19'!$B$12:$B$25,$F59,'19'!$C$12:$C$25)+SUMIF('20'!$B$12:$B$25,$F59,'20'!$C$12:$C$25)+SUMIF('21'!$B$12:$B$25,$F59,'21'!$C$12:$C$25)+SUMIF('22'!$B$12:$B$25,$F59,'22'!$C$12:$C$25)+SUMIF('23'!$B$12:$B$25,$F59,'23'!$C$12:$C$25)+SUMIF('24'!$B$12:$B$25,$F59,'24'!$C$12:$C$25)+SUMIF('25'!$B$12:$B$25,$F59,'25'!$C$12:$C$25)+SUMIF('26'!$B$12:$B$25,$F59,'26'!$C$12:$C$25)+SUMIF('27'!$B$12:$B$25,$F59,'27'!$C$12:$C$25)+SUMIF('28'!$B$12:$B$25,$F59,'28'!$C$12:$C$25)+SUMIF('29'!$B$12:$B$25,$F59,'29'!$C$12:$C$25)+SUMIF('30'!$B$12:$B$25,$F59,'30'!$C$12:$C$25)+SUMIF('31'!$B$12:$B$25,$F59,'31'!$C$12:$C$25) -> 0 | H59: =IFERROR($G59/'RECAP DU JOURNAL'!$G$40,0) -> 0 | I59: =IFERROR($G59/COUNTIF('RECAP DU JOURNAL'!$F$9:$F$39,">0"),0) -> 0
A60: TOTAL DÉPENSES | B60: =SUM($B$56:$B$59) -> 0 | C60: =IFERROR($B60/$B60,0) -> 0 | D60: =IFERROR($B60/COUNTIF('RECAP DU JOURNAL'!$F$9:$F$39,">0"),0) -> 0 | F60: ORANGE | G60: =SUMIF('01'!$B$12:$B$25,$F60,'01'!$C$12:$C$25)+SUMIF('02'!$B$12:$B$25,$F60,'02'!$C$12:$C$25)+SUMIF('03'!$B$12:$B$25,$F60,'03'!$C$12:$C$25)+SUMIF('04'!$B$12:$B$25,$F60,'04'!$C$12:$C$25)+SUMIF('05'!$B$12:$B$25,$F60,'05'!$C$12:$C$25)+SUMIF('06'!$B$12:$B$25,$F60,'06'!$C$12:$C$25)+SUMIF('07'!$B$12:$B$25,$F60,'07'!$C$12:$C$25)+SUMIF('08'!$B$12:$B$25,$F60,'08'!$C$12:$C$25)+SUMIF('09'!$B$12:$B$25,$F60,'09'!$C$12:$C$25)+SUMIF('10'!$B$12:$B$25,$F60,'10'!$C$12:$C$25)+SUMIF('11'!$B$12:$B$25,$F60,'11'!$C$12:$C$25)+SUMIF('12'!$B$12:$B$25,$F60,'12'!$C$12:$C$25)+SUMIF('13'!$B$12:$B$25,$F60,'13'!$C$12:$C$25)+SUMIF('14'!$B$12:$B$25,$F60,'14'!$C$12:$C$25)+SUMIF('15'!$B$12:$B$25,$F60,'15'!$C$12:$C$25)+SUMIF('16'!$B$12:$B$25,$F60,'16'!$C$12:$C$25)+SUMIF('17'!$B$12:$B$25,$F60,'17'!$C$12:$C$25)+SUMIF('18'!$B$12:$B$25,$F60,'18'!$C$12:$C$25)+SUMIF('19'!$B$12:$B$25,$F60,'19'!$C$12:$C$25)+SUMIF('20'!$B$12:$B$25,$F60,'20'!$C$12:$C$25)+SUMIF('21'!$B$12:$B$25,$F60,'21'!$C$12:$C$25)+SUMIF('22'!$B$12:$B$25,$F60,'22'!$C$12:$C$25)+SUMIF('23'!$B$12:$B$25,$F60,'23'!$C$12:$C$25)+SUMIF('24'!$B$12:$B$25,$F60,'24'!$C$12:$C$25)+SUMIF('25'!$B$12:$B$25,$F60,'25'!$C$12:$C$25)+SUMIF('26'!$B$12:$B$25,$F60,'26'!$C$12:$C$25)+SUMIF('27'!$B$12:$B$25,$F60,'27'!$C$12:$C$25)+SUMIF('28'!$B$12:$B$25,$F60,'28'!$C$12:$C$25)+SUMIF('29'!$B$12:$B$25,$F60,'29'!$C$12:$C$25)+SUMIF('30'!$B$12:$B$25,$F60,'30'!$C$12:$C$25)+SUMIF('31'!$B$12:$B$25,$F60,'31'!$C$12:$C$25) -> 0 | H60: =IFERROR($G60/'RECAP DU JOURNAL'!$G$40,0) -> 0 | I60: =IFERROR($G60/COUNTIF('RECAP DU JOURNAL'!$F$9:$F$39,">0"),0) -> 0
F61: BOULANGERIE | G61: =SUMIF('01'!$B$12:$B$25,$F61,'01'!$C$12:$C$25)+SUMIF('02'!$B$12:$B$25,$F61,'02'!$C$12:$C$25)+SUMIF('03'!$B$12:$B$25,$F61,'03'!$C$12:$C$25)+SUMIF('04'!$B$12:$B$25,$F61,'04'!$C$12:$C$25)+SUMIF('05'!$B$12:$B$25,$F61,'05'!$C$12:$C$25)+SUMIF('06'!$B$12:$B$25,$F61,'06'!$C$12:$C$25)+SUMIF('07'!$B$12:$B$25,$F61,'07'!$C$12:$C$25)+SUMIF('08'!$B$12:$B$25,$F61,'08'!$C$12:$C$25)+SUMIF('09'!$B$12:$B$25,$F61,'09'!$C$12:$C$25)+SUMIF('10'!$B$12:$B$25,$F61,'10'!$C$12:$C$25)+SUMIF('11'!$B$12:$B$25,$F61,'11'!$C$12:$C$25)+SUMIF('12'!$B$12:$B$25,$F61,'12'!$C$12:$C$25)+SUMIF('13'!$B$12:$B$25,$F61,'13'!$C$12:$C$25)+SUMIF('14'!$B$12:$B$25,$F61,'14'!$C$12:$C$25)+SUMIF('15'!$B$12:$B$25,$F61,'15'!$C$12:$C$25)+SUMIF('16'!$B$12:$B$25,$F61,'16'!$C$12:$C$25)+SUMIF('17'!$B$12:$B$25,$F61,'17'!$C$12:$C$25)+SUMIF('18'!$B$12:$B$25,$F61,'18'!$C$12:$C$25)+SUMIF('19'!$B$12:$B$25,$F61,'19'!$C$12:$C$25)+SUMIF('20'!$B$12:$B$25,$F61,'20'!$C$12:$C$25)+SUMIF('21'!$B$12:$B$25,$F61,'21'!$C$12:$C$25)+SUMIF('22'!$B$12:$B$25,$F61,'22'!$C$12:$C$25)+SUMIF('23'!$B$12:$B$25,$F61,'23'!$C$12:$C$25)+SUMIF('24'!$B$12:$B$25,$F61,'24'!$C$12:$C$25)+SUMIF('25'!$B$12:$B$25,$F61,'25'!$C$12:$C$25)+SUMIF('26'!$B$12:$B$25,$F61,'26'!$C$12:$C$25)+SUMIF('27'!$B$12:$B$25,$F61,'27'!$C$12:$C$25)+SUMIF('28'!$B$12:$B$25,$F61,'28'!$C$12:$C$25)+SUMIF('29'!$B$12:$B$25,$F61,'29'!$C$12:$C$25)+SUMIF('30'!$B$12:$B$25,$F61,'30'!$C$12:$C$25)+SUMIF('31'!$B$12:$B$25,$F61,'31'!$C$12:$C$25) -> 0 | H61: =IFERROR($G61/'RECAP DU JOURNAL'!$G$40,0) -> 0 | I61: =IFERROR($G61/COUNTIF('RECAP DU JOURNAL'!$F$9:$F$39,">0"),0) -> 0
F62: COCA | G62: =SUMIF('01'!$B$12:$B$25,$F62,'01'!$C$12:$C$25)+SUMIF('02'!$B$12:$B$25,$F62,'02'!$C$12:$C$25)+SUMIF('03'!$B$12:$B$25,$F62,'03'!$C$12:$C$25)+SUMIF('04'!$B$12:$B$25,$F62,'04'!$C$12:$C$25)+SUMIF('05'!$B$12:$B$25,$F62,'05'!$C$12:$C$25)+SUMIF('06'!$B$12:$B$25,$F62,'06'!$C$12:$C$25)+SUMIF('07'!$B$12:$B$25,$F62,'07'!$C$12:$C$25)+SUMIF('08'!$B$12:$B$25,$F62,'08'!$C$12:$C$25)+SUMIF('09'!$B$12:$B$25,$F62,'09'!$C$12:$C$25)+SUMIF('10'!$B$12:$B$25,$F62,'10'!$C$12:$C$25)+SUMIF('11'!$B$12:$B$25,$F62,'11'!$C$12:$C$25)+SUMIF('12'!$B$12:$B$25,$F62,'12'!$C$12:$C$25)+SUMIF('13'!$B$12:$B$25,$F62,'13'!$C$12:$C$25)+SUMIF('14'!$B$12:$B$25,$F62,'14'!$C$12:$C$25)+SUMIF('15'!$B$12:$B$25,$F62,'15'!$C$12:$C$25)+SUMIF('16'!$B$12:$B$25,$F62,'16'!$C$12:$C$25)+SUMIF('17'!$B$12:$B$25,$F62,'17'!$C$12:$C$25)+SUMIF('18'!$B$12:$B$25,$F62,'18'!$C$12:$C$25)+SUMIF('19'!$B$12:$B$25,$F62,'19'!$C$12:$C$25)+SUMIF('20'!$B$12:$B$25,$F62,'20'!$C$12:$C$25)+SUMIF('21'!$B$12:$B$25,$F62,'21'!$C$12:$C$25)+SUMIF('22'!$B$12:$B$25,$F62,'22'!$C$12:$C$25)+SUMIF('23'!$B$12:$B$25,$F62,'23'!$C$12:$C$25)+SUMIF('24'!$B$12:$B$25,$F62,'24'!$C$12:$C$25)+SUMIF('25'!$B$12:$B$25,$F62,'25'!$C$12:$C$25)+SUMIF('26'!$B$12:$B$25,$F62,'26'!$C$12:$C$25)+SUMIF('27'!$B$12:$B$25,$F62,'27'!$C$12:$C$25)+SUMIF('28'!$B$12:$B$25,$F62,'28'!$C$12:$C$25)+SUMIF('29'!$B$12:$B$25,$F62,'29'!$C$12:$C$25)+SUMIF('30'!$B$12:$B$25,$F62,'30'!$C$12:$C$25)+SUMIF('31'!$B$12:$B$25,$F62,'31'!$C$12:$C$25) -> 0 | H62: =IFERROR($G62/'RECAP DU JOURNAL'!$G$40,0) -> 0 | I62: =IFERROR($G62/COUNTIF('RECAP DU JOURNAL'!$F$9:$F$39,">0"),0) -> 0
F63: MECAFE | G63: =SUMIF('01'!$B$12:$B$25,$F63,'01'!$C$12:$C$25)+SUMIF('02'!$B$12:$B$25,$F63,'02'!$C$12:$C$25)+SUMIF('03'!$B$12:$B$25,$F63,'03'!$C$12:$C$25)+SUMIF('04'!$B$12:$B$25,$F63,'04'!$C$12:$C$25)+SUMIF('05'!$B$12:$B$25,$F63,'05'!$C$12:$C$25)+SUMIF('06'!$B$12:$B$25,$F63,'06'!$C$12:$C$25)+SUMIF('07'!$B$12:$B$25,$F63,'07'!$C$12:$C$25)+SUMIF('08'!$B$12:$B$25,$F63,'08'!$C$12:$C$25)+SUMIF('09'!$B$12:$B$25,$F63,'09'!$C$12:$C$25)+SUMIF('10'!$B$12:$B$25,$F63,'10'!$C$12:$C$25)+SUMIF('11'!$B$12:$B$25,$F63,'11'!$C$12:$C$25)+SUMIF('12'!$B$12:$B$25,$F63,'12'!$C$12:$C$25)+SUMIF('13'!$B$12:$B$25,$F63,'13'!$C$12:$C$25)+SUMIF('14'!$B$12:$B$25,$F63,'14'!$C$12:$C$25)+SUMIF('15'!$B$12:$B$25,$F63,'15'!$C$12:$C$25)+SUMIF('16'!$B$12:$B$25,$F63,'16'!$C$12:$C$25)+SUMIF('17'!$B$12:$B$25,$F63,'17'!$C$12:$C$25)+SUMIF('18'!$B$12:$B$25,$F63,'18'!$C$12:$C$25)+SUMIF('19'!$B$12:$B$25,$F63,'19'!$C$12:$C$25)+SUMIF('20'!$B$12:$B$25,$F63,'20'!$C$12:$C$25)+SUMIF('21'!$B$12:$B$25,$F63,'21'!$C$12:$C$25)+SUMIF('22'!$B$12:$B$25,$F63,'22'!$C$12:$C$25)+SUMIF('23'!$B$12:$B$25,$F63,'23'!$C$12:$C$25)+SUMIF('24'!$B$12:$B$25,$F63,'24'!$C$12:$C$25)+SUMIF('25'!$B$12:$B$25,$F63,'25'!$C$12:$C$25)+SUMIF('26'!$B$12:$B$25,$F63,'26'!$C$12:$C$25)+SUMIF('27'!$B$12:$B$25,$F63,'27'!$C$12:$C$25)+SUMIF('28'!$B$12:$B$25,$F63,'28'!$C$12:$C$25)+SUMIF('29'!$B$12:$B$25,$F63,'29'!$C$12:$C$25)+SUMIF('30'!$B$12:$B$25,$F63,'30'!$C$12:$C$25)+SUMIF('31'!$B$12:$B$25,$F63,'31'!$C$12:$C$25) -> 0 | H63: =IFERROR($G63/'RECAP DU JOURNAL'!$G$40,0) -> 0 | I63: =IFERROR($G63/COUNTIF('RECAP DU JOURNAL'!$F$9:$F$39,">0"),0) -> 0
F64: OULMES | G64: =SUMIF('01'!$B$12:$B$25,$F64,'01'!$C$12:$C$25)+SUMIF('02'!$B$12:$B$25,$F64,'02'!$C$12:$C$25)+SUMIF('03'!$B$12:$B$25,$F64,'03'!$C$12:$C$25)+SUMIF('04'!$B$12:$B$25,$F64,'04'!$C$12:$C$25)+SUMIF('05'!$B$12:$B$25,$F64,'05'!$C$12:$C$25)+SUMIF('06'!$B$12:$B$25,$F64,'06'!$C$12:$C$25)+SUMIF('07'!$B$12:$B$25,$F64,'07'!$C$12:$C$25)+SUMIF('08'!$B$12:$B$25,$F64,'08'!$C$12:$C$25)+SUMIF('09'!$B$12:$B$25,$F64,'09'!$C$12:$C$25)+SUMIF('10'!$B$12:$B$25,$F64,'10'!$C$12:$C$25)+SUMIF('11'!$B$12:$B$25,$F64,'11'!$C$12:$C$25)+SUMIF('12'!$B$12:$B$25,$F64,'12'!$C$12:$C$25)+SUMIF('13'!$B$12:$B$25,$F64,'13'!$C$12:$C$25)+SUMIF('14'!$B$12:$B$25,$F64,'14'!$C$12:$C$25)+SUMIF('15'!$B$12:$B$25,$F64,'15'!$C$12:$C$25)+SUMIF('16'!$B$12:$B$25,$F64,'16'!$C$12:$C$25)+SUMIF('17'!$B$12:$B$25,$F64,'17'!$C$12:$C$25)+SUMIF('18'!$B$12:$B$25,$F64,'18'!$C$12:$C$25)+SUMIF('19'!$B$12:$B$25,$F64,'19'!$C$12:$C$25)+SUMIF('20'!$B$12:$B$25,$F64,'20'!$C$12:$C$25)+SUMIF('21'!$B$12:$B$25,$F64,'21'!$C$12:$C$25)+SUMIF('22'!$B$12:$B$25,$F64,'22'!$C$12:$C$25)+SUMIF('23'!$B$12:$B$25,$F64,'23'!$C$12:$C$25)+SUMIF('24'!$B$12:$B$25,$F64,'24'!$C$12:$C$25)+SUMIF('25'!$B$12:$B$25,$F64,'25'!$C$12:$C$25)+SUMIF('26'!$B$12:$B$25,$F64,'26'!$C$12:$C$25)+SUMIF('27'!$B$12:$B$25,$F64,'27'!$C$12:$C$25)+SUMIF('28'!$B$12:$B$25,$F64,'28'!$C$12:$C$25)+SUMIF('29'!$B$12:$B$25,$F64,'29'!$C$12:$C$25)+SUMIF('30'!$B$12:$B$25,$F64,'30'!$C$12:$C$25)+SUMIF('31'!$B$12:$B$25,$F64,'31'!$C$12:$C$25) -> 0 | H64: =IFERROR($G64/'RECAP DU JOURNAL'!$G$40,0) -> 0 | I64: =IFERROR($G64/COUNTIF('RECAP DU JOURNAL'!$F$9:$F$39,">0"),0) -> 0
F65: FRUITS | G65: =SUMIF('01'!$B$12:$B$25,$F65,'01'!$C$12:$C$25)+SUMIF('02'!$B$12:$B$25,$F65,'02'!$C$12:$C$25)+SUMIF('03'!$B$12:$B$25,$F65,'03'!$C$12:$C$25)+SUMIF('04'!$B$12:$B$25,$F65,'04'!$C$12:$C$25)+SUMIF('05'!$B$12:$B$25,$F65,'05'!$C$12:$C$25)+SUMIF('06'!$B$12:$B$25,$F65,'06'!$C$12:$C$25)+SUMIF('07'!$B$12:$B$25,$F65,'07'!$C$12:$C$25)+SUMIF('08'!$B$12:$B$25,$F65,'08'!$C$12:$C$25)+SUMIF('09'!$B$12:$B$25,$F65,'09'!$C$12:$C$25)+SUMIF('10'!$B$12:$B$25,$F65,'10'!$C$12:$C$25)+SUMIF('11'!$B$12:$B$25,$F65,'11'!$C$12:$C$25)+SUMIF('12'!$B$12:$B$25,$F65,'12'!$C$12:$C$25)+SUMIF('13'!$B$12:$B$25,$F65,'13'!$C$12:$C$25)+SUMIF('14'!$B$12:$B$25,$F65,'14'!$C$12:$C$25)+SUMIF('15'!$B$12:$B$25,$F65,'15'!$C$12:$C$25)+SUMIF('16'!$B$12:$B$25,$F65,'16'!$C$12:$C$25)+SUMIF('17'!$B$12:$B$25,$F65,'17'!$C$12:$C$25)+SUMIF('18'!$B$12:$B$25,$F65,'18'!$C$12:$C$25)+SUMIF('19'!$B$12:$B$25,$F65,'19'!$C$12:$C$25)+SUMIF('20'!$B$12:$B$25,$F65,'20'!$C$12:$C$25)+SUMIF('21'!$B$12:$B$25,$F65,'21'!$C$12:$C$25)+SUMIF('22'!$B$12:$B$25,$F65,'22'!$C$12:$C$25)+SUMIF('23'!$B$12:$B$25,$F65,'23'!$C$12:$C$25)+SUMIF('24'!$B$12:$B$25,$F65,'24'!$C$12:$C$25)+SUMIF('25'!$B$12:$B$25,$F65,'25'!$C$12:$C$25)+SUMIF('26'!$B$12:$B$25,$F65,'26'!$C$12:$C$25)+SUMIF('27'!$B$12:$B$25,$F65,'27'!$C$12:$C$25)+SUMIF('28'!$B$12:$B$25,$F65,'28'!$C$12:$C$25)+SUMIF('29'!$B$12:$B$25,$F65,'29'!$C$12:$C$25)+SUMIF('30'!$B$12:$B$25,$F65,'30'!$C$12:$C$25)+SUMIF('31'!$B$12:$B$25,$F65,'31'!$C$12:$C$25) -> 0 | H65: =IFERROR($G65/'RECAP DU JOURNAL'!$G$40,0) -> 0 | I65: =IFERROR($G65/COUNTIF('RECAP DU JOURNAL'!$F$9:$F$39,">0"),0) -> 0
F66: KHLII | G66: =SUMIF('01'!$B$12:$B$25,$F66,'01'!$C$12:$C$25)+SUMIF('02'!$B$12:$B$25,$F66,'02'!$C$12:$C$25)+SUMIF('03'!$B$12:$B$25,$F66,'03'!$C$12:$C$25)+SUMIF('04'!$B$12:$B$25,$F66,'04'!$C$12:$C$25)+SUMIF('05'!$B$12:$B$25,$F66,'05'!$C$12:$C$25)+SUMIF('06'!$B$12:$B$25,$F66,'06'!$C$12:$C$25)+SUMIF('07'!$B$12:$B$25,$F66,'07'!$C$12:$C$25)+SUMIF('08'!$B$12:$B$25,$F66,'08'!$C$12:$C$25)+SUMIF('09'!$B$12:$B$25,$F66,'09'!$C$12:$C$25)+SUMIF('10'!$B$12:$B$25,$F66,'10'!$C$12:$C$25)+SUMIF('11'!$B$12:$B$25,$F66,'11'!$C$12:$C$25)+SUMIF('12'!$B$12:$B$25,$F66,'12'!$C$12:$C$25)+SUMIF('13'!$B$12:$B$25,$F66,'13'!$C$12:$C$25)+SUMIF('14'!$B$12:$B$25,$F66,'14'!$C$12:$C$25)+SUMIF('15'!$B$12:$B$25,$F66,'15'!$C$12:$C$25)+SUMIF('16'!$B$12:$B$25,$F66,'16'!$C$12:$C$25)+SUMIF('17'!$B$12:$B$25,$F66,'17'!$C$12:$C$25)+SUMIF('18'!$B$12:$B$25,$F66,'18'!$C$12:$C$25)+SUMIF('19'!$B$12:$B$25,$F66,'19'!$C$12:$C$25)+SUMIF('20'!$B$12:$B$25,$F66,'20'!$C$12:$C$25)+SUMIF('21'!$B$12:$B$25,$F66,'21'!$C$12:$C$25)+SUMIF('22'!$B$12:$B$25,$F66,'22'!$C$12:$C$25)+SUMIF('23'!$B$12:$B$25,$F66,'23'!$C$12:$C$25)+SUMIF('24'!$B$12:$B$25,$F66,'24'!$C$12:$C$25)+SUMIF('25'!$B$12:$B$25,$F66,'25'!$C$12:$C$25)+SUMIF('26'!$B$12:$B$25,$F66,'26'!$C$12:$C$25)+SUMIF('27'!$B$12:$B$25,$F66,'27'!$C$12:$C$25)+SUMIF('28'!$B$12:$B$25,$F66,'28'!$C$12:$C$25)+SUMIF('29'!$B$12:$B$25,$F66,'29'!$C$12:$C$25)+SUMIF('30'!$B$12:$B$25,$F66,'30'!$C$12:$C$25)+SUMIF('31'!$B$12:$B$25,$F66,'31'!$C$12:$C$25) -> 0 | H66: =IFERROR($G66/'RECAP DU JOURNAL'!$G$40,0) -> 0 | I66: =IFERROR($G66/COUNTIF('RECAP DU JOURNAL'!$F$9:$F$39,">0"),0) -> 0
F67: CITRIN | G67: =SUMIF('01'!$B$12:$B$25,$F67,'01'!$C$12:$C$25)+SUMIF('02'!$B$12:$B$25,$F67,'02'!$C$12:$C$25)+SUMIF('03'!$B$12:$B$25,$F67,'03'!$C$12:$C$25)+SUMIF('04'!$B$12:$B$25,$F67,'04'!$C$12:$C$25)+SUMIF('05'!$B$12:$B$25,$F67,'05'!$C$12:$C$25)+SUMIF('06'!$B$12:$B$25,$F67,'06'!$C$12:$C$25)+SUMIF('07'!$B$12:$B$25,$F67,'07'!$C$12:$C$25)+SUMIF('08'!$B$12:$B$25,$F67,'08'!$C$12:$C$25)+SUMIF('09'!$B$12:$B$25,$F67,'09'!$C$12:$C$25)+SUMIF('10'!$B$12:$B$25,$F67,'10'!$C$12:$C$25)+SUMIF('11'!$B$12:$B$25,$F67,'11'!$C$12:$C$25)+SUMIF('12'!$B$12:$B$25,$F67,'12'!$C$12:$C$25)+SUMIF('13'!$B$12:$B$25,$F67,'13'!$C$12:$C$25)+SUMIF('14'!$B$12:$B$25,$F67,'14'!$C$12:$C$25)+SUMIF('15'!$B$12:$B$25,$F67,'15'!$C$12:$C$25)+SUMIF('16'!$B$12:$B$25,$F67,'16'!$C$12:$C$25)+SUMIF('17'!$B$12:$B$25,$F67,'17'!$C$12:$C$25)+SUMIF('18'!$B$12:$B$25,$F67,'18'!$C$12:$C$25)+SUMIF('19'!$B$12:$B$25,$F67,'19'!$C$12:$C$25)+SUMIF('20'!$B$12:$B$25,$F67,'20'!$C$12:$C$25)+SUMIF('21'!$B$12:$B$25,$F67,'21'!$C$12:$C$25)+SUMIF('22'!$B$12:$B$25,$F67,'22'!$C$12:$C$25)+SUMIF('23'!$B$12:$B$25,$F67,'23'!$C$12:$C$25)+SUMIF('24'!$B$12:$B$25,$F67,'24'!$C$12:$C$25)+SUMIF('25'!$B$12:$B$25,$F67,'25'!$C$12:$C$25)+SUMIF('26'!$B$12:$B$25,$F67,'26'!$C$12:$C$25)+SUMIF('27'!$B$12:$B$25,$F67,'27'!$C$12:$C$25)+SUMIF('28'!$B$12:$B$25,$F67,'28'!$C$12:$C$25)+SUMIF('29'!$B$12:$B$25,$F67,'29'!$C$12:$C$25)+SUMIF('30'!$B$12:$B$25,$F67,'30'!$C$12:$C$25)+SUMIF('31'!$B$12:$B$25,$F67,'31'!$C$12:$C$25) -> 0 | H67: =IFERROR($G67/'RECAP DU JOURNAL'!$G$40,0) -> 0 | I67: =IFERROR($G67/COUNTIF('RECAP DU JOURNAL'!$F$9:$F$39,">0"),0) -> 0
A70: Le tableau des fournisseurs cherche chaque nom dans le bloc ACHATS des 31 feuilles jour : écrivez toujours un fournisseur de la même façon (utilisez la liste déroulante) pour que le total soit juste. L’ordre des lignes a été figé sur le poids constaté en août 2026 ; les montants, eux, suivent toujours le mois en cours.

Sheet RECAP DU JOURNAL
A1: RÉCAP DU JOURNAL
A2: Le mois entier, jour par jour. Tout est repris des feuilles 01 à 31 : aucune saisie ici, sauf les quatre réglages ci-dessous.
A3: Année | C3: 2026 | E3: Premier jour du mois | F3: =DATE($C$3,$C$4,1) -> 46266 | H3: =$F$3 -> 46266
A4: Mois (1 à 12) | C4: 9 | E4: Nombre de jours | F4: =DAY(EOMONTH($F$3,0)) -> 30
A5: Caisse au 1er du mois | C5: 4223
A6: Objectif recette / jour | C6: 2200
A8: DATE | B8: JOUR | C8: RECETTE CAISSE | D8: GLOVO ESPÈCES | E8: GLOVO CARTE | F8: TOTAL RECETTE | G8: ACHATS | H8: CHARGES FIXES | I8: SALAIRES | J8: VIREMENTS | K8: TOTAL DÉPENSES | L8: RÉSULTAT DU JOUR | M8: CAISSE CE SOIR | N8: vs OBJ.
A9: =IF(1>$F$4,"",DATE($C$3,$C$4,1)) -> 46266 | B9: =IF($A9="","",CHOOSE(WEEKDAY($A9,2),"Lundi","Mardi","Mercredi","Jeudi","Vendredi","Samedi","Dimanche")) -> Mardi | C9: =IF($A9="","",'01'!$C$29) -> 0 | D9: =IF($A9="","",'01'!$C$30) -> 0 | E9: =IF($A9="","",'01'!$C$31) -> 0 | F9: =IF($A9="","",'01'!$C$32) -> 0 | G9: =IF($A9="","",'01'!$C$26) -> 0 | H9: =IF($A9="","",'01'!$F$26) -> 0 | I9: =IF($A9="","",'01'!$I$26) -> 0 | J9: =IF($A9="","",'01'!$L$26) -> 0 | K9: =IF($A9="","",SUM($G9:$J9)) -> 0 | L9: =IF($A9="","",$F9-$K9) -> 0 | M9: =IF($A9="","",'01'!$I$32) -> 4223 | N9: =IF($A9="","",IF($F9=0,"—",$F9-$C$6)) -> —
A10: =IF(2>$F$4,"",DATE($C$3,$C$4,2)) -> 46267 | B10: =IF($A10="","",CHOOSE(WEEKDAY($A10,2),"Lundi","Mardi","Mercredi","Jeudi","Vendredi","Samedi","Dimanche")) -> Mercredi | C10: =IF($A10="","",'02'!$C$29) -> 0 | D10: =IF($A10="","",'02'!$C$30) -> 0 | E10: =IF($A10="","",'02'!$C$31) -> 0 | F10: =IF($A10="","",'02'!$C$32) -> 0 | G10: =IF($A10="","",'02'!$C$26) -> 0 | H10: =IF($A10="","",'02'!$F$26) -> 0 | I10: =IF($A10="","",'02'!$I$26) -> 0 | J10: =IF($A10="","",'02'!$L$26) -> 0 | K10: =IF($A10="","",SUM($G10:$J10)) -> 0 | L10: =IF($A10="","",$F10-$K10) -> 0 | M10: =IF($A10="","",'02'!$I$32) -> 4223 | N10: =IF($A10="","",IF($F10=0,"—",$F10-$C$6)) -> —
A11: =IF(3>$F$4,"",DATE($C$3,$C$4,3)) -> 46268 | B11: =IF($A11="","",CHOOSE(WEEKDAY($A11,2),"Lundi","Mardi","Mercredi","Jeudi","Vendredi","Samedi","Dimanche")) -> Jeudi | C11: =IF($A11="","",'03'!$C$29) -> 0 | D11: =IF($A11="","",'03'!$C$30) -> 0 | E11: =IF($A11="","",'03'!$C$31) -> 0 | F11: =IF($A11="","",'03'!$C$32) -> 0 | G11: =IF($A11="","",'03'!$C$26) -> 0 | H11: =IF($A11="","",'03'!$F$26) -> 0 | I11: =IF($A11="","",'03'!$I$26) -> 0 | J11: =IF($A11="","",'03'!$L$26) -> 0 | K11: =IF($A11="","",SUM($G11:$J11)) -> 0 | L11: =IF($A11="","",$F11-$K11) -> 0 | M11: =IF($A11="","",'03'!$I$32) -> 4223 | N11: =IF($A11="","",IF($F11=0,"—",$F11-$C$6)) -> —
A12: =IF(4>$F$4,"",DATE($C$3,$C$4,4)) -> 46269 | B12: =IF($A12="","",CHOOSE(WEEKDAY($A12,2),"Lundi","Mardi","Mercredi","Jeudi","Vendredi","Samedi","Dimanche")) -> Vendredi | C12: =IF($A12="","",'04'!$C$29) -> 0 | D12: =IF($A12="","",'04'!$C$30) -> 0 | E12: =IF($A12="","",'04'!$C$31) -> 0 | F12: =IF($A12="","",'04'!$C$32) -> 0 | G12: =IF($A12="","",'04'!$C$26) -> 0 | H12: =IF($A12="","",'04'!$F$26) -> 0 | I12: =IF($A12="","",'04'!$I$26) -> 0 | J12: =IF($A12="","",'04'!$L$26) -> 0 | K12: =IF($A12="","",SUM($G12:$J12)) -> 0 | L12: =IF($A12="","",$F12-$K12) -> 0 | M12: =IF($A12="","",'04'!$I$32) -> 4223 | N12: =IF($A12="","",IF($F12=0,"—",$F12-$C$6)) -> —
A13: =IF(5>$F$4,"",DATE($C$3,$C$4,5)) -> 46270 | B13: =IF($A13="","",CHOOSE(WEEKDAY($A13,2),"Lundi","Mardi","Mercredi","Jeudi","Vendredi","Samedi","Dimanche")) -> Samedi | C13: =IF($A13="","",'05'!$C$29) -> 0 | D13: =IF($A13="","",'05'!$C$30) -> 0 | E13: =IF($A13="","",'05'!$C$31) -> 0 | F13: =IF($A13="","",'05'!$C$32) -> 0 | G13: =IF($A13="","",'05'!$C$26) -> 0 | H13: =IF($A13="","",'05'!$F$26) -> 0 | I13: =IF($A13="","",'05'!$I$26) -> 0 | J13: =IF($A13="","",'05'!$L$26) -> 0 | K13: =IF($A13="","",SUM($G13:$J13)) -> 0 | L13: =IF($A13="","",$F13-$K13) -> 0 | M13: =IF($A13="","",'05'!$I$32) -> 4223 | N13: =IF($A13="","",IF($F13=0,"—",$F13-$C$6)) -> —
A14: =IF(6>$F$4,"",DATE($C$3,$C$4,6)) -> 46271 | B14: =IF($A14="","",CHOOSE(WEEKDAY($A14,2),"Lundi","Mardi","Mercredi","Jeudi","Vendredi","Samedi","Dimanche")) -> Dimanche | C14: =IF($A14="","",'06'!$C$29) -> 0 | D14: =IF($A14="","",'06'!$C$30) -> 0 | E14: =IF($A14="","",'06'!$C$31) -> 0 | F14: =IF($A14="","",'06'!$C$32) -> 0 | G14: =IF($A14="","",'06'!$C$26) -> 0 | H14: =IF($A14="","",'06'!$F$26) -> 0 | I14: =IF($A14="","",'06'!$I$26) -> 0 | J14: =IF($A14="","",'06'!$L$26) -> 0 | K14: =IF($A14="","",SUM($G14:$J14)) -> 0 | L14: =IF($A14="","",$F14-$K14) -> 0 | M14: =IF($A14="","",'06'!$I$32) -> 4223 | N14: =IF($A14="","",IF($F14=0,"—",$F14-$C$6)) -> —
A15: =IF(7>$F$4,"",DATE($C$3,$C$4,7)) -> 46272 | B15: =IF($A15="","",CHOOSE(WEEKDAY($A15,2),"Lundi","Mardi","Mercredi","Jeudi","Vendredi","Samedi","Dimanche")) -> Lundi | C15: =IF($A15="","",'07'!$C$29) -> 0 | D15: =IF($A15="","",'07'!$C$30) -> 0 | E15: =IF($A15="","",'07'!$C$31) -> 0 | F15: =IF($A15="","",'07'!$C$32) -> 0 | G15: =IF($A15="","",'07'!$C$26) -> 0 | H15: =IF($A15="","",'07'!$F$26) -> 0 | I15: =IF($A15="","",'07'!$I$26) -> 0 | J15: =IF($A15="","",'07'!$L$26) -> 0 | K15: =IF($A15="","",SUM($G15:$J15)) -> 0 | L15: =IF($A15="","",$F15-$K15) -> 0 | M15: =IF($A15="","",'07'!$I$32) -> 4223 | N15: =IF($A15="","",IF($F15=0,"—",$F15-$C$6)) -> —
A16: =IF(8>$F$4,"",DATE($C$3,$C$4,8)) -> 46273 | B16: =IF($A16="","",CHOOSE(WEEKDAY($A16,2),"Lundi","Mardi","Mercredi","Jeudi","Vendredi","Samedi","Dimanche")) -> Mardi | C16: =IF($A16="","",'08'!$C$29) -> 0 | D16: =IF($A16="","",'08'!$C$30) -> 0 | E16: =IF($A16="","",'08'!$C$31) -> 0 | F16: =IF($A16="","",'08'!$C$32) -> 0 | G16: =IF($A16="","",'08'!$C$26) -> 0 | H16: =IF($A16="","",'08'!$F$26) -> 0 | I16: =IF($A16="","",'08'!$I$26) -> 0 | J16: =IF($A16="","",'08'!$L$26) -> 0 | K16: =IF($A16="","",SUM($G16:$J16)) -> 0 | L16: =IF($A16="","",$F16-$K16) -> 0 | M16: =IF($A16="","",'08'!$I$32) -> 4223 | N16: =IF($A16="","",IF($F16=0,"—",$F16-$C$6)) -> —
A17: =IF(9>$F$4,"",DATE($C$3,$C$4,9)) -> 46274 | B17: =IF($A17="","",CHOOSE(WEEKDAY($A17,2),"Lundi","Mardi","Mercredi","Jeudi","Vendredi","Samedi","Dimanche")) -> Mercredi | C17: =IF($A17="","",'09'!$C$29) -> 0 | D17: =IF($A17="","",'09'!$C$30) -> 0 | E17: =IF($A17="","",'09'!$C$31) -> 0 | F17: =IF($A17="","",'09'!$C$32) -> 0 | G17: =IF($A17="","",'09'!$C$26) -> 0 | H17: =IF($A17="","",'09'!$F$26) -> 0 | I17: =IF($A17="","",'09'!$I$26) -> 0 | J17: =IF($A17="","",'09'!$L$26) -> 0 | K17: =IF($A17="","",SUM($G17:$J17)) -> 0 | L17: =IF($A17="","",$F17-$K17) -> 0 | M17: =IF($A17="","",'09'!$I$32) -> 4223 | N17: =IF($A17="","",IF($F17=0,"—",$F17-$C$6)) -> —
A18: =IF(10>$F$4,"",DATE($C$3,$C$4,10)) -> 46275 | B18: =IF($A18="","",CHOOSE(WEEKDAY($A18,2),"Lundi","Mardi","Mercredi","Jeudi","Vendredi","Samedi","Dimanche")) -> Jeudi | C18: =IF($A18="","",'10'!$C$29) -> 0 | D18: =IF($A18="","",'10'!$C$30) -> 0 | E18: =IF($A18="","",'10'!$C$31) -> 0 | F18: =IF($A18="","",'10'!$C$32) -> 0 | G18: =IF($A18="","",'10'!$C$26) -> 0 | H18: =IF($A18="","",'10'!$F$26) -> 0 | I18: =IF($A18="","",'10'!$I$26) -> 0 | J18: =IF($A18="","",'10'!$L$26) -> 0 | K18: =IF($A18="","",SUM($G18:$J18)) -> 0 | L18: =IF($A18="","",$F18-$K18) -> 0 | M18: =IF($A18="","",'10'!$I$32) -> 4223 | N18: =IF($A18="","",IF($F18=0,"—",$F18-$C$6)) -> —
A19: =IF(11>$F$4,"",DATE($C$3,$C$4,11)) -> 46276 | B19: =IF($A19="","",CHOOSE(WEEKDAY($A19,2),"Lundi","Mardi","Mercredi","Jeudi","Vendredi","Samedi","Dimanche")) -> Vendredi | C19: =IF($A19="","",'11'!$C$29) -> 0 | D19: =IF($A19="","",'11'!$C$30) -> 0 | E19: =IF($A19="","",'11'!$C$31) -> 0 | F19: =IF($A19="","",'11'!$C$32) -> 0 | G19: =IF($A19="","",'11'!$C$26) -> 0 | H19: =IF($A19="","",'11'!$F$26) -> 0 | I19: =IF($A19="","",'11'!$I$26) -> 0 | J19: =IF($A19="","",'11'!$L$26) -> 0 | K19: =IF($A19="","",SUM($G19:$J19)) -> 0 | L19: =IF($A19="","",$F19-$K19) -> 0 | M19: =IF($A19="","",'11'!$I$32) -> 4223 | N19: =IF($A19="","",IF($F19=0,"—",$F19-$C$6)) -> —
A20: =IF(12>$F$4,"",DATE($C$3,$C$4,12)) -> 46277 | B20: =IF($A20="","",CHOOSE(WEEKDAY($A20,2),"Lundi","Mardi","Mercredi","Jeudi","Vendredi","Samedi","Dimanche")) -> Samedi | C20: =IF($A20="","",'12'!$C$29) -> 0 | D20: =IF($A20="","",'12'!$C$30) -> 0 | E20: =IF($A20="","",'12'!$C$31) -> 0 | F20: =IF($A20="","",'12'!$C$32) -> 0 | G20: =IF($A20="","",'12'!$C$26) -> 0 | H20: =IF($A20="","",'12'!$F$26) -> 0 | I20: =IF($A20="","",'12'!$I$26) -> 0 | J20: =IF($A20="","",'12'!$L$26) -> 0 | K20: =IF($A20="","",SUM($G20:$J20)) -> 0 | L20: =IF($A20="","",$F20-$K20) -> 0 | M20: =IF($A20="","",'12'!$I$32) -> 4223 | N20: =IF($A20="","",IF($F20=0,"—",$F20-$C$6)) -> —
A21: =IF(13>$F$4,"",DATE($C$3,$C$4,13)) -> 46278 | B21: =IF($A21="","",CHOOSE(WEEKDAY($A21,2),"Lundi","Mardi","Mercredi","Jeudi","Vendredi","Samedi","Dimanche")) -> Dimanche | C21: =IF($A21="","",'13'!$C$29) -> 0 | D21: =IF($A21="","",'13'!$C$30) -> 0 | E21: =IF($A21="","",'13'!$C$31) -> 0 | F21: =IF($A21="","",'13'!$C$32) -> 0 | G21: =IF($A21="","",'13'!$C$26) -> 0 | H21: =IF($A21="","",'13'!$F$26) -> 0 | I21: =IF($A21="","",'13'!$I$26) -> 0 | J21: =IF($A21="","",'13'!$L$26) -> 0 | K21: =IF($A21="","",SUM($G21:$J21)) -> 0 | L21: =IF($A21="","",$F21-$K21) -> 0 | M21: =IF($A21="","",'13'!$I$32) -> 4223 | N21: =IF($A21="","",IF($F21=0,"—",$F21-$C$6)) -> —
A22: =IF(14>$F$4,"",DATE($C$3,$C$4,14)) -> 46279 | B22: =IF($A22="","",CHOOSE(WEEKDAY($A22,2),"Lundi","Mardi","Mercredi","Jeudi","Vendredi","Samedi","Dimanche")) -> Lundi | C22: =IF($A22="","",'14'!$C$29) -> 0 | D22: =IF($A22="","",'14'!$C$30) -> 0 | E22: =IF($A22="","",'14'!$C$31) -> 0 | F22: =IF($A22="","",'14'!$C$32) -> 0 | G22: =IF($A22="","",'14'!$C$26) -> 0 | H22: =IF($A22="","",'14'!$F$26) -> 0 | I22: =IF($A22="","",'14'!$I$26) -> 0 | J22: =IF($A22="","",'14'!$L$26) -> 0 | K22: =IF($A22="","",SUM($G22:$J22)) -> 0 | L22: =IF($A22="","",$F22-$K22) -> 0 | M22: =IF($A22="","",'14'!$I$32) -> 4223 | N22: =IF($A22="","",IF($F22=0,"—",$F22-$C$6)) -> —
A23: =IF(15>$F$4,"",DATE($C$3,$C$4,15)) -> 46280 | B23: =IF($A23="","",CHOOSE(WEEKDAY($A23,2),"Lundi","Mardi","Mercredi","Jeudi","Vendredi","Samedi","Dimanche")) -> Mardi | C23: =IF($A23="","",'15'!$C$29) -> 0 | D23: =IF($A23="","",'15'!$C$30) -> 0 | E23: =IF($A23="","",'15'!$C$31) -> 0 | F23: =IF($A23="","",'15'!$C$32) -> 0 | G23: =IF($A23="","",'15'!$C$26) -> 0 | H23: =IF($A23="","",'15'!$F$26) -> 0 | I23: =IF($A23="","",'15'!$I$26) -> 0 | J23: =IF($A23="","",'15'!$L$26) -> 0 | K23: =IF($A23="","",SUM($G23:$J23)) -> 0 | L23: =IF($A23="","",$F23-$K23) -> 0 | M23: =IF($A23="","",'15'!$I$32) -> 4223 | N23: =IF($A23="","",IF($F23=0,"—",$F23-$C$6)) -> —
A24: =IF(16>$F$4,"",DATE($C$3,$C$4,16)) -> 46281 | B24: =IF($A24="","",CHOOSE(WEEKDAY($A24,2),"Lundi","Mardi","Mercredi","Jeudi","Vendredi","Samedi","Dimanche")) -> Mercredi | C24: =IF($A24="","",'16'!$C$29) -> 0 | D24: =IF($A24="","",'16'!$C$30) -> 0 | E24: =IF($A24="","",'16'!$C$31) -> 0 | F24: =IF($A24="","",'16'!$C$32) -> 0 | G24: =IF($A24="","",'16'!$C$26) -> 0 | H24: =IF($A24="","",'16'!$F$26) -> 0 | I24: =IF($A24="","",'16'!$I$26) -> 0 | J24: =IF($A24="","",'16'!$L$26) -> 0 | K24: =IF($A24="","",SUM($G24:$J24)) -> 0 | L24: =IF($A24="","",$F24-$K24) -> 0 | M24: =IF($A24="","",'16'!$I$32) -> 4223 | N24: =IF($A24="","",IF($F24=0,"—",$F24-$C$6)) -> —
A25: =IF(17>$F$4,"",DATE($C$3,$C$4,17)) -> 46282 | B25: =IF($A25="","",CHOOSE(WEEKDAY($A25,2),"Lundi","Mardi","Mercredi","Jeudi","Vendredi","Samedi","Dimanche")) -> Jeudi | C25: =IF($A25="","",'17'!$C$29) -> 0 | D25: =IF($A25="","",'17'!$C$30) -> 0 | E25: =IF($A25="","",'17'!$C$31) -> 0 | F25: =IF($A25="","",'17'!$C$32) -> 0 | G25: =IF($A25="","",'17'!$C$26) -> 0 | H25: =IF($A25="","",'17'!$F$26) -> 0 | I25: =IF($A25="","",'17'!$I$26) -> 0 | J25: =IF($A25="","",'17'!$L$26) -> 0 | K25: =IF($A25="","",SUM($G25:$J25)) -> 0 | L25: =IF($A25="","",$F25-$K25) -> 0 | M25: =IF($A25="","",'17'!$I$32) -> 4223 | N25: =IF($A25="","",IF($F25=0,"—",$F25-$C$6)) -> —
A26: =IF(18>$F$4,"",DATE($C$3,$C$4,18)) -> 46283 | B26: =IF($A26="","",CHOOSE(WEEKDAY($A26,2),"Lundi","Mardi","Mercredi","Jeudi","Vendredi","Samedi","Dimanche")) -> Vendredi | C26: =IF($A26="","",'18'!$C$29) -> 0 | D26: =IF($A26="","",'18'!$C$30) -> 0 | E26: =IF($A26="","",'18'!$C$31) -> 0 | F26: =IF($A26="","",'18'!$C$32) -> 0 | G26: =IF($A26="","",'18'!$C$26) -> 0 | H26: =IF($A26="","",'18'!$F$26) -> 0 | I26: =IF($A26="","",'18'!$I$26) -> 0 | J26: =IF($A26="","",'18'!$L$26) -> 0 | K26: =IF($A26="","",SUM($G26:$J26)) -> 0 | L26: =IF($A26="","",$F26-$K26) -> 0 | M26: =IF($A26="","",'18'!$I$32) -> 4223 | N26: =IF($A26="","",IF($F26=0,"—",$F26-$C$6)) -> —
A27: =IF(19>$F$4,"",DATE($C$3,$C$4,19)) -> 46284 | B27: =IF($A27="","",CHOOSE(WEEKDAY($A27,2),"Lundi","Mardi","Mercredi","Jeudi","Vendredi","Samedi","Dimanche")) -> Samedi | C27: =IF($A27="","",'19'!$C$29) -> 0 | D27: =IF($A27="","",'19'!$C$30) -> 0 | E27: =IF($A27="","",'19'!$C$31) -> 0 | F27: =IF($A27="","",'19'!$C$32) -> 0 | G27: =IF($A27="","",'19'!$C$26) -> 0 | H27: =IF($A27="","",'19'!$F$26) -> 0 | I27: =IF($A27="","",'19'!$I$26) -> 0 | J27: =IF($A27="","",'19'!$L$26) -> 0 | K27: =IF($A27="","",SUM($G27:$J27)) -> 0 | L27: =IF($A27="","",$F27-$K27) -> 0 | M27: =IF($A27="","",'19'!$I$32) -> 4223 | N27: =IF($A27="","",IF($F27=0,"—",$F27-$C$6)) -> —
A28: =IF(20>$F$4,"",DATE($C$3,$C$4,20)) -> 46285 | B28: =IF($A28="","",CHOOSE(WEEKDAY($A28,2),"Lundi","Mardi","Mercredi","Jeudi","Vendredi","Samedi","Dimanche")) -> Dimanche | C28: =IF($A28="","",'20'!$C$29) -> 0 | D28: =IF($A28="","",'20'!$C$30) -> 0 | E28: =IF($A28="","",'20'!$C$31) -> 0 | F28: =IF($A28="","",'20'!$C$32) -> 0 | G28: =IF($A28="","",'20'!$C$26) -> 0 | H28: =IF($A28="","",'20'!$F$26) -> 0 | I28: =IF($A28="","",'20'!$I$26) -> 0 | J28: =IF($A28="","",'20'!$L$26) -> 0 | K28: =IF($A28="","",SUM($G28:$J28)) -> 0 | L28: =IF($A28="","",$F28-$K28) -> 0 | M28: =IF($A28="","",'20'!$I$32) -> 4223 | N28: =IF($A28="","",IF($F28=0,"—",$F28-$C$6)) -> —
A29: =IF(21>$F$4,"",DATE($C$3,$C$4,21)) -> 46286 | B29: =IF($A29="","",CHOOSE(WEEKDAY($A29,2),"Lundi","Mardi","Mercredi","Jeudi","Vendredi","Samedi","Dimanche")) -> Lundi | C29: =IF($A29="","",'21'!$C$29) -> 0 | D29: =IF($A29="","",'21'!$C$30) -> 0 | E29: =IF($A29="","",'21'!$C$31) -> 0 | F29: =IF($A29="","",'21'!$C$32) -> 0 | G29: =IF($A29="","",'21'!$C$26) -> 0 | H29: =IF($A29="","",'21'!$F$26) -> 0 | I29: =IF($A29="","",'21'!$I$26) -> 0 | J29: =IF($A29="","",'21'!$L$26) -> 0 | K29: =IF($A29="","",SUM($G29:$J29)) -> 0 | L29: =IF($A29="","",$F29-$K29) -> 0 | M29: =IF($A29="","",'21'!$I$32) -> 4223 | N29: =IF($A29="","",IF($F29=0,"—",$F29-$C$6)) -> —
A30: =IF(22>$F$4,"",DATE($C$3,$C$4,22)) -> 46287 | B30: =IF($A30="","",CHOOSE(WEEKDAY($A30,2),"Lundi","Mardi","Mercredi","Jeudi","Vendredi","Samedi","Dimanche")) -> Mardi | C30: =IF($A30="","",'22'!$C$29) -> 0 | D30: =IF($A30="","",'22'!$C$30) -> 0 | E30: =IF($A30="","",'22'!$C$31) -> 0 | F30: =IF($A30="","",'22'!$C$32) -> 0 | G30: =IF($A30="","",'22'!$C$26) -> 0 | H30: =IF($A30="","",'22'!$F$26) -> 0 | I30: =IF($A30="","",'22'!$I$26) -> 0 | J30: =IF($A30="","",'22'!$L$26) -> 0 | K30: =IF($A30="","",SUM($G30:$J30)) -> 0 | L30: =IF($A30="","",$F30-$K30) -> 0 | M30: =IF($A30="","",'22'!$I$32) -> 4223 | N30: =IF($A30="","",IF($F30=0,"—",$F30-$C$6)) -> —
A31: =IF(23>$F$4,"",DATE($C$3,$C$4,23)) -> 46288 | B31: =IF($A31="","",CHOOSE(WEEKDAY($A31,2),"Lundi","Mardi","Mercredi","Jeudi","Vendredi","Samedi","Dimanche")) -> Mercredi | C31: =IF($A31="","",'23'!$C$29) -> 0 | D31: =IF($A31="","",'23'!$C$30) -> 0 | E31: =IF($A31="","",'23'!$C$31) -> 0 | F31: =IF($A31="","",'23'!$C$32) -> 0 | G31: =IF($A31="","",'23'!$C$26) -> 0 | H31: =IF($A31="","",'23'!$F$26) -> 0 | I31: =IF($A31="","",'23'!$I$26) -> 0 | J31: =IF($A31="","",'23'!$L$26) -> 0 | K31: =IF($A31="","",SUM($G31:$J31)) -> 0 | L31: =IF($A31="","",$F31-$K31) -> 0 | M31: =IF($A31="","",'23'!$I$32) -> 4223 | N31: =IF($A31="","",IF($F31=0,"—",$F31-$C$6)) -> —
A32: =IF(24>$F$4,"",DATE($C$3,$C$4,24)) -> 46289 | B32: =IF($A32="","",CHOOSE(WEEKDAY($A32,2),"Lundi","Mardi","Mercredi","Jeudi","Vendredi","Samedi","Dimanche")) -> Jeudi | C32: =IF($A32="","",'24'!$C$29) -> 0 | D32: =IF($A32="","",'24'!$C$30) -> 0 | E32: =IF($A32="","",'24'!$C$31) -> 0 | F32: =IF($A32="","",'24'!$C$32) -> 0 | G32: =IF($A32="","",'24'!$C$26) -> 0 | H32: =IF($A32="","",'24'!$F$26) -> 0 | I32: =IF($A32="","",'24'!$I$26) -> 0 | J32: =IF($A32="","",'24'!$L$26) -> 0 | K32: =IF($A32="","",SUM($G32:$J32)) -> 0 | L32: =IF($A32="","",$F32-$K32) -> 0 | M32: =IF($A32="","",'24'!$I$32) -> 4223 | N32: =IF($A32="","",IF($F32=0,"—",$F32-$C$6)) -> —
A33: =IF(25>$F$4,"",DATE($C$3,$C$4,25)) -> 46290 | B33: =IF($A33="","",CHOOSE(WEEKDAY($A33,2),"Lundi","Mardi","Mercredi","Jeudi","Vendredi","Samedi","Dimanche")) -> Vendredi | C33: =IF($A33="","",'25'!$C$29) -> 0 | D33: =IF($A33="","",'25'!$C$30) -> 0 | E33: =IF($A33="","",'25'!$C$31) -> 0 | F33: =IF($A33="","",'25'!$C$32) -> 0 | G33: =IF($A33="","",'25'!$C$26) -> 0 | H33: =IF($A33="","",'25'!$F$26) -> 0 | I33: =IF($A33="","",'25'!$I$26) -> 0 | J33: =IF($A33="","",'25'!$L$26) -> 0 | K33: =IF($A33="","",SUM($G33:$J33)) -> 0 | L33: =IF($A33="","",$F33-$K33) -> 0 | M33: =IF($A33="","",'25'!$I$32) -> 4223 | N33: =IF($A33="","",IF($F33=0,"—",$F33-$C$6)) -> —
A34: =IF(26>$F$4,"",DATE($C$3,$C$4,26)) -> 46291 | B34: =IF($A34="","",CHOOSE(WEEKDAY($A34,2),"Lundi","Mardi","Mercredi","Jeudi","Vendredi","Samedi","Dimanche")) -> Samedi | C34: =IF($A34="","",'26'!$C$29) -> 0 | D34: =IF($A34="","",'26'!$C$30) -> 0 | E34: =IF($A34="","",'26'!$C$31) -> 0 | F34: =IF($A34="","",'26'!$C$32) -> 0 | G34: =IF($A34="","",'26'!$C$26) -> 0 | H34: =IF($A34="","",'26'!$F$26) -> 0 | I34: =IF($A34="","",'26'!$I$26) -> 0 | J34: =IF($A34="","",'26'!$L$26) -> 0 | K34: =IF($A34="","",SUM($G34:$J34)) -> 0 | L34: =IF($A34="","",$F34-$K34) -> 0 | M34: =IF($A34="","",'26'!$I$32) -> 4223 | N34: =IF($A34="","",IF($F34=0,"—",$F34-$C$6)) -> —
A35: =IF(27>$F$4,"",DATE($C$3,$C$4,27)) -> 46292 | B35: =IF($A35="","",CHOOSE(WEEKDAY($A35,2),"Lundi","Mardi","Mercredi","Jeudi","Vendredi","Samedi","Dimanche")) -> Dimanche | C35: =IF($A35="","",'27'!$C$29) -> 0 | D35: =IF($A35="","",'27'!$C$30) -> 0 | E35: =IF($A35="","",'27'!$C$31) -> 0 | F35: =IF($A35="","",'27'!$C$32) -> 0 | G35: =IF($A35="","",'27'!$C$26) -> 0 | H35: =IF($A35="","",'27'!$F$26) -> 0 | I35: =IF($A35="","",'27'!$I$26) -> 0 | J35: =IF($A35="","",'27'!$L$26) -> 0 | K35: =IF($A35="","",SUM($G35:$J35)) -> 0 | L35: =IF($A35="","",$F35-$K35) -> 0 | M35: =IF($A35="","",'27'!$I$32) -> 4223 | N35: =IF($A35="","",IF($F35=0,"—",$F35-$C$6)) -> —
A36: =IF(28>$F$4,"",DATE($C$3,$C$4,28)) -> 46293 | B36: =IF($A36="","",CHOOSE(WEEKDAY($A36,2),"Lundi","Mardi","Mercredi","Jeudi","Vendredi","Samedi","Dimanche")) -> Lundi | C36: =IF($A36="","",'28'!$C$29) -> 0 | D36: =IF($A36="","",'28'!$C$30) -> 0 | E36: =IF($A36="","",'28'!$C$31) -> 0 | F36: =IF($A36="","",'28'!$C$32) -> 0 | G36: =IF($A36="","",'28'!$C$26) -> 0 | H36: =IF($A36="","",'28'!$F$26) -> 0 | I36: =IF($A36="","",'28'!$I$26) -> 0 | J36: =IF($A36="","",'28'!$L$26) -> 0 | K36: =IF($A36="","",SUM($G36:$J36)) -> 0 | L36: =IF($A36="","",$F36-$K36) -> 0 | M36: =IF($A36="","",'28'!$I$32) -> 4223 | N36: =IF($A36="","",IF($F36=0,"—",$F36-$C$6)) -> —
A37: =IF(29>$F$4,"",DATE($C$3,$C$4,29)) -> 46294 | B37: =IF($A37="","",CHOOSE(WEEKDAY($A37,2),"Lundi","Mardi","Mercredi","Jeudi","Vendredi","Samedi","Dimanche")) -> Mardi | C37: =IF($A37="","",'29'!$C$29) -> 0 | D37: =IF($A37="","",'29'!$C$30) -> 0 | E37: =IF($A37="","",'29'!$C$31) -> 0 | F37: =IF($A37="","",'29'!$C$32) -> 0 | G37: =IF($A37="","",'29'!$C$26) -> 0 | H37: =IF($A37="","",'29'!$F$26) -> 0 | I37: =IF($A37="","",'29'!$I$26) -> 0 | J37: =IF($A37="","",'29'!$L$26) -> 0 | K37: =IF($A37="","",SUM($G37:$J37)) -> 0 | L37: =IF($A37="","",$F37-$K37) -> 0 | M37: =IF($A37="","",'29'!$I$32) -> 4223 | N37: =IF($A37="","",IF($F37=0,"—",$F37-$C$6)) -> —
A38: =IF(30>$F$4,"",DATE($C$3,$C$4,30)) -> 46295 | B38: =IF($A38="","",CHOOSE(WEEKDAY($A38,2),"Lundi","Mardi","Mercredi","Jeudi","Vendredi","Samedi","Dimanche")) -> Mercredi | C38: =IF($A38="","",'30'!$C$29) -> 0 | D38: =IF($A38="","",'30'!$C$30) -> 0 | E38: =IF($A38="","",'30'!$C$31) -> 0 | F38: =IF($A38="","",'30'!$C$32) -> 0 | G38: =IF($A38="","",'30'!$C$26) -> 0 | H38: =IF($A38="","",'30'!$F$26) -> 0 | I38: =IF($A38="","",'30'!$I$26) -> 0 | J38: =IF($A38="","",'30'!$L$26) -> 0 | K38: =IF($A38="","",SUM($G38:$J38)) -> 0 | L38: =IF($A38="","",$F38-$K38) -> 0 | M38: =IF($A38="","",'30'!$I$32) -> 4223 | N38: =IF($A38="","",IF($F38=0,"—",$F38-$C$6)) -> —
A39: =IF(31>$F$4,"",DATE($C$3,$C$4,31)) | B39: =IF($A39="","",CHOOSE(WEEKDAY($A39,2),"Lundi","Mardi","Mercredi","Jeudi","Vendredi","Samedi","Dimanche")) | C39: =IF($A39="","",'31'!$C$29) | D39: =IF($A39="","",'31'!$C$30) | E39: =IF($A39="","",'31'!$C$31) | F39: =IF($A39="","",'31'!$C$32) | G39: =IF($A39="","",'31'!$C$26) | H39: =IF($A39="","",'31'!$F$26) | I39: =IF($A39="","",'31'!$I$26) | J39: =IF($A39="","",'31'!$L$26) | K39: =IF($A39="","",SUM($G39:$J39)) | L39: =IF($A39="","",$F39-$K39) | M39: =IF($A39="","",'31'!$I$32) | N39: =IF($A39="","",IF($F39=0,"—",$F39-$C$6))
A40: TOTAL DU MOIS | C40: =SUM(C9:C39) -> 0 | D40: =SUM(D9:D39) -> 0 | E40: =SUM(E9:E39) -> 0 | F40: =SUM(F9:F39) -> 0 | G40: =SUM(G9:G39) -> 0 | H40: =SUM(H9:H39) -> 0 | I40: =SUM(I9:I39) -> 0 | J40: =SUM(J9:J39) -> 0 | ... L40: =SUM(L9:L39) -> 0 | M40: =INDEX($M$9:$M$39,$F$4) -> 4223 | N40: =SUMIF($F$9:$F$39,">0",$N$9:$N$39) -> 0
A41: PART DE LA RECETTE | G41: =IFERROR(G40/$F$40,0) -> 0 | H41: =IFERROR(H40/$F$40,0) -> 0 | I41: =IFERROR(I40/$F$40,0) -> 0 | J41: =IFERROR(J40/$F$40,0) -> 0 | K41: =IFERROR(K40/$F$40,0) -> 0 | L41: =IFERROR(L40/$F$40,0) -> 0
...

Sheet 01
A1: CAISSE DU JOUR
A2: =IF(1>'RECAP DU JOURNAL'!$F$4,"— ce jour n'existe pas dans le mois —",DATE('RECAP DU JOURNAL'!$C$3,'RECAP DU JOURNAL'!$C$4,1)) -> 46266 | G2: CAFÉ VICTOR HUGO — Mohammedia
A4: À REMPLIR ▸ les quatre blocs de dépenses ci-dessous ▸ puis, en bas, la RECETTE comptée dans la caisse. Les cases jaunes sont les vôtres ; le reste se calcule tout seul.
B6: CAISSE DE LA VEILLE | E6: RECETTE DU JOUR | H6: TOTAL DÉPENSES | K6: SOLDE CE SOIR
B7: =$I$29 -> 4223 | E7: =$C$32 -> 0 | H7: =$I$31 -> 0 | K7: =$I$32 -> 4223
B10: DÉPENSES — ACHATS DU JOUR | E10: CHARGES FIXES | H10: SALAIRES ET AVANCES | K10: VIREMENTS ET DIVERS
B11: LIBELLÉ | C11: MONTANT | E11: LIBELLÉ | F11: MONTANT | H11: LIBELLÉ | I11: MONTANT | K11: LIBELLÉ | L11: MONTANT
E12: LOYER | H12: BAR MEN | K12: BANQUE
E13: EAU + ÉLECTRICITÉ | H13: BAR MEN ALI | K13: MOUHSSINE
E14: INTERNET & TÉLÉPHONE | H14: FATIMA | K14: HAMID
E15: TAXES & IMPÔTS | H15: MARWA | K15: AVANCE LOYER
E16: ASSURANCE | H16: LAHCEN | K16: PRÉLÈVEMENT PERSONNEL
E17: ABONNEMENTS TV | H17: ABDELLAH | K17: AUTRE VIREMENT
E18: ENTRETIEN & RÉPARATION | H18: AHMED
E19: AUTRE CHARGE FIXE | H19: ALI
H20: LATIFA 1
H21: LATIFA 2
H22: HAMZA
B26: TOTAL | C26: =SUM(C12:C25) -> 0 | E26: TOTAL | F26: =SUM(F12:F25) -> 0 | H26: TOTAL | I26: =SUM(I12:I25) -> 0 | K26: TOTAL | L26: =SUM(L12:L25) -> 0
B28: RECETTES DU JOUR | H28: SOLDE DE LA CAISSE
B29: Recette caisse (espèces comptées) | H29: Caisse de la veille | I29: ='RECAP DU JOURNAL'!$C$5 -> 4223
B30: Glovo — espèces | H30: Recette du jour (+) | I30: =$C$32 -> 0
B31: Glovo — carte | H31: Dépenses du jour (−) | I31: =$C$26+$F$26+$I$26+$L$26 -> 0
B32: TOTAL RECETTE DU JOUR | C32: =SUM($C$29:$C$31) -> 0 | H32: SOLDE EN CAISSE CE SOIR | I32: =$I$29+$I$30-$I$31 -> 4223
B34: Le solde de ce soir devient automatiquement la caisse de la veille sur la feuille du lendemain. Les libellés en gris des blocs CHARGES FIXES, SALAIRES et VIREMENTS sont fixes : ils permettent au classeur de totaliser chaque poste sur tout le mois — ne les modifiez pas.

Sheet 02
A1: CAISSE DU JOUR
A2: =IF(2>'RECAP DU JOURNAL'!$F$4,"— ce jour n'existe pas dans le mois —",DATE('RECAP DU JOURNAL'!$C$3,'RECAP DU JOURNAL'!$C$4,2)) -> 46267 | G2: CAFÉ VICTOR HUGO — Mohammedia
A4: À REMPLIR ▸ les quatre blocs de dépenses ci-dessous ▸ puis, en bas, la RECETTE comptée dans la caisse. Les cases jaunes sont les vôtres ; le reste se calcule tout seul.
B6: CAISSE DE LA VEILLE | E6: RECETTE DU JOUR | H6: TOTAL DÉPENSES | K6: SOLDE CE SOIR
B7: =$I$29 -> 4223 | E7: =$C$32 -> 0 | H7: =$I$31 -> 0 | K7: =$I$32 -> 4223
B10: DÉPENSES — ACHATS DU JOUR | E10: CHARGES FIXES | H10: SALAIRES ET AVANCES | K10: VIREMENTS ET DIVERS
B11: LIBELLÉ | C11: MONTANT | E11: LIBELLÉ | F11: MONTANT | H11: LIBELLÉ | I11: MONTANT | K11: LIBELLÉ | L11: MONTANT
E12: LOYER | H12: BAR MEN | K12: BANQUE
E13: EAU + ÉLECTRICITÉ | H13: BAR MEN ALI | K13: MOUHSSINE
E14: INTERNET & TÉLÉPHONE | H14: FATIMA | K14: HAMID
E15: TAXES & IMPÔTS | H15: MARWA | K15: AVANCE LOYER
E16: ASSURANCE | H16: LAHCEN | K16: PRÉLÈVEMENT PERSONNEL
E17: ABONNEMENTS TV | H17: ABDELLAH | K17: AUTRE VIREMENT
E18: ENTRETIEN & RÉPARATION | H18: AHMED
E19: AUTRE CHARGE FIXE | H19: ALI
H20: LATIFA 1
H21: LATIFA 2
H22: HAMZA
B26: TOTAL | C26: =SUM(C12:C25) -> 0 | E26: TOTAL | F26: =SUM(F12:F25) -> 0 | H26: TOTAL | I26: =SUM(I12:I25) -> 0 | K26: TOTAL | L26: =SUM(L12:L25) -> 0
B28: RECETTES DU JOUR | H28: SOLDE DE LA CAISSE
B29: Recette caisse (espèces comptées) | H29: Caisse de la veille | I29: ='01'!$I$32 -> 4223
B30: Glovo — espèces | H30: Recette du jour (+) | I30: =$C$32 -> 0
B31: Glovo — carte | H31: Dépenses du jour (−) | I31: =$C$26+$F$26+$I$26+$L$26 -> 0
B32: TOTAL RECETTE DU JOUR | C32: =SUM($C$29:$C$31) -> 0 | H32: SOLDE EN CAISSE CE SOIR | I32: =$I$29+$I$30-$I$31 -> 4223
B34: Le solde de ce soir devient automatiquement la caisse de la veille sur la feuille du lendemain. Les libellés en gris des blocs CHARGES FIXES, SALAIRES et VIREMENTS sont fixes : ils permettent au classeur de totaliser chaque poste sur tout le mois — ne les modifiez pas.

Sheet 03
A1: CAISSE DU JOUR
A2: =IF(3>'RECAP DU JOURNAL'!$F$4,"— ce jour n'existe pas dans le mois —",DATE('RECAP DU JOURNAL'!$C$3,'RECAP DU JOURNAL'!$C$4,3)) -> 46268 | G2: CAFÉ VICTOR HUGO — Mohammedia
A4: À REMPLIR ▸ les quatre blocs de dépenses ci-dessous ▸ puis, en bas, la RECETTE comptée dans la caisse. Les cases jaunes sont les vôtres ; le reste se calcule tout seul.
B6: CAISSE DE LA VEILLE | E6: RECETTE DU JOUR | H6: TOTAL DÉPENSES | K6: SOLDE CE SOIR
B7: =$I$29 -> 4223 | E7: =$C$32 -> 0 | H7: =$I$31 -> 0 | K7: =$I$32 -> 4223
B10: DÉPENSES — ACHATS DU JOUR | E10: CHARGES FIXES | H10: SALAIRES ET AVANCES | K10: VIREMENTS ET DIVERS
B11: LIBELLÉ | C11: MONTANT | E11: LIBELLÉ | F11: MONTANT | H11: LIBELLÉ | I11: MONTANT | K11: LIBELLÉ | L11: MONTANT
E12: LOYER | H12: BAR MEN | K12: BANQUE
E13: EAU + ÉLECTRICITÉ | H13: BAR MEN ALI | K13: MOUHSSINE
E14: INTERNET & TÉLÉPHONE | H14: FATIMA | K14: HAMID
E15: TAXES & IMPÔTS | H15: MARWA | K15: AVANCE LOYER
E16: ASSURANCE | H16: LAHCEN | K16: PRÉLÈVEMENT PERSONNEL
E17: ABONNEMENTS TV | H17: ABDELLAH | K17: AUTRE VIREMENT
E18: ENTRETIEN & RÉPARATION | H18: AHMED
E19: AUTRE CHARGE FIXE | H19: ALI
H20: LATIFA 1
H21: LATIFA 2
H22: HAMZA
B26: TOTAL | C26: =SUM(C12:C25) -> 0 | E26: TOTAL | F26: =SUM(F12:F25) -> 0 | H26: TOTAL | I26: =SUM(I12:I25) -> 0 | K26: TOTAL | L26: =SUM(L12:L25) -> 0
B28: RECETTES DU JOUR | H28: SOLDE DE LA CAISSE
B29: Recette caisse (espèces comptées) | H29: Caisse de la veille | I29: ='02'!$I$32 -> 4223
B30: Glovo — espèces | H30: Recette du jour (+) | I30: =$C$32 -> 0
B31: Glovo — carte | H31: Dépenses du jour (−) | I31: =$C$26+$F$26+$I$26+$L$26 -> 0
B32: TOTAL RECETTE DU JOUR | C32: =SUM($C$29:$C$31) -> 0 | H32: SOLDE EN CAISSE CE SOIR | I32: =$I$29+$I$30-$I$31 -> 4223
B34: Le solde de ce soir devient automatiquement la caisse de la veille sur la feuille du lendemain. Les libellés en gris des blocs CHARGES FIXES, SALAIRES et VIREMENTS sont fixes : ils permettent au classeur de totaliser chaque poste sur tout le mois — ne les modifiez pas.

Sheet 04
A1: CAISSE DU JOUR
A2: =IF(4>'RECAP DU JOURNAL'!$F$4,"— ce jour n'existe pas dans le mois —",DATE('RECAP DU JOURNAL'!$C$3,'RECAP DU JOURNAL'!$C$4,4)) -> 46269 | G2: CAFÉ VICTOR HUGO — Mohammedia
A4: À REMPLIR ▸ les quatre blocs de dépenses ci-dessous ▸ puis, en bas, la RECETTE comptée dans la caisse. Les cases jaunes sont les vôtres ; le reste se calcule tout seul.
B6: CAISSE DE LA VEILLE | E6: RECETTE DU JOUR | H6: TOTAL DÉPENSES | K6: SOLDE CE SOIR
B7: =$I$29 -> 4223 | E7: =$C$32 -> 0 | H7: =$I$31 -> 0 | K7: =$I$32 -> 4223
B10: DÉPENSES — ACHATS DU JOUR | E10: CHARGES FIXES | H10: SALAIRES ET AVANCES | K10: VIREMENTS ET DIVERS
B11: LIBELLÉ | C11: MONTANT | E11: LIBELLÉ | F11: MONTANT | H11: LIBELLÉ | I11: MONTANT | K11: LIBELLÉ | L11: MONTANT
E12: LOYER | H12: BAR MEN | K12: BANQUE
E13: EAU + ÉLECTRICITÉ | H13: BAR MEN ALI | K13: MOUHSSINE
E14: INTERNET & TÉLÉPHONE | H14: FATIMA | K14: HAMID
E15: TAXES & IMPÔTS | H15: MARWA | K15: AVANCE LOYER
E16: ASSURANCE | H16: LAHCEN | K16: PRÉLÈVEMENT PERSONNEL
E17: ABONNEMENTS TV | H17: ABDELLAH | K17: AUTRE VIREMENT
E18: ENTRETIEN & RÉPARATION | H18: AHMED
E19: AUTRE CHARGE FIXE | H19: ALI
H20: LATIFA 1
H21: LATIFA 2
H22: HAMZA
B26: TOTAL | C26: =SUM(C12:C25) -> 0 | E26: TOTAL | F26: =SUM(F12:F25) -> 0 | H26: TOTAL | I26: =SUM(I12:I25) -> 0 | K26: TOTAL | L26: =SUM(L12:L25) -> 0
B28: RECETTES DU JOUR | H28: SOLDE DE LA CAISSE
B29: Recette caisse (espèces comptées) | H29: Caisse de la veille | I29: ='03'!$I$32 -> 4223
B30: Glovo — espèces | H30: Recette du jour (+) | I30: =$C$32 -> 0
B31: Glovo — carte | H31: Dépenses du jour (−) | I31: =$C$26+$F$26+$I$26+$L$26 -> 0
B32: TOTAL RECETTE DU JOUR | C32: =SUM($C$29:$C$31) -> 0 | H32: SOLDE EN CAISSE CE SOIR | I32: =$I$29+$I$30-$I$31 -> 4223
B34: Le solde de ce soir devient automatiquement la caisse de la veille sur la feuille du lendemain. Les libellés en gris des blocs CHARGES FIXES, SALAIRES et VIREMENTS sont fixes : ils permettent au classeur de totaliser chaque poste sur tout le mois — ne les modifiez pas.

Sheet 05
A1: CAISSE DU JOUR
A2: =IF(5>'RECAP DU JOURNAL'!$F$4,"— ce jour n'existe pas dans le mois —",DATE('RECAP DU JOURNAL'!$C$3,'RECAP DU JOURNAL'!$C$4,5)) -> 46270 | G2: CAFÉ VICTOR HUGO — Mohammedia
A4: À REMPLIR ▸ les quatre blocs de dépenses ci-dessous ▸ puis, en bas, la RECETTE comptée dans la caisse. Les cases jaunes sont les vôtres ; le reste se calcule tout seul.
B6: CAISSE DE LA VEILLE | E6: RECETTE DU JOUR | H6: TOTAL DÉPENSES | K6: SOLDE CE SOIR
B7: =$I$29 -> 4223 | E7: =$C$32 -> 0 | H7: =$I$31 -> 0 | K7: =$I$32 -> 4223
B10: DÉPENSES — ACHATS DU JOUR | E10: CHARGES FIXES | H10: SALAIRES ET AVANCES | K10: VIREMENTS ET DIVERS
B11: LIBELLÉ | C11: MONTANT | E11: LIBELLÉ | F11: MONTANT | H11: LIBELLÉ | I11: MONTANT | K11: LIBELLÉ | L11: MONTANT
E12: LOYER | H12: BAR MEN | K12: BANQUE
E13: EAU + ÉLECTRICITÉ | H13: BAR MEN ALI | K13: MOUHSSINE
E14: INTERNET & TÉLÉPHONE | H14: FATIMA | K14: HAMID
E15: TAXES & IMPÔTS | H15: MARWA | K15: AVANCE LOYER
E16: ASSURANCE | H16: LAHCEN | K16: PRÉLÈVEMENT PERSONNEL
E17: ABONNEMENTS TV | H17: ABDELLAH | K17: AUTRE VIREMENT
E18: ENTRETIEN & RÉPARATION | H18: AHMED
E19: AUTRE CHARGE FIXE | H19: ALI
H20: LATIFA 1
H21: LATIFA 2
H22: HAMZA
B26: TOTAL | C26: =SUM(C12:C25) -> 0 | E26: TOTAL | F26: =SUM(F12:F25) -> 0 | H26: TOTAL | I26: =SUM(I12:I25) -> 0 | K26: TOTAL | L26: =SUM(L12:L25) -> 0
B28: RECETTES DU JOUR | H28: SOLDE DE LA CAISSE
B29: Recette caisse (espèces comptées) | H29: Caisse de la veille | I29: ='04'!$I$32 -> 4223
B30: Glovo — espèces | H30: Recette du jour (+) | I30: =$C$32 -> 0
B31: Glovo — carte | H31: Dépenses du jour (−) | I31: =$C$26+$F$26+$I$26+$L$26 -> 0
B32: TOTAL RECETTE DU JOUR | C32: =SUM($C$29:$C$31) -> 0 | H32: SOLDE EN CAISSE CE SOIR | I32: =$I$29+$I$30-$I$31 -> 4223
B34: Le solde de ce soir devient automatiquement la caisse de la veille sur la feuille du lendemain. Les libellés en gris des blocs CHARGES FIXES, SALAIRES et VIREMENTS sont fixes : ils permettent au classeur de totaliser chaque poste sur tout le mois — ne les modifiez pas.

Sheet 06
A1: CAISSE DU JOUR
A2: =IF(6>'RECAP DU JOURNAL'!$F$4,"— ce jour n'existe pas dans le mois —",DATE('RECAP DU JOURNAL'!$C$3,'RECAP DU JOURNAL'!$C$4,6)) -> 46271 | G2: CAFÉ VICTOR HUGO — Mohammedia
A4: À REMPLIR ▸ les quatre blocs de dépenses ci-dessous ▸ puis, en bas, la RECETTE comptée dans la caisse. Les cases jaunes sont les vôtres ; le reste se calcule tout seul.
B6: CAISSE DE LA VEILLE | E6: RECETTE DU JOUR | H6: TOTAL DÉPENSES | K6: SOLDE CE SOIR
B7: =$I$29 -> 4223 | E7: =$C$32 -> 0 | H7: =$I$31 -> 0 | K7: =$I$32 -> 4223
B10: DÉPENSES — ACHATS DU JOUR | E10: CHARGES FIXES | H10: SALAIRES ET AVANCES | K10: VIREMENTS ET DIVERS
B11: LIBELLÉ | C11: MONTANT | E11: LIBELLÉ | F11: MONTANT | H11: LIBELLÉ | I11: MONTANT | K11: LIBELLÉ | L11: MONTANT
E12: LOYER | H12: BAR MEN | K12: BANQUE
E13: EAU + ÉLECTRICITÉ | H13: BAR MEN ALI | K13: MOUHSSINE
E14: INTERNET & TÉLÉPHONE | H14: FATIMA | K14: HAMID
E15: TAXES & IMPÔTS | H15: MARWA | K15: AVANCE LOYER
E16: ASSURANCE | H16: LAHCEN | K16: PRÉLÈVEMENT PERSONNEL
E17: ABONNEMENTS TV | H17: ABDELLAH | K17: AUTRE VIREMENT
E18: ENTRETIEN & RÉPARATION | H18: AHMED
E19: AUTRE CHARGE FIXE | H19: ALI
H20: LATIFA 1
H21: LATIFA 2
H22: HAMZA
B26: TOTAL | C26: =SUM(C12:C25) -> 0 | E26: TOTAL | F26: =SUM(F12:F25) -> 0 | H26: TOTAL | I26: =SUM(I12:I25) -> 0 | K26: TOTAL | L26: =SUM(L12:L25) -> 0
B28: RECETTES DU JOUR | H28: SOLDE DE LA CAISSE
B29: Recette caisse (espèces comptées) | H29: Caisse de la veille | I29: ='05'!$I$32 -> 4223
B30: Glovo — espèces | H30: Recette du jour (+) | I30: =$C$32 -> 0
B31: Glovo — carte | H31: Dépenses du jour (−) | I31: =$C$26+$F$26+$I$26+$L$26 -> 0
B32: TOTAL RECETTE DU JOUR | C32: =SUM($C$29:$C$31) -> 0 | H32: SOLDE EN CAISSE CE SOIR | I32: =$I$29+$I$30-$I$31 -> 4223
B34: Le solde de ce soir devient automatiquement la caisse de la veille sur la feuille du lendemain. Les libellés en gris des blocs CHARGES FIXES, SALAIRES et VIREMENTS sont fixes : ils permettent au classeur de totaliser chaque poste sur tout le mois — ne les modifiez pas.

Sheet 07
A1: CAISSE DU JOUR
A2: =IF(7>'RECAP DU JOURNAL'!$F$4,"— ce jour n'existe pas dans le mois —",DATE('RECAP DU JOURNAL'!$C$3,'RECAP DU JOURNAL'!$C$4,7)) -> 46272 | G2: CAFÉ VICTOR HUGO — Mohammedia
A4: À REMPLIR ▸ les quatre blocs de dépenses ci-dessous ▸ puis, en bas, la RECETTE comptée dans la caisse. Les cases jaunes sont les vôtres ; le reste se calcule tout seul.
B6: CAISSE DE LA VEILLE | E6: RECETTE DU JOUR | H6: TOTAL DÉPENSES | K6: SOLDE CE SOIR
B7: =$I$29 -> 4223 | E7: =$C$32 -> 0 | H7: =$I$31 -> 0 | K7: =$I$32 -> 4223
B10: DÉPENSES — ACHATS DU JOUR | E10: CHARGES FIXES | H10: SALAIRES ET AVANCES | K10: VIREMENTS ET DIVERS
B11: LIBELLÉ | C11: MONTANT | E11: LIBELLÉ | F11: MONTANT | H11: LIBELLÉ | I11: MONTANT | K11: LIBELLÉ | L11: MONTANT
E12: LOYER | H12: BAR MEN | K12: BANQUE
E13: EAU + ÉLECTRICITÉ | H13: BAR MEN ALI | K13: MOUHSSINE
E14: INTERNET & TÉLÉPHONE | H14: FATIMA | K14: HAMID
E15: TAXES & IMPÔTS | H15: MARWA | K15: AVANCE LOYER
E16: ASSURANCE | H16: LAHCEN | K16: PRÉLÈVEMENT PERSONNEL
E17: ABONNEMENTS TV | H17: ABDELLAH | K17: AUTRE VIREMENT
E18: ENTRETIEN & RÉPARATION | H18: AHMED
E19: AUTRE CHARGE FIXE | H19: ALI
H20: LATIFA 1
H21: LATIFA 2
H22: HAMZA
B26: TOTAL | C26: =SUM(C12:C25) -> 0 | E26: TOTAL | F26: =SUM(F12:F25) -> 0 | H26: TOTAL | I26: =SUM(I12:I25) -> 0 | K26: TOTAL | L26: =SUM(L12:L25) -> 0
B28: RECETTES DU JOUR | H28: SOLDE DE LA CAISSE
B29: Recette caisse (espèces comptées) | H29: Caisse de la veille | I29: ='06'!$I$32 -> 4223
B30: Glovo — espèces | H30: Recette du jour (+) | I30: =$C$32 -> 0
B31: Glovo — carte | H31: Dépenses du jour (−) | I31: =$C$26+$F$26+$I$26+$L$26 -> 0
B32: TOTAL RECETTE DU JOUR | C32: =SUM($C$29:$C$31) -> 0 | H32: SOLDE EN CAISSE CE SOIR | I32: =$I$29+$I$30-$I$31 -> 4223
B34: Le solde de ce soir devient automatiquement la caisse de la veille sur la feuille du lendemain. Les libellés en gris des blocs CHARGES FIXES, SALAIRES et VIREMENTS sont fixes : ils permettent au classeur de totaliser chaque poste sur tout le mois — ne les modifiez pas.

Sheet 08
A1: CAISSE DU JOUR
A2: =IF(8>'RECAP DU JOURNAL'!$F$4,"— ce jour n'existe pas dans le mois —",DATE('RECAP DU JOURNAL'!$C$3,'RECAP DU JOURNAL'!$C$4,8)) -> 46273 | G2: CAFÉ VICTOR HUGO — Mohammedia
A4: À REMPLIR ▸ les quatre blocs de dépenses ci-dessous ▸ puis, en bas, la RECETTE comptée dans la caisse. Les cases jaunes sont les vôtres ; le reste se calcule tout seul.
B6: CAISSE DE LA VEILLE | E6: RECETTE DU JOUR | H6: TOTAL DÉPENSES | K6: SOLDE CE SOIR
B7: =$I$29 -> 4223 | E7: =$C$32 -> 0 | H7: =$I$31 -> 0 | K7: =$I$32 -> 4223
B10: DÉPENSES — ACHATS DU JOUR | E10: CHARGES FIXES | H10: SALAIRES ET AVANCES | K10: VIREMENTS ET DIVERS
B11: LIBELLÉ | C11: MONTANT | E11: LIBELLÉ | F11: MONTANT | H11: LIBELLÉ | I11: MONTANT | K11: LIBELLÉ | L11: MONTANT
E12: LOYER | H12: BAR MEN | K12: BANQUE
E13: EAU + ÉLECTRICITÉ | H13: BAR MEN ALI | K13: MOUHSSINE
E14: INTERNET & TÉLÉPHONE | H14: FATIMA | K14: HAMID
E15: TAXES & IMPÔTS | H15: MARWA | K15: AVANCE LOYER
E16: ASSURANCE | H16: LAHCEN | K16: PRÉLÈVEMENT PERSONNEL
E17: ABONNEMENTS TV | H17: ABDELLAH | K17: AUTRE VIREMENT
E18: ENTRETIEN & RÉPARATION | H18: AHMED
E19: AUTRE CHARGE FIXE | H19: ALI
H20: LATIFA 1
H21: LATIFA 2
H22: HAMZA
B26: TOTAL | C26: =SUM(C12:C25) -> 0 | E26: TOTAL | F26: =SUM(F12:F25) -> 0 | H26: TOTAL | I26: =SUM(I12:I25) -> 0 | K26: TOTAL | L26: =SUM(L12:L25) -> 0
B28: RECETTES DU JOUR | H28: SOLDE DE LA CAISSE
B29: Recette caisse (espèces comptées) | H29: Caisse de la veille | I29: ='07'!$I$32 -> 4223
B30: Glovo — espèces | H30: Recette du jour (+) | I30: =$C$32 -> 0
B31: Glovo — carte | H31: Dépenses du jour (−) | I31: =$C$26+$F$26+$I$26+$L$26 -> 0
B32: TOTAL RECETTE DU JOUR | C32: =SUM($C$29:$C$31) -> 0 | H32: SOLDE EN CAISSE CE SOIR | I32: =$I$29+$I$30-$I$31 -> 4223
B34: Le solde de ce soir devient automatiquement la caisse de la veille sur la feuille du lendemain. Les libellés en gris des blocs CHARGES FIXES, SALAIRES et VIREMENTS sont fixes : ils permettent au classeur de totaliser chaque poste sur tout le mois — ne les modifiez pas.

Sheet 09
A1: CAISSE DU JOUR
A2: =IF(9>'RECAP DU JOURNAL'!$F$4,"— ce jour n'existe pas dans le mois —",DATE('RECAP DU JOURNAL'!$C$3,'RECAP DU JOURNAL'!$C$4,9)) -> 46274 | G2: CAFÉ VICTOR HUGO — Mohammedia
A4: À REMPLIR ▸ les quatre blocs de dépenses ci-dessous ▸ puis, en bas, la RECETTE comptée dans la caisse. Les cases jaunes sont les vôtres ; le reste se calcule tout seul.
B6: CAISSE DE LA VEILLE | E6: RECETTE DU JOUR | H6: TOTAL DÉPENSES | K6: SOLDE CE SOIR
